INFO:werkzeug: * Running on http://127.0.0.1:5000/ (Press CTRL+C to quit)
INFO:werkzeug:127.0.0.1 - - [06/Oct/2020 00:50:24] "[37mGET / HTTP/1.1[0m" 200 -
INFO:werkzeug:127.0.0.1 - - [06/Oct/2020 00:50:25] "[37mGET /static/css/style.css HTTP/1.1[0m" 200 -
INFO:werkzeug:127.0.0.1 - - [06/Oct/2020 00:50:25] "[37mGET /static/images/uwa_logo.png HTTP/1.1[0m" 200 -
INFO:werkzeug:127.0.0.1 - - [06/Oct/2020 00:50:26] "[37mGET /login HTTP/1.1[0m" 200 -
ERROR:app:Exception on /login [POST]
Traceback (most recent call last):
  File "c:\users\xiaocheng wang\appdata\local\programs\python\python38-32\lib\site-packages\sqlalchemy\engine\base.py", line 1247, in _execute_context
    self.dialect.do_execute(
  File "c:\users\xiaocheng wang\appdata\local\programs\python\python38-32\lib\site-packages\sqlalchemy\engine\default.py", line 590, in do_execute
    cursor.execute(statement, parameters)
sqlite3.OperationalError: no such column: user.confirmed

The above exception was the direct cause of the following exception:

Traceback (most recent call last):
  File "c:\users\xiaocheng wang\appdata\local\programs\python\python38-32\lib\site-packages\flask\app.py", line 2447, in wsgi_app
    response = self.full_dispatch_request()
  File "c:\users\xiaocheng wang\appdata\local\programs\python\python38-32\lib\site-packages\flask\app.py", line 1952, in full_dispatch_request
    rv = self.handle_user_exception(e)
  File "c:\users\xiaocheng wang\appdata\local\programs\python\python38-32\lib\site-packages\flask\app.py", line 1821, in handle_user_exception
    reraise(exc_type, exc_value, tb)
  File "c:\users\xiaocheng wang\appdata\local\programs\python\python38-32\lib\site-packages\flask\_compat.py", line 39, in reraise
    raise value
  File "c:\users\xiaocheng wang\appdata\local\programs\python\python38-32\lib\site-packages\flask\app.py", line 1950, in full_dispatch_request
    rv = self.dispatch_request()
  File "c:\users\xiaocheng wang\appdata\local\programs\python\python38-32\lib\site-packages\flask\app.py", line 1936, in dispatch_request
    return self.view_functions[rule.endpoint](**req.view_args)
  File "E:\Study\UWA\Year3\S2\CITS3200\project\SDURI-Admin-Platform\app\routes.py", line 48, in login
    user = User.query.filter_by(email=form.email.data).first()
  File "c:\users\xiaocheng wang\appdata\local\programs\python\python38-32\lib\site-packages\sqlalchemy\orm\query.py", line 3300, in first
    ret = list(self[0:1])
  File "c:\users\xiaocheng wang\appdata\local\programs\python\python38-32\lib\site-packages\sqlalchemy\orm\query.py", line 3078, in __getitem__
    return list(res)
  File "c:\users\xiaocheng wang\appdata\local\programs\python\python38-32\lib\site-packages\sqlalchemy\orm\query.py", line 3405, in __iter__
    return self._execute_and_instances(context)
  File "c:\users\xiaocheng wang\appdata\local\programs\python\python38-32\lib\site-packages\sqlalchemy\orm\query.py", line 3430, in _execute_and_instances
    result = conn.execute(querycontext.statement, self._params)
  File "c:\users\xiaocheng wang\appdata\local\programs\python\python38-32\lib\site-packages\sqlalchemy\engine\base.py", line 984, in execute
    return meth(self, multiparams, params)
  File "c:\users\xiaocheng wang\appdata\local\programs\python\python38-32\lib\site-packages\sqlalchemy\sql\elements.py", line 293, in _execute_on_connection
    return connection._execute_clauseelement(self, multiparams, params)
  File "c:\users\xiaocheng wang\appdata\local\programs\python\python38-32\lib\site-packages\sqlalchemy\engine\base.py", line 1097, in _execute_clauseelement
    ret = self._execute_context(
  File "c:\users\xiaocheng wang\appdata\local\programs\python\python38-32\lib\site-packages\sqlalchemy\engine\base.py", line 1287, in _execute_context
    self._handle_dbapi_exception(
  File "c:\users\xiaocheng wang\appdata\local\programs\python\python38-32\lib\site-packages\sqlalchemy\engine\base.py", line 1481, in _handle_dbapi_exception
    util.raise_(
  File "c:\users\xiaocheng wang\appdata\local\programs\python\python38-32\lib\site-packages\sqlalchemy\util\compat.py", line 178, in raise_
    raise exception
  File "c:\users\xiaocheng wang\appdata\local\programs\python\python38-32\lib\site-packages\sqlalchemy\engine\base.py", line 1247, in _execute_context
    self.dialect.do_execute(
  File "c:\users\xiaocheng wang\appdata\local\programs\python\python38-32\lib\site-packages\sqlalchemy\engine\default.py", line 590, in do_execute
    cursor.execute(statement, parameters)
sqlalchemy.exc.OperationalError: (sqlite3.OperationalError) no such column: user.confirmed
[SQL: SELECT user.id AS user_id, user.name AS user_name, user.email AS user_email, user.confirmed AS user_confirmed, user.password AS user_password, user.role AS user_role, user.registered_on AS user_registered_on, user.confirmed_on AS user_confirmed_on, user.password_reset_token AS user_password_reset_token 
FROM user 
WHERE user.email = ?
 LIMIT ? OFFSET ?]
[parameters: ('super2@uwa.edu.au', 1, 0)]
(Background on this error at: http://sqlalche.me/e/e3q8)
INFO:werkzeug:127.0.0.1 - - [06/Oct/2020 00:50:31] "[35m[1mPOST /login HTTP/1.1[0m" 500 -
INFO:werkzeug:127.0.0.1 - - [06/Oct/2020 00:50:31] "[33mGET /favicon.ico HTTP/1.1[0m" 404 -
INFO:werkzeug:127.0.0.1 - - [06/Oct/2020 00:50:41] "[37mGET /login HTTP/1.1[0m" 200 -
