INFO:werkzeug: * Running on http://127.0.0.1:5000/ (Press CTRL+C to quit)
INFO:werkzeug:127.0.0.1 - - [14/Sep/2020 19:23:30] "[37mGET / HTTP/1.1[0m" 200 -
ERROR:app:Exception on /favicon.ico [GET]
Traceback (most recent call last):
  File "C:\Users\Xiaocheng Wang\AppData\Local\Programs\Python\Python38-32\lib\site-packages\flask\app.py", line 2447, in wsgi_app
    response = self.full_dispatch_request()
  File "C:\Users\Xiaocheng Wang\AppData\Local\Programs\Python\Python38-32\lib\site-packages\flask\app.py", line 1952, in full_dispatch_request
    rv = self.handle_user_exception(e)
  File "C:\Users\Xiaocheng Wang\AppData\Local\Programs\Python\Python38-32\lib\site-packages\flask\app.py", line 1821, in handle_user_exception
    reraise(exc_type, exc_value, tb)
  File "C:\Users\Xiaocheng Wang\AppData\Local\Programs\Python\Python38-32\lib\site-packages\flask\_compat.py", line 39, in reraise
    raise value
  File "C:\Users\Xiaocheng Wang\AppData\Local\Programs\Python\Python38-32\lib\site-packages\flask\app.py", line 1950, in full_dispatch_request
    rv = self.dispatch_request()
  File "C:\Users\Xiaocheng Wang\AppData\Local\Programs\Python\Python38-32\lib\site-packages\flask\app.py", line 1936, in dispatch_request
    return self.view_functions[rule.endpoint](**req.view_args)
  File "E:\Study\UWA\Year3\S2\CITS3200\project\SDURI-Admin-Platform\app\routes.py", line 30, in favicon
    return send_from_directory(os.path.join(app.root_path, 'static'),
NameError: name 'send_from_directory' is not defined
INFO:werkzeug:127.0.0.1 - - [14/Sep/2020 19:23:30] "[35m[1mGET /favicon.ico HTTP/1.1[0m" 500 -
INFO:werkzeug:127.0.0.1 - - [14/Sep/2020 19:23:39] "[37mGET /index HTTP/1.1[0m" 200 -
ERROR:app:Exception on /favicon.ico [GET]
Traceback (most recent call last):
  File "C:\Users\Xiaocheng Wang\AppData\Local\Programs\Python\Python38-32\lib\site-packages\flask\app.py", line 2447, in wsgi_app
    response = self.full_dispatch_request()
  File "C:\Users\Xiaocheng Wang\AppData\Local\Programs\Python\Python38-32\lib\site-packages\flask\app.py", line 1952, in full_dispatch_request
    rv = self.handle_user_exception(e)
  File "C:\Users\Xiaocheng Wang\AppData\Local\Programs\Python\Python38-32\lib\site-packages\flask\app.py", line 1821, in handle_user_exception
    reraise(exc_type, exc_value, tb)
  File "C:\Users\Xiaocheng Wang\AppData\Local\Programs\Python\Python38-32\lib\site-packages\flask\_compat.py", line 39, in reraise
    raise value
  File "C:\Users\Xiaocheng Wang\AppData\Local\Programs\Python\Python38-32\lib\site-packages\flask\app.py", line 1950, in full_dispatch_request
    rv = self.dispatch_request()
  File "C:\Users\Xiaocheng Wang\AppData\Local\Programs\Python\Python38-32\lib\site-packages\flask\app.py", line 1936, in dispatch_request
    return self.view_functions[rule.endpoint](**req.view_args)
  File "E:\Study\UWA\Year3\S2\CITS3200\project\SDURI-Admin-Platform\app\routes.py", line 30, in favicon
    return send_from_directory(os.path.join(app.root_path, 'static'),
NameError: name 'send_from_directory' is not defined
INFO:werkzeug:127.0.0.1 - - [14/Sep/2020 19:23:39] "[35m[1mGET /favicon.ico HTTP/1.1[0m" 500 -
INFO:werkzeug:127.0.0.1 - - [14/Sep/2020 19:23:43] "[33mGET /project_list HTTP/1.1[0m" 404 -
ERROR:app:Exception on /favicon.ico [GET]
Traceback (most recent call last):
  File "C:\Users\Xiaocheng Wang\AppData\Local\Programs\Python\Python38-32\lib\site-packages\flask\app.py", line 2447, in wsgi_app
    response = self.full_dispatch_request()
  File "C:\Users\Xiaocheng Wang\AppData\Local\Programs\Python\Python38-32\lib\site-packages\flask\app.py", line 1952, in full_dispatch_request
    rv = self.handle_user_exception(e)
  File "C:\Users\Xiaocheng Wang\AppData\Local\Programs\Python\Python38-32\lib\site-packages\flask\app.py", line 1821, in handle_user_exception
    reraise(exc_type, exc_value, tb)
  File "C:\Users\Xiaocheng Wang\AppData\Local\Programs\Python\Python38-32\lib\site-packages\flask\_compat.py", line 39, in reraise
    raise value
  File "C:\Users\Xiaocheng Wang\AppData\Local\Programs\Python\Python38-32\lib\site-packages\flask\app.py", line 1950, in full_dispatch_request
    rv = self.dispatch_request()
  File "C:\Users\Xiaocheng Wang\AppData\Local\Programs\Python\Python38-32\lib\site-packages\flask\app.py", line 1936, in dispatch_request
    return self.view_functions[rule.endpoint](**req.view_args)
  File "E:\Study\UWA\Year3\S2\CITS3200\project\SDURI-Admin-Platform\app\routes.py", line 30, in favicon
    return send_from_directory(os.path.join(app.root_path, 'static'),
NameError: name 'send_from_directory' is not defined
INFO:werkzeug:127.0.0.1 - - [14/Sep/2020 19:23:43] "[35m[1mGET /favicon.ico HTTP/1.1[0m" 500 -
INFO:werkzeug:127.0.0.1 - - [14/Sep/2020 19:23:49] "[33mGET /project-list HTTP/1.1[0m" 404 -
ERROR:app:Exception on /favicon.ico [GET]
Traceback (most recent call last):
  File "C:\Users\Xiaocheng Wang\AppData\Local\Programs\Python\Python38-32\lib\site-packages\flask\app.py", line 2447, in wsgi_app
    response = self.full_dispatch_request()
  File "C:\Users\Xiaocheng Wang\AppData\Local\Programs\Python\Python38-32\lib\site-packages\flask\app.py", line 1952, in full_dispatch_request
    rv = self.handle_user_exception(e)
  File "C:\Users\Xiaocheng Wang\AppData\Local\Programs\Python\Python38-32\lib\site-packages\flask\app.py", line 1821, in handle_user_exception
    reraise(exc_type, exc_value, tb)
  File "C:\Users\Xiaocheng Wang\AppData\Local\Programs\Python\Python38-32\lib\site-packages\flask\_compat.py", line 39, in reraise
    raise value
  File "C:\Users\Xiaocheng Wang\AppData\Local\Programs\Python\Python38-32\lib\site-packages\flask\app.py", line 1950, in full_dispatch_request
    rv = self.dispatch_request()
  File "C:\Users\Xiaocheng Wang\AppData\Local\Programs\Python\Python38-32\lib\site-packages\flask\app.py", line 1936, in dispatch_request
    return self.view_functions[rule.endpoint](**req.view_args)
  File "E:\Study\UWA\Year3\S2\CITS3200\project\SDURI-Admin-Platform\app\routes.py", line 30, in favicon
    return send_from_directory(os.path.join(app.root_path, 'static'),
NameError: name 'send_from_directory' is not defined
INFO:werkzeug:127.0.0.1 - - [14/Sep/2020 19:23:49] "[35m[1mGET /favicon.ico HTTP/1.1[0m" 500 -
INFO:werkzeug:127.0.0.1 - - [14/Sep/2020 19:27:12] "[37mGET / HTTP/1.1[0m" 200 -
ERROR:app:Exception on /favicon.ico [GET]
Traceback (most recent call last):
  File "C:\Users\Xiaocheng Wang\AppData\Local\Programs\Python\Python38-32\lib\site-packages\flask\app.py", line 2447, in wsgi_app
    response = self.full_dispatch_request()
  File "C:\Users\Xiaocheng Wang\AppData\Local\Programs\Python\Python38-32\lib\site-packages\flask\app.py", line 1952, in full_dispatch_request
    rv = self.handle_user_exception(e)
  File "C:\Users\Xiaocheng Wang\AppData\Local\Programs\Python\Python38-32\lib\site-packages\flask\app.py", line 1821, in handle_user_exception
    reraise(exc_type, exc_value, tb)
  File "C:\Users\Xiaocheng Wang\AppData\Local\Programs\Python\Python38-32\lib\site-packages\flask\_compat.py", line 39, in reraise
    raise value
  File "C:\Users\Xiaocheng Wang\AppData\Local\Programs\Python\Python38-32\lib\site-packages\flask\app.py", line 1950, in full_dispatch_request
    rv = self.dispatch_request()
  File "C:\Users\Xiaocheng Wang\AppData\Local\Programs\Python\Python38-32\lib\site-packages\flask\app.py", line 1936, in dispatch_request
    return self.view_functions[rule.endpoint](**req.view_args)
  File "E:\Study\UWA\Year3\S2\CITS3200\project\SDURI-Admin-Platform\app\routes.py", line 30, in favicon
    return send_from_directory(os.path.join(app.root_path, 'static'),
NameError: name 'send_from_directory' is not defined
INFO:werkzeug:127.0.0.1 - - [14/Sep/2020 19:27:12] "[35m[1mGET /favicon.ico HTTP/1.1[0m" 500 -
INFO:werkzeug:127.0.0.1 - - [14/Sep/2020 19:29:15] "[37mGET / HTTP/1.1[0m" 200 -
ERROR:app:Exception on /favicon.ico [GET]
Traceback (most recent call last):
  File "C:\Users\Xiaocheng Wang\AppData\Local\Programs\Python\Python38-32\lib\site-packages\flask\app.py", line 2447, in wsgi_app
    response = self.full_dispatch_request()
  File "C:\Users\Xiaocheng Wang\AppData\Local\Programs\Python\Python38-32\lib\site-packages\flask\app.py", line 1952, in full_dispatch_request
    rv = self.handle_user_exception(e)
  File "C:\Users\Xiaocheng Wang\AppData\Local\Programs\Python\Python38-32\lib\site-packages\flask\app.py", line 1821, in handle_user_exception
    reraise(exc_type, exc_value, tb)
  File "C:\Users\Xiaocheng Wang\AppData\Local\Programs\Python\Python38-32\lib\site-packages\flask\_compat.py", line 39, in reraise
    raise value
  File "C:\Users\Xiaocheng Wang\AppData\Local\Programs\Python\Python38-32\lib\site-packages\flask\app.py", line 1950, in full_dispatch_request
    rv = self.dispatch_request()
  File "C:\Users\Xiaocheng Wang\AppData\Local\Programs\Python\Python38-32\lib\site-packages\flask\app.py", line 1936, in dispatch_request
    return self.view_functions[rule.endpoint](**req.view_args)
  File "E:\Study\UWA\Year3\S2\CITS3200\project\SDURI-Admin-Platform\app\routes.py", line 30, in favicon
    return send_from_directory(os.path.join(app.root_path, 'static'),
NameError: name 'send_from_directory' is not defined
INFO:werkzeug:127.0.0.1 - - [14/Sep/2020 19:29:15] "[35m[1mGET /favicon.ico HTTP/1.1[0m" 500 -
INFO:werkzeug:127.0.0.1 - - [14/Sep/2020 19:29:20] "[37mGET / HTTP/1.1[0m" 200 -
ERROR:app:Exception on /favicon.ico [GET]
Traceback (most recent call last):
  File "C:\Users\Xiaocheng Wang\AppData\Local\Programs\Python\Python38-32\lib\site-packages\flask\app.py", line 2447, in wsgi_app
    response = self.full_dispatch_request()
  File "C:\Users\Xiaocheng Wang\AppData\Local\Programs\Python\Python38-32\lib\site-packages\flask\app.py", line 1952, in full_dispatch_request
    rv = self.handle_user_exception(e)
  File "C:\Users\Xiaocheng Wang\AppData\Local\Programs\Python\Python38-32\lib\site-packages\flask\app.py", line 1821, in handle_user_exception
    reraise(exc_type, exc_value, tb)
  File "C:\Users\Xiaocheng Wang\AppData\Local\Programs\Python\Python38-32\lib\site-packages\flask\_compat.py", line 39, in reraise
    raise value
  File "C:\Users\Xiaocheng Wang\AppData\Local\Programs\Python\Python38-32\lib\site-packages\flask\app.py", line 1950, in full_dispatch_request
    rv = self.dispatch_request()
  File "C:\Users\Xiaocheng Wang\AppData\Local\Programs\Python\Python38-32\lib\site-packages\flask\app.py", line 1936, in dispatch_request
    return self.view_functions[rule.endpoint](**req.view_args)
  File "E:\Study\UWA\Year3\S2\CITS3200\project\SDURI-Admin-Platform\app\routes.py", line 30, in favicon
    return send_from_directory(os.path.join(app.root_path, 'static'),
NameError: name 'send_from_directory' is not defined
INFO:werkzeug:127.0.0.1 - - [14/Sep/2020 19:29:20] "[35m[1mGET /favicon.ico HTTP/1.1[0m" 500 -
