INFO:werkzeug: * Running on http://127.0.0.1:5000/ (Press CTRL+C to quit)
INFO:werkzeug:127.0.0.1 - - [14/Sep/2020 19:39:39] "[37mGET / HTTP/1.1[0m" 200 -
ERROR:app:Exception on /favicon.ico [GET]
Traceback (most recent call last):
  File "C:\Users\Xiaocheng Wang\AppData\Local\Programs\Python\Python38-32\lib\site-packages\flask\app.py", line 2447, in wsgi_app
    response = self.full_dispatch_request()
  File "C:\Users\Xiaocheng Wang\AppData\Local\Programs\Python\Python38-32\lib\site-packages\flask\app.py", line 1952, in full_dispatch_request
    rv = self.handle_user_exception(e)
  File "C:\Users\Xiaocheng Wang\AppData\Local\Programs\Python\Python38-32\lib\site-packages\flask\app.py", line 1821, in handle_user_exception
    reraise(exc_type, exc_value, tb)
  File "C:\Users\Xiaocheng Wang\AppData\Local\Programs\Python\Python38-32\lib\site-packages\flask\_compat.py", line 39, in reraise
    raise value
  File "C:\Users\Xiaocheng Wang\AppData\Local\Programs\Python\Python38-32\lib\site-packages\flask\app.py", line 1950, in full_dispatch_request
    rv = self.dispatch_request()
  File "C:\Users\Xiaocheng Wang\AppData\Local\Programs\Python\Python38-32\lib\site-packages\flask\app.py", line 1936, in dispatch_request
    return self.view_functions[rule.endpoint](**req.view_args)
  File "E:\Study\UWA\Year3\S2\CITS3200\project\SDURI-Admin-Platform\app\routes.py", line 32, in favicon
    return send_from_directory(os.path.join(app.root_path, 'static'),
NameError: name 'send_from_directory' is not defined
INFO:werkzeug:127.0.0.1 - - [14/Sep/2020 19:39:39] "[35m[1mGET /favicon.ico HTTP/1.1[0m" 500 -
INFO:werkzeug:127.0.0.1 - - [14/Sep/2020 19:39:45] "[37mGET /project_list HTTP/1.1[0m" 200 -
INFO:werkzeug:127.0.0.1 - - [14/Sep/2020 19:39:45] "[37mGET /static/images/uwa_logo.png HTTP/1.1[0m" 200 -
INFO:werkzeug:127.0.0.1 - - [14/Sep/2020 19:39:45] "[37mGET /static/images/favicon.ico HTTP/1.1[0m" 200 -
INFO:werkzeug:127.0.0.1 - - [14/Sep/2020 19:39:51] "[37mGET /project_list/single_project HTTP/1.1[0m" 200 -
INFO:werkzeug:127.0.0.1 - - [14/Sep/2020 19:39:53] "[37mGET /project_list HTTP/1.1[0m" 200 -
INFO:werkzeug:127.0.0.1 - - [14/Sep/2020 19:39:55] "[37mGET /index HTTP/1.1[0m" 200 -
ERROR:app:Exception on /favicon.ico [GET]
Traceback (most recent call last):
  File "C:\Users\Xiaocheng Wang\AppData\Local\Programs\Python\Python38-32\lib\site-packages\flask\app.py", line 2447, in wsgi_app
    response = self.full_dispatch_request()
  File "C:\Users\Xiaocheng Wang\AppData\Local\Programs\Python\Python38-32\lib\site-packages\flask\app.py", line 1952, in full_dispatch_request
    rv = self.handle_user_exception(e)
  File "C:\Users\Xiaocheng Wang\AppData\Local\Programs\Python\Python38-32\lib\site-packages\flask\app.py", line 1821, in handle_user_exception
    reraise(exc_type, exc_value, tb)
  File "C:\Users\Xiaocheng Wang\AppData\Local\Programs\Python\Python38-32\lib\site-packages\flask\_compat.py", line 39, in reraise
    raise value
  File "C:\Users\Xiaocheng Wang\AppData\Local\Programs\Python\Python38-32\lib\site-packages\flask\app.py", line 1950, in full_dispatch_request
    rv = self.dispatch_request()
  File "C:\Users\Xiaocheng Wang\AppData\Local\Programs\Python\Python38-32\lib\site-packages\flask\app.py", line 1936, in dispatch_request
    return self.view_functions[rule.endpoint](**req.view_args)
  File "E:\Study\UWA\Year3\S2\CITS3200\project\SDURI-Admin-Platform\app\routes.py", line 32, in favicon
    return send_from_directory(os.path.join(app.root_path, 'static'),
NameError: name 'send_from_directory' is not defined
INFO:werkzeug:127.0.0.1 - - [14/Sep/2020 19:39:55] "[35m[1mGET /favicon.ico HTTP/1.1[0m" 500 -
INFO:werkzeug:127.0.0.1 - - [14/Sep/2020 19:41:21] "[32mGET /register HTTP/1.1[0m" 302 -
INFO:werkzeug:127.0.0.1 - - [14/Sep/2020 19:41:21] "[37mGET /index HTTP/1.1[0m" 200 -
ERROR:app:Exception on /favicon.ico [GET]
Traceback (most recent call last):
  File "C:\Users\Xiaocheng Wang\AppData\Local\Programs\Python\Python38-32\lib\site-packages\flask\app.py", line 2447, in wsgi_app
    response = self.full_dispatch_request()
  File "C:\Users\Xiaocheng Wang\AppData\Local\Programs\Python\Python38-32\lib\site-packages\flask\app.py", line 1952, in full_dispatch_request
    rv = self.handle_user_exception(e)
  File "C:\Users\Xiaocheng Wang\AppData\Local\Programs\Python\Python38-32\lib\site-packages\flask\app.py", line 1821, in handle_user_exception
    reraise(exc_type, exc_value, tb)
  File "C:\Users\Xiaocheng Wang\AppData\Local\Programs\Python\Python38-32\lib\site-packages\flask\_compat.py", line 39, in reraise
    raise value
  File "C:\Users\Xiaocheng Wang\AppData\Local\Programs\Python\Python38-32\lib\site-packages\flask\app.py", line 1950, in full_dispatch_request
    rv = self.dispatch_request()
  File "C:\Users\Xiaocheng Wang\AppData\Local\Programs\Python\Python38-32\lib\site-packages\flask\app.py", line 1936, in dispatch_request
    return self.view_functions[rule.endpoint](**req.view_args)
  File "E:\Study\UWA\Year3\S2\CITS3200\project\SDURI-Admin-Platform\app\routes.py", line 32, in favicon
    return send_from_directory(os.path.join(app.root_path, 'static'),
NameError: name 'send_from_directory' is not defined
INFO:werkzeug:127.0.0.1 - - [14/Sep/2020 19:41:21] "[35m[1mGET /favicon.ico HTTP/1.1[0m" 500 -
INFO:werkzeug:127.0.0.1 - - [14/Sep/2020 19:41:27] "[32mGET /register HTTP/1.1[0m" 302 -
INFO:werkzeug:127.0.0.1 - - [14/Sep/2020 19:41:27] "[37mGET /index HTTP/1.1[0m" 200 -
ERROR:app:Exception on /favicon.ico [GET]
Traceback (most recent call last):
  File "C:\Users\Xiaocheng Wang\AppData\Local\Programs\Python\Python38-32\lib\site-packages\flask\app.py", line 2447, in wsgi_app
    response = self.full_dispatch_request()
  File "C:\Users\Xiaocheng Wang\AppData\Local\Programs\Python\Python38-32\lib\site-packages\flask\app.py", line 1952, in full_dispatch_request
    rv = self.handle_user_exception(e)
  File "C:\Users\Xiaocheng Wang\AppData\Local\Programs\Python\Python38-32\lib\site-packages\flask\app.py", line 1821, in handle_user_exception
    reraise(exc_type, exc_value, tb)
  File "C:\Users\Xiaocheng Wang\AppData\Local\Programs\Python\Python38-32\lib\site-packages\flask\_compat.py", line 39, in reraise
    raise value
  File "C:\Users\Xiaocheng Wang\AppData\Local\Programs\Python\Python38-32\lib\site-packages\flask\app.py", line 1950, in full_dispatch_request
    rv = self.dispatch_request()
  File "C:\Users\Xiaocheng Wang\AppData\Local\Programs\Python\Python38-32\lib\site-packages\flask\app.py", line 1936, in dispatch_request
    return self.view_functions[rule.endpoint](**req.view_args)
  File "E:\Study\UWA\Year3\S2\CITS3200\project\SDURI-Admin-Platform\app\routes.py", line 32, in favicon
    return send_from_directory(os.path.join(app.root_path, 'static'),
NameError: name 'send_from_directory' is not defined
INFO:werkzeug:127.0.0.1 - - [14/Sep/2020 19:41:27] "[35m[1mGET /favicon.ico HTTP/1.1[0m" 500 -
INFO:werkzeug:127.0.0.1 - - [14/Sep/2020 19:41:31] "[32mGET /login HTTP/1.1[0m" 302 -
INFO:werkzeug:127.0.0.1 - - [14/Sep/2020 19:41:31] "[37mGET /index HTTP/1.1[0m" 200 -
ERROR:app:Exception on /favicon.ico [GET]
Traceback (most recent call last):
  File "C:\Users\Xiaocheng Wang\AppData\Local\Programs\Python\Python38-32\lib\site-packages\flask\app.py", line 2447, in wsgi_app
    response = self.full_dispatch_request()
  File "C:\Users\Xiaocheng Wang\AppData\Local\Programs\Python\Python38-32\lib\site-packages\flask\app.py", line 1952, in full_dispatch_request
    rv = self.handle_user_exception(e)
  File "C:\Users\Xiaocheng Wang\AppData\Local\Programs\Python\Python38-32\lib\site-packages\flask\app.py", line 1821, in handle_user_exception
    reraise(exc_type, exc_value, tb)
  File "C:\Users\Xiaocheng Wang\AppData\Local\Programs\Python\Python38-32\lib\site-packages\flask\_compat.py", line 39, in reraise
    raise value
  File "C:\Users\Xiaocheng Wang\AppData\Local\Programs\Python\Python38-32\lib\site-packages\flask\app.py", line 1950, in full_dispatch_request
    rv = self.dispatch_request()
  File "C:\Users\Xiaocheng Wang\AppData\Local\Programs\Python\Python38-32\lib\site-packages\flask\app.py", line 1936, in dispatch_request
    return self.view_functions[rule.endpoint](**req.view_args)
  File "E:\Study\UWA\Year3\S2\CITS3200\project\SDURI-Admin-Platform\app\routes.py", line 32, in favicon
    return send_from_directory(os.path.join(app.root_path, 'static'),
NameError: name 'send_from_directory' is not defined
INFO:werkzeug:127.0.0.1 - - [14/Sep/2020 19:41:31] "[35m[1mGET /favicon.ico HTTP/1.1[0m" 500 -
INFO:werkzeug:127.0.0.1 - - [14/Sep/2020 19:41:36] "[32mGET /admin HTTP/1.1[0m" 308 -
INFO:werkzeug:127.0.0.1 - - [14/Sep/2020 19:41:36] "[37mGET /admin/ HTTP/1.1[0m" 200 -
INFO:werkzeug:127.0.0.1 - - [14/Sep/2020 19:41:36] "[37mGET /admin/static/bootstrap/bootstrap3/swatch/default/bootstrap.min.css?v=3.3.5 HTTP/1.1[0m" 200 -
INFO:werkzeug:127.0.0.1 - - [14/Sep/2020 19:41:36] "[37mGET /admin/static/bootstrap/bootstrap3/css/bootstrap-theme.min.css?v=3.3.5 HTTP/1.1[0m" 200 -
INFO:werkzeug:127.0.0.1 - - [14/Sep/2020 19:41:36] "[37mGET /admin/static/admin/css/bootstrap3/admin.css?v=1.1.1 HTTP/1.1[0m" 200 -
INFO:werkzeug:127.0.0.1 - - [14/Sep/2020 19:41:36] "[37mGET /admin/static/admin/css/bootstrap3/submenu.css HTTP/1.1[0m" 200 -
INFO:werkzeug:127.0.0.1 - - [14/Sep/2020 19:41:36] "[37mGET /admin/static/admin/js/helpers.js?v=1.0.0 HTTP/1.1[0m" 200 -
INFO:werkzeug:127.0.0.1 - - [14/Sep/2020 19:41:36] "[37mGET /admin/static/bootstrap/bootstrap3/js/bootstrap.min.js?v=3.3.5 HTTP/1.1[0m" 200 -
INFO:werkzeug:127.0.0.1 - - [14/Sep/2020 19:41:36] "[37mGET /admin/static/vendor/select2/select2.min.js?v=3.5.2 HTTP/1.1[0m" 200 -
INFO:werkzeug:127.0.0.1 - - [14/Sep/2020 19:41:36] "[37mGET /admin/static/vendor/moment.min.js?v=2.22.2 HTTP/1.1[0m" 200 -
INFO:werkzeug:127.0.0.1 - - [14/Sep/2020 19:41:36] "[37mGET /admin/static/vendor/jquery.min.js?v=3.3.1 HTTP/1.1[0m" 200 -
ERROR:app:Exception on /favicon.ico [GET]
Traceback (most recent call last):
  File "C:\Users\Xiaocheng Wang\AppData\Local\Programs\Python\Python38-32\lib\site-packages\flask\app.py", line 2447, in wsgi_app
    response = self.full_dispatch_request()
  File "C:\Users\Xiaocheng Wang\AppData\Local\Programs\Python\Python38-32\lib\site-packages\flask\app.py", line 1952, in full_dispatch_request
    rv = self.handle_user_exception(e)
  File "C:\Users\Xiaocheng Wang\AppData\Local\Programs\Python\Python38-32\lib\site-packages\flask\app.py", line 1821, in handle_user_exception
    reraise(exc_type, exc_value, tb)
  File "C:\Users\Xiaocheng Wang\AppData\Local\Programs\Python\Python38-32\lib\site-packages\flask\_compat.py", line 39, in reraise
    raise value
  File "C:\Users\Xiaocheng Wang\AppData\Local\Programs\Python\Python38-32\lib\site-packages\flask\app.py", line 1950, in full_dispatch_request
    rv = self.dispatch_request()
  File "C:\Users\Xiaocheng Wang\AppData\Local\Programs\Python\Python38-32\lib\site-packages\flask\app.py", line 1936, in dispatch_request
    return self.view_functions[rule.endpoint](**req.view_args)
  File "E:\Study\UWA\Year3\S2\CITS3200\project\SDURI-Admin-Platform\app\routes.py", line 32, in favicon
    return send_from_directory(os.path.join(app.root_path, 'static'),
NameError: name 'send_from_directory' is not defined
INFO:werkzeug:127.0.0.1 - - [14/Sep/2020 19:41:36] "[35m[1mGET /favicon.ico HTTP/1.1[0m" 500 -
ERROR:app:Exception on /admin/supervisor/ [GET]
Traceback (most recent call last):
  File "C:\Users\Xiaocheng Wang\AppData\Local\Programs\Python\Python38-32\lib\site-packages\sqlalchemy\engine\base.py", line 1247, in _execute_context
    self.dialect.do_execute(
  File "C:\Users\Xiaocheng Wang\AppData\Local\Programs\Python\Python38-32\lib\site-packages\sqlalchemy\engine\default.py", line 590, in do_execute
    cursor.execute(statement, parameters)
sqlite3.OperationalError: no such table: supervisor

The above exception was the direct cause of the following exception:

Traceback (most recent call last):
  File "C:\Users\Xiaocheng Wang\AppData\Local\Programs\Python\Python38-32\lib\site-packages\flask\app.py", line 2447, in wsgi_app
    response = self.full_dispatch_request()
  File "C:\Users\Xiaocheng Wang\AppData\Local\Programs\Python\Python38-32\lib\site-packages\flask\app.py", line 1952, in full_dispatch_request
    rv = self.handle_user_exception(e)
  File "C:\Users\Xiaocheng Wang\AppData\Local\Programs\Python\Python38-32\lib\site-packages\flask\app.py", line 1821, in handle_user_exception
    reraise(exc_type, exc_value, tb)
  File "C:\Users\Xiaocheng Wang\AppData\Local\Programs\Python\Python38-32\lib\site-packages\flask\_compat.py", line 39, in reraise
    raise value
  File "C:\Users\Xiaocheng Wang\AppData\Local\Programs\Python\Python38-32\lib\site-packages\flask\app.py", line 1950, in full_dispatch_request
    rv = self.dispatch_request()
  File "C:\Users\Xiaocheng Wang\AppData\Local\Programs\Python\Python38-32\lib\site-packages\flask\app.py", line 1936, in dispatch_request
    return self.view_functions[rule.endpoint](**req.view_args)
  File "C:\Users\Xiaocheng Wang\AppData\Local\Programs\Python\Python38-32\lib\site-packages\flask_admin\base.py", line 69, in inner
    return self._run_view(f, *args, **kwargs)
  File "C:\Users\Xiaocheng Wang\AppData\Local\Programs\Python\Python38-32\lib\site-packages\flask_admin\base.py", line 368, in _run_view
    return fn(self, *args, **kwargs)
  File "C:\Users\Xiaocheng Wang\AppData\Local\Programs\Python\Python38-32\lib\site-packages\flask_admin\model\base.py", line 1969, in index_view
    count, data = self.get_list(view_args.page, sort_column, view_args.sort_desc,
  File "C:\Users\Xiaocheng Wang\AppData\Local\Programs\Python\Python38-32\lib\site-packages\flask_admin\contrib\sqla\view.py", line 1065, in get_list
    count = count_query.scalar() if count_query else None
  File "C:\Users\Xiaocheng Wang\AppData\Local\Programs\Python\Python38-32\lib\site-packages\sqlalchemy\orm\query.py", line 3393, in scalar
    ret = self.one()
  File "C:\Users\Xiaocheng Wang\AppData\Local\Programs\Python\Python38-32\lib\site-packages\sqlalchemy\orm\query.py", line 3360, in one
    ret = self.one_or_none()
  File "C:\Users\Xiaocheng Wang\AppData\Local\Programs\Python\Python38-32\lib\site-packages\sqlalchemy\orm\query.py", line 3329, in one_or_none
    ret = list(self)
  File "C:\Users\Xiaocheng Wang\AppData\Local\Programs\Python\Python38-32\lib\site-packages\sqlalchemy\orm\query.py", line 3405, in __iter__
    return self._execute_and_instances(context)
  File "C:\Users\Xiaocheng Wang\AppData\Local\Programs\Python\Python38-32\lib\site-packages\sqlalchemy\orm\query.py", line 3430, in _execute_and_instances
    result = conn.execute(querycontext.statement, self._params)
  File "C:\Users\Xiaocheng Wang\AppData\Local\Programs\Python\Python38-32\lib\site-packages\sqlalchemy\engine\base.py", line 984, in execute
    return meth(self, multiparams, params)
  File "C:\Users\Xiaocheng Wang\AppData\Local\Programs\Python\Python38-32\lib\site-packages\sqlalchemy\sql\elements.py", line 293, in _execute_on_connection
    return connection._execute_clauseelement(self, multiparams, params)
  File "C:\Users\Xiaocheng Wang\AppData\Local\Programs\Python\Python38-32\lib\site-packages\sqlalchemy\engine\base.py", line 1097, in _execute_clauseelement
    ret = self._execute_context(
  File "C:\Users\Xiaocheng Wang\AppData\Local\Programs\Python\Python38-32\lib\site-packages\sqlalchemy\engine\base.py", line 1287, in _execute_context
    self._handle_dbapi_exception(
  File "C:\Users\Xiaocheng Wang\AppData\Local\Programs\Python\Python38-32\lib\site-packages\sqlalchemy\engine\base.py", line 1481, in _handle_dbapi_exception
    util.raise_(
  File "C:\Users\Xiaocheng Wang\AppData\Local\Programs\Python\Python38-32\lib\site-packages\sqlalchemy\util\compat.py", line 178, in raise_
    raise exception
  File "C:\Users\Xiaocheng Wang\AppData\Local\Programs\Python\Python38-32\lib\site-packages\sqlalchemy\engine\base.py", line 1247, in _execute_context
    self.dialect.do_execute(
  File "C:\Users\Xiaocheng Wang\AppData\Local\Programs\Python\Python38-32\lib\site-packages\sqlalchemy\engine\default.py", line 590, in do_execute
    cursor.execute(statement, parameters)
sqlalchemy.exc.OperationalError: (sqlite3.OperationalError) no such table: supervisor
[SQL: SELECT count(?) AS count_1 
FROM supervisor]
[parameters: ('*',)]
(Background on this error at: http://sqlalche.me/e/e3q8)
INFO:werkzeug:127.0.0.1 - - [14/Sep/2020 19:41:37] "[35m[1mGET /admin/supervisor/ HTTP/1.1[0m" 500 -
ERROR:app:Exception on /favicon.ico [GET]
Traceback (most recent call last):
  File "C:\Users\Xiaocheng Wang\AppData\Local\Programs\Python\Python38-32\lib\site-packages\flask\app.py", line 2447, in wsgi_app
    response = self.full_dispatch_request()
  File "C:\Users\Xiaocheng Wang\AppData\Local\Programs\Python\Python38-32\lib\site-packages\flask\app.py", line 1952, in full_dispatch_request
    rv = self.handle_user_exception(e)
  File "C:\Users\Xiaocheng Wang\AppData\Local\Programs\Python\Python38-32\lib\site-packages\flask\app.py", line 1821, in handle_user_exception
    reraise(exc_type, exc_value, tb)
  File "C:\Users\Xiaocheng Wang\AppData\Local\Programs\Python\Python38-32\lib\site-packages\flask\_compat.py", line 39, in reraise
    raise value
  File "C:\Users\Xiaocheng Wang\AppData\Local\Programs\Python\Python38-32\lib\site-packages\flask\app.py", line 1950, in full_dispatch_request
    rv = self.dispatch_request()
  File "C:\Users\Xiaocheng Wang\AppData\Local\Programs\Python\Python38-32\lib\site-packages\flask\app.py", line 1936, in dispatch_request
    return self.view_functions[rule.endpoint](**req.view_args)
  File "E:\Study\UWA\Year3\S2\CITS3200\project\SDURI-Admin-Platform\app\routes.py", line 32, in favicon
    return send_from_directory(os.path.join(app.root_path, 'static'),
NameError: name 'send_from_directory' is not defined
INFO:werkzeug:127.0.0.1 - - [14/Sep/2020 19:41:37] "[35m[1mGET /favicon.ico HTTP/1.1[0m" 500 -
INFO:werkzeug:127.0.0.1 - - [14/Sep/2020 19:42:09] "[37mGET /admin/ HTTP/1.1[0m" 200 -
ERROR:app:Exception on /favicon.ico [GET]
Traceback (most recent call last):
  File "C:\Users\Xiaocheng Wang\AppData\Local\Programs\Python\Python38-32\lib\site-packages\flask\app.py", line 2447, in wsgi_app
    response = self.full_dispatch_request()
  File "C:\Users\Xiaocheng Wang\AppData\Local\Programs\Python\Python38-32\lib\site-packages\flask\app.py", line 1952, in full_dispatch_request
    rv = self.handle_user_exception(e)
  File "C:\Users\Xiaocheng Wang\AppData\Local\Programs\Python\Python38-32\lib\site-packages\flask\app.py", line 1821, in handle_user_exception
    reraise(exc_type, exc_value, tb)
  File "C:\Users\Xiaocheng Wang\AppData\Local\Programs\Python\Python38-32\lib\site-packages\flask\_compat.py", line 39, in reraise
    raise value
  File "C:\Users\Xiaocheng Wang\AppData\Local\Programs\Python\Python38-32\lib\site-packages\flask\app.py", line 1950, in full_dispatch_request
    rv = self.dispatch_request()
  File "C:\Users\Xiaocheng Wang\AppData\Local\Programs\Python\Python38-32\lib\site-packages\flask\app.py", line 1936, in dispatch_request
    return self.view_functions[rule.endpoint](**req.view_args)
  File "E:\Study\UWA\Year3\S2\CITS3200\project\SDURI-Admin-Platform\app\routes.py", line 32, in favicon
    return send_from_directory(os.path.join(app.root_path, 'static'),
NameError: name 'send_from_directory' is not defined
INFO:werkzeug:127.0.0.1 - - [14/Sep/2020 19:42:09] "[35m[1mGET /favicon.ico HTTP/1.1[0m" 500 -
INFO:werkzeug:127.0.0.1 - - [14/Sep/2020 19:42:11] "[37mGET /admin/user/ HTTP/1.1[0m" 200 -
INFO:werkzeug:127.0.0.1 - - [14/Sep/2020 19:42:11] "[37mGET /admin/static/vendor/bootstrap-daterangepicker/daterangepicker-bs3.css?v=1.3.22 HTTP/1.1[0m" 200 -
INFO:werkzeug:127.0.0.1 - - [14/Sep/2020 19:42:11] "[37mGET /admin/static/vendor/select2/select2.css?v=3.5.2 HTTP/1.1[0m" 200 -
INFO:werkzeug:127.0.0.1 - - [14/Sep/2020 19:42:11] "[37mGET /admin/static/vendor/select2/select2-bootstrap3.css?v=1.4.6 HTTP/1.1[0m" 200 -
INFO:werkzeug:127.0.0.1 - - [14/Sep/2020 19:42:11] "[37mGET /admin/static/admin/js/form.js?v=1.0.1 HTTP/1.1[0m" 200 -
INFO:werkzeug:127.0.0.1 - - [14/Sep/2020 19:42:11] "[37mGET /admin/static/admin/js/filters.js?v=1.0.0 HTTP/1.1[0m" 200 -
INFO:werkzeug:127.0.0.1 - - [14/Sep/2020 19:42:11] "[37mGET /admin/static/admin/js/actions.js?v=1.0.0 HTTP/1.1[0m" 200 -
INFO:werkzeug:127.0.0.1 - - [14/Sep/2020 19:42:11] "[37mGET /admin/static/vendor/bootstrap-daterangepicker/daterangepicker.js?v=1.3.22 HTTP/1.1[0m" 200 -
INFO:werkzeug:127.0.0.1 - - [14/Sep/2020 19:42:11] "[37mGET /admin/static/bootstrap/bootstrap3/swatch/fonts/glyphicons-halflings-regular.woff2 HTTP/1.1[0m" 200 -
ERROR:app:Exception on /favicon.ico [GET]
Traceback (most recent call last):
  File "C:\Users\Xiaocheng Wang\AppData\Local\Programs\Python\Python38-32\lib\site-packages\flask\app.py", line 2447, in wsgi_app
    response = self.full_dispatch_request()
  File "C:\Users\Xiaocheng Wang\AppData\Local\Programs\Python\Python38-32\lib\site-packages\flask\app.py", line 1952, in full_dispatch_request
    rv = self.handle_user_exception(e)
  File "C:\Users\Xiaocheng Wang\AppData\Local\Programs\Python\Python38-32\lib\site-packages\flask\app.py", line 1821, in handle_user_exception
    reraise(exc_type, exc_value, tb)
  File "C:\Users\Xiaocheng Wang\AppData\Local\Programs\Python\Python38-32\lib\site-packages\flask\_compat.py", line 39, in reraise
    raise value
  File "C:\Users\Xiaocheng Wang\AppData\Local\Programs\Python\Python38-32\lib\site-packages\flask\app.py", line 1950, in full_dispatch_request
    rv = self.dispatch_request()
  File "C:\Users\Xiaocheng Wang\AppData\Local\Programs\Python\Python38-32\lib\site-packages\flask\app.py", line 1936, in dispatch_request
    return self.view_functions[rule.endpoint](**req.view_args)
  File "E:\Study\UWA\Year3\S2\CITS3200\project\SDURI-Admin-Platform\app\routes.py", line 32, in favicon
    return send_from_directory(os.path.join(app.root_path, 'static'),
NameError: name 'send_from_directory' is not defined
INFO:werkzeug:127.0.0.1 - - [14/Sep/2020 19:42:11] "[35m[1mGET /favicon.ico HTTP/1.1[0m" 500 -
INFO:werkzeug:127.0.0.1 - - [14/Sep/2020 19:42:20] "[37mGET /admin/ HTTP/1.1[0m" 200 -
ERROR:app:Exception on /favicon.ico [GET]
Traceback (most recent call last):
  File "C:\Users\Xiaocheng Wang\AppData\Local\Programs\Python\Python38-32\lib\site-packages\flask\app.py", line 2447, in wsgi_app
    response = self.full_dispatch_request()
  File "C:\Users\Xiaocheng Wang\AppData\Local\Programs\Python\Python38-32\lib\site-packages\flask\app.py", line 1952, in full_dispatch_request
    rv = self.handle_user_exception(e)
  File "C:\Users\Xiaocheng Wang\AppData\Local\Programs\Python\Python38-32\lib\site-packages\flask\app.py", line 1821, in handle_user_exception
    reraise(exc_type, exc_value, tb)
  File "C:\Users\Xiaocheng Wang\AppData\Local\Programs\Python\Python38-32\lib\site-packages\flask\_compat.py", line 39, in reraise
    raise value
  File "C:\Users\Xiaocheng Wang\AppData\Local\Programs\Python\Python38-32\lib\site-packages\flask\app.py", line 1950, in full_dispatch_request
    rv = self.dispatch_request()
  File "C:\Users\Xiaocheng Wang\AppData\Local\Programs\Python\Python38-32\lib\site-packages\flask\app.py", line 1936, in dispatch_request
    return self.view_functions[rule.endpoint](**req.view_args)
  File "E:\Study\UWA\Year3\S2\CITS3200\project\SDURI-Admin-Platform\app\routes.py", line 32, in favicon
    return send_from_directory(os.path.join(app.root_path, 'static'),
NameError: name 'send_from_directory' is not defined
INFO:werkzeug:127.0.0.1 - - [14/Sep/2020 19:42:21] "[35m[1mGET /favicon.ico HTTP/1.1[0m" 500 -
INFO:werkzeug:127.0.0.1 - - [14/Sep/2020 19:42:22] "[37mGET /admin/user/ HTTP/1.1[0m" 200 -
ERROR:app:Exception on /favicon.ico [GET]
Traceback (most recent call last):
  File "C:\Users\Xiaocheng Wang\AppData\Local\Programs\Python\Python38-32\lib\site-packages\flask\app.py", line 2447, in wsgi_app
    response = self.full_dispatch_request()
  File "C:\Users\Xiaocheng Wang\AppData\Local\Programs\Python\Python38-32\lib\site-packages\flask\app.py", line 1952, in full_dispatch_request
    rv = self.handle_user_exception(e)
  File "C:\Users\Xiaocheng Wang\AppData\Local\Programs\Python\Python38-32\lib\site-packages\flask\app.py", line 1821, in handle_user_exception
    reraise(exc_type, exc_value, tb)
  File "C:\Users\Xiaocheng Wang\AppData\Local\Programs\Python\Python38-32\lib\site-packages\flask\_compat.py", line 39, in reraise
    raise value
  File "C:\Users\Xiaocheng Wang\AppData\Local\Programs\Python\Python38-32\lib\site-packages\flask\app.py", line 1950, in full_dispatch_request
    rv = self.dispatch_request()
  File "C:\Users\Xiaocheng Wang\AppData\Local\Programs\Python\Python38-32\lib\site-packages\flask\app.py", line 1936, in dispatch_request
    return self.view_functions[rule.endpoint](**req.view_args)
  File "E:\Study\UWA\Year3\S2\CITS3200\project\SDURI-Admin-Platform\app\routes.py", line 32, in favicon
    return send_from_directory(os.path.join(app.root_path, 'static'),
NameError: name 'send_from_directory' is not defined
INFO:werkzeug:127.0.0.1 - - [14/Sep/2020 19:42:22] "[35m[1mGET /favicon.ico HTTP/1.1[0m" 500 -
ERROR:app:Exception on /admin/student/ [GET]
Traceback (most recent call last):
  File "C:\Users\Xiaocheng Wang\AppData\Local\Programs\Python\Python38-32\lib\site-packages\sqlalchemy\engine\base.py", line 1247, in _execute_context
    self.dialect.do_execute(
  File "C:\Users\Xiaocheng Wang\AppData\Local\Programs\Python\Python38-32\lib\site-packages\sqlalchemy\engine\default.py", line 590, in do_execute
    cursor.execute(statement, parameters)
sqlite3.OperationalError: no such column: student.gender

The above exception was the direct cause of the following exception:

Traceback (most recent call last):
  File "C:\Users\Xiaocheng Wang\AppData\Local\Programs\Python\Python38-32\lib\site-packages\flask\app.py", line 2447, in wsgi_app
    response = self.full_dispatch_request()
  File "C:\Users\Xiaocheng Wang\AppData\Local\Programs\Python\Python38-32\lib\site-packages\flask\app.py", line 1952, in full_dispatch_request
    rv = self.handle_user_exception(e)
  File "C:\Users\Xiaocheng Wang\AppData\Local\Programs\Python\Python38-32\lib\site-packages\flask\app.py", line 1821, in handle_user_exception
    reraise(exc_type, exc_value, tb)
  File "C:\Users\Xiaocheng Wang\AppData\Local\Programs\Python\Python38-32\lib\site-packages\flask\_compat.py", line 39, in reraise
    raise value
  File "C:\Users\Xiaocheng Wang\AppData\Local\Programs\Python\Python38-32\lib\site-packages\flask\app.py", line 1950, in full_dispatch_request
    rv = self.dispatch_request()
  File "C:\Users\Xiaocheng Wang\AppData\Local\Programs\Python\Python38-32\lib\site-packages\flask\app.py", line 1936, in dispatch_request
    return self.view_functions[rule.endpoint](**req.view_args)
  File "C:\Users\Xiaocheng Wang\AppData\Local\Programs\Python\Python38-32\lib\site-packages\flask_admin\base.py", line 69, in inner
    return self._run_view(f, *args, **kwargs)
  File "C:\Users\Xiaocheng Wang\AppData\Local\Programs\Python\Python38-32\lib\site-packages\flask_admin\base.py", line 368, in _run_view
    return fn(self, *args, **kwargs)
  File "C:\Users\Xiaocheng Wang\AppData\Local\Programs\Python\Python38-32\lib\site-packages\flask_admin\model\base.py", line 1969, in index_view
    count, data = self.get_list(view_args.page, sort_column, view_args.sort_desc,
  File "C:\Users\Xiaocheng Wang\AppData\Local\Programs\Python\Python38-32\lib\site-packages\flask_admin\contrib\sqla\view.py", line 1079, in get_list
    query = query.all()
  File "C:\Users\Xiaocheng Wang\AppData\Local\Programs\Python\Python38-32\lib\site-packages\sqlalchemy\orm\query.py", line 3246, in all
    return list(self)
  File "C:\Users\Xiaocheng Wang\AppData\Local\Programs\Python\Python38-32\lib\site-packages\sqlalchemy\orm\query.py", line 3405, in __iter__
    return self._execute_and_instances(context)
  File "C:\Users\Xiaocheng Wang\AppData\Local\Programs\Python\Python38-32\lib\site-packages\sqlalchemy\orm\query.py", line 3430, in _execute_and_instances
    result = conn.execute(querycontext.statement, self._params)
  File "C:\Users\Xiaocheng Wang\AppData\Local\Programs\Python\Python38-32\lib\site-packages\sqlalchemy\engine\base.py", line 984, in execute
    return meth(self, multiparams, params)
  File "C:\Users\Xiaocheng Wang\AppData\Local\Programs\Python\Python38-32\lib\site-packages\sqlalchemy\sql\elements.py", line 293, in _execute_on_connection
    return connection._execute_clauseelement(self, multiparams, params)
  File "C:\Users\Xiaocheng Wang\AppData\Local\Programs\Python\Python38-32\lib\site-packages\sqlalchemy\engine\base.py", line 1097, in _execute_clauseelement
    ret = self._execute_context(
  File "C:\Users\Xiaocheng Wang\AppData\Local\Programs\Python\Python38-32\lib\site-packages\sqlalchemy\engine\base.py", line 1287, in _execute_context
    self._handle_dbapi_exception(
  File "C:\Users\Xiaocheng Wang\AppData\Local\Programs\Python\Python38-32\lib\site-packages\sqlalchemy\engine\base.py", line 1481, in _handle_dbapi_exception
    util.raise_(
  File "C:\Users\Xiaocheng Wang\AppData\Local\Programs\Python\Python38-32\lib\site-packages\sqlalchemy\util\compat.py", line 178, in raise_
    raise exception
  File "C:\Users\Xiaocheng Wang\AppData\Local\Programs\Python\Python38-32\lib\site-packages\sqlalchemy\engine\base.py", line 1247, in _execute_context
    self.dialect.do_execute(
  File "C:\Users\Xiaocheng Wang\AppData\Local\Programs\Python\Python38-32\lib\site-packages\sqlalchemy\engine\default.py", line 590, in do_execute
    cursor.execute(statement, parameters)
sqlalchemy.exc.OperationalError: (sqlite3.OperationalError) no such column: student.gender
[SQL: SELECT student.id AS student_id, student.user_id AS student_user_id, student.title AS student_title, student.gender AS student_gender, student.dob AS student_dob, student.ppname AS student_ppname, student.surname AS student_surname, student.firstname AS student_firstname, student.prefname AS student_prefname, student.charname AS student_charname, student.birth_cntry AS student_birth_cntry, student.citizen_cntry AS student_citizen_cntry, student.street_addr AS student_street_addr, student.city_addr AS student_city_addr, student.state_addr AS student_state_addr, student.postcode_addr AS student_postcode_addr, student.cntry_addr AS student_cntry_addr, student.emg_name AS student_emg_name, student.emg_rel AS student_emg_rel, student.emg_ph AS student_emg_ph, student.uni_name AS student_uni_name, student.uni_majors AS student_uni_majors, student.uni_gpa AS student_uni_gpa, student.uni_years AS student_uni_years, student.uni_awards AS student_uni_awards, student.want_eng_prog AS student_want_eng_prog, student.eng_prog_choice AS student_eng_prog_choice, student.native AS student_native, student.ielts_test_sc AS student_ielts_test_sc, student.toefl_test_sc AS student_toefl_test_sc, student.other_test_sc AS student_other_test_sc, student.eng_file AS student_eng_file, student."longQ1" AS "student_longQ1", student."longQ2" AS "student_longQ2", student."longQ3" AS "student_longQ3", student."longQ4" AS "student_longQ4", student.cv_file AS student_cv_file, student.transcr_file AS student_transcr_file, student.tuition_fee AS student_tuition_fee, user_1.id AS user_1_id, user_1.name AS user_1_name, user_1.email AS user_1_email, user_1.password AS user_1_password, user_1.role AS user_1_role 
FROM student LEFT OUTER JOIN user AS user_1 ON user_1.id = student.user_id
 LIMIT ? OFFSET ?]
[parameters: (20, 0)]
(Background on this error at: http://sqlalche.me/e/e3q8)
INFO:werkzeug:127.0.0.1 - - [14/Sep/2020 19:42:23] "[35m[1mGET /admin/student/ HTTP/1.1[0m" 500 -
ERROR:app:Exception on /favicon.ico [GET]
Traceback (most recent call last):
  File "C:\Users\Xiaocheng Wang\AppData\Local\Programs\Python\Python38-32\lib\site-packages\flask\app.py", line 2447, in wsgi_app
    response = self.full_dispatch_request()
  File "C:\Users\Xiaocheng Wang\AppData\Local\Programs\Python\Python38-32\lib\site-packages\flask\app.py", line 1952, in full_dispatch_request
    rv = self.handle_user_exception(e)
  File "C:\Users\Xiaocheng Wang\AppData\Local\Programs\Python\Python38-32\lib\site-packages\flask\app.py", line 1821, in handle_user_exception
    reraise(exc_type, exc_value, tb)
  File "C:\Users\Xiaocheng Wang\AppData\Local\Programs\Python\Python38-32\lib\site-packages\flask\_compat.py", line 39, in reraise
    raise value
  File "C:\Users\Xiaocheng Wang\AppData\Local\Programs\Python\Python38-32\lib\site-packages\flask\app.py", line 1950, in full_dispatch_request
    rv = self.dispatch_request()
  File "C:\Users\Xiaocheng Wang\AppData\Local\Programs\Python\Python38-32\lib\site-packages\flask\app.py", line 1936, in dispatch_request
    return self.view_functions[rule.endpoint](**req.view_args)
  File "E:\Study\UWA\Year3\S2\CITS3200\project\SDURI-Admin-Platform\app\routes.py", line 32, in favicon
    return send_from_directory(os.path.join(app.root_path, 'static'),
NameError: name 'send_from_directory' is not defined
INFO:werkzeug:127.0.0.1 - - [14/Sep/2020 19:42:23] "[35m[1mGET /favicon.ico HTTP/1.1[0m" 500 -
INFO:werkzeug:127.0.0.1 - - [14/Sep/2020 19:42:41] "[37mGET /project_list HTTP/1.1[0m" 200 -
INFO:werkzeug:127.0.0.1 - - [14/Sep/2020 19:42:48] "[37mGET /project_list/single_project HTTP/1.1[0m" 200 -
INFO:werkzeug:127.0.0.1 - - [14/Sep/2020 19:43:30] "[33mGET /supervisor HTTP/1.1[0m" 404 -
ERROR:app:Exception on /favicon.ico [GET]
Traceback (most recent call last):
  File "C:\Users\Xiaocheng Wang\AppData\Local\Programs\Python\Python38-32\lib\site-packages\flask\app.py", line 2447, in wsgi_app
    response = self.full_dispatch_request()
  File "C:\Users\Xiaocheng Wang\AppData\Local\Programs\Python\Python38-32\lib\site-packages\flask\app.py", line 1952, in full_dispatch_request
    rv = self.handle_user_exception(e)
  File "C:\Users\Xiaocheng Wang\AppData\Local\Programs\Python\Python38-32\lib\site-packages\flask\app.py", line 1821, in handle_user_exception
    reraise(exc_type, exc_value, tb)
  File "C:\Users\Xiaocheng Wang\AppData\Local\Programs\Python\Python38-32\lib\site-packages\flask\_compat.py", line 39, in reraise
    raise value
  File "C:\Users\Xiaocheng Wang\AppData\Local\Programs\Python\Python38-32\lib\site-packages\flask\app.py", line 1950, in full_dispatch_request
    rv = self.dispatch_request()
  File "C:\Users\Xiaocheng Wang\AppData\Local\Programs\Python\Python38-32\lib\site-packages\flask\app.py", line 1936, in dispatch_request
    return self.view_functions[rule.endpoint](**req.view_args)
  File "E:\Study\UWA\Year3\S2\CITS3200\project\SDURI-Admin-Platform\app\routes.py", line 32, in favicon
    return send_from_directory(os.path.join(app.root_path, 'static'),
NameError: name 'send_from_directory' is not defined
INFO:werkzeug:127.0.0.1 - - [14/Sep/2020 19:43:30] "[35m[1mGET /favicon.ico HTTP/1.1[0m" 500 -
INFO:werkzeug:127.0.0.1 - - [14/Sep/2020 19:43:32] "[33mGET /supervisors HTTP/1.1[0m" 404 -
ERROR:app:Exception on /favicon.ico [GET]
Traceback (most recent call last):
  File "C:\Users\Xiaocheng Wang\AppData\Local\Programs\Python\Python38-32\lib\site-packages\flask\app.py", line 2447, in wsgi_app
    response = self.full_dispatch_request()
  File "C:\Users\Xiaocheng Wang\AppData\Local\Programs\Python\Python38-32\lib\site-packages\flask\app.py", line 1952, in full_dispatch_request
    rv = self.handle_user_exception(e)
  File "C:\Users\Xiaocheng Wang\AppData\Local\Programs\Python\Python38-32\lib\site-packages\flask\app.py", line 1821, in handle_user_exception
    reraise(exc_type, exc_value, tb)
  File "C:\Users\Xiaocheng Wang\AppData\Local\Programs\Python\Python38-32\lib\site-packages\flask\_compat.py", line 39, in reraise
    raise value
  File "C:\Users\Xiaocheng Wang\AppData\Local\Programs\Python\Python38-32\lib\site-packages\flask\app.py", line 1950, in full_dispatch_request
    rv = self.dispatch_request()
  File "C:\Users\Xiaocheng Wang\AppData\Local\Programs\Python\Python38-32\lib\site-packages\flask\app.py", line 1936, in dispatch_request
    return self.view_functions[rule.endpoint](**req.view_args)
  File "E:\Study\UWA\Year3\S2\CITS3200\project\SDURI-Admin-Platform\app\routes.py", line 32, in favicon
    return send_from_directory(os.path.join(app.root_path, 'static'),
NameError: name 'send_from_directory' is not defined
INFO:werkzeug:127.0.0.1 - - [14/Sep/2020 19:43:32] "[35m[1mGET /favicon.ico HTTP/1.1[0m" 500 -
INFO:werkzeug:127.0.0.1 - - [14/Sep/2020 19:49:59] "[37mGET /admin/ HTTP/1.1[0m" 200 -
ERROR:app:Exception on /favicon.ico [GET]
Traceback (most recent call last):
  File "C:\Users\Xiaocheng Wang\AppData\Local\Programs\Python\Python38-32\lib\site-packages\flask\app.py", line 2447, in wsgi_app
    response = self.full_dispatch_request()
  File "C:\Users\Xiaocheng Wang\AppData\Local\Programs\Python\Python38-32\lib\site-packages\flask\app.py", line 1952, in full_dispatch_request
    rv = self.handle_user_exception(e)
  File "C:\Users\Xiaocheng Wang\AppData\Local\Programs\Python\Python38-32\lib\site-packages\flask\app.py", line 1821, in handle_user_exception
    reraise(exc_type, exc_value, tb)
  File "C:\Users\Xiaocheng Wang\AppData\Local\Programs\Python\Python38-32\lib\site-packages\flask\_compat.py", line 39, in reraise
    raise value
  File "C:\Users\Xiaocheng Wang\AppData\Local\Programs\Python\Python38-32\lib\site-packages\flask\app.py", line 1950, in full_dispatch_request
    rv = self.dispatch_request()
  File "C:\Users\Xiaocheng Wang\AppData\Local\Programs\Python\Python38-32\lib\site-packages\flask\app.py", line 1936, in dispatch_request
    return self.view_functions[rule.endpoint](**req.view_args)
  File "E:\Study\UWA\Year3\S2\CITS3200\project\SDURI-Admin-Platform\app\routes.py", line 32, in favicon
    return send_from_directory(os.path.join(app.root_path, 'static'),
NameError: name 'send_from_directory' is not defined
INFO:werkzeug:127.0.0.1 - - [14/Sep/2020 19:49:59] "[35m[1mGET /favicon.ico HTTP/1.1[0m" 500 -
INFO:werkzeug:127.0.0.1 - - [14/Sep/2020 19:50:01] "[37mGET /admin/user/ HTTP/1.1[0m" 200 -
ERROR:app:Exception on /favicon.ico [GET]
Traceback (most recent call last):
  File "C:\Users\Xiaocheng Wang\AppData\Local\Programs\Python\Python38-32\lib\site-packages\flask\app.py", line 2447, in wsgi_app
    response = self.full_dispatch_request()
  File "C:\Users\Xiaocheng Wang\AppData\Local\Programs\Python\Python38-32\lib\site-packages\flask\app.py", line 1952, in full_dispatch_request
    rv = self.handle_user_exception(e)
  File "C:\Users\Xiaocheng Wang\AppData\Local\Programs\Python\Python38-32\lib\site-packages\flask\app.py", line 1821, in handle_user_exception
    reraise(exc_type, exc_value, tb)
  File "C:\Users\Xiaocheng Wang\AppData\Local\Programs\Python\Python38-32\lib\site-packages\flask\_compat.py", line 39, in reraise
    raise value
  File "C:\Users\Xiaocheng Wang\AppData\Local\Programs\Python\Python38-32\lib\site-packages\flask\app.py", line 1950, in full_dispatch_request
    rv = self.dispatch_request()
  File "C:\Users\Xiaocheng Wang\AppData\Local\Programs\Python\Python38-32\lib\site-packages\flask\app.py", line 1936, in dispatch_request
    return self.view_functions[rule.endpoint](**req.view_args)
  File "E:\Study\UWA\Year3\S2\CITS3200\project\SDURI-Admin-Platform\app\routes.py", line 32, in favicon
    return send_from_directory(os.path.join(app.root_path, 'static'),
NameError: name 'send_from_directory' is not defined
INFO:werkzeug:127.0.0.1 - - [14/Sep/2020 19:50:01] "[35m[1mGET /favicon.ico HTTP/1.1[0m" 500 -
INFO:werkzeug:127.0.0.1 - - [14/Sep/2020 19:50:09] "[37mGET /admin/user/new/?url=%2Fadmin%2Fuser%2F HTTP/1.1[0m" 200 -
ERROR:app:Exception on /favicon.ico [GET]
Traceback (most recent call last):
  File "C:\Users\Xiaocheng Wang\AppData\Local\Programs\Python\Python38-32\lib\site-packages\flask\app.py", line 2447, in wsgi_app
    response = self.full_dispatch_request()
  File "C:\Users\Xiaocheng Wang\AppData\Local\Programs\Python\Python38-32\lib\site-packages\flask\app.py", line 1952, in full_dispatch_request
    rv = self.handle_user_exception(e)
  File "C:\Users\Xiaocheng Wang\AppData\Local\Programs\Python\Python38-32\lib\site-packages\flask\app.py", line 1821, in handle_user_exception
    reraise(exc_type, exc_value, tb)
  File "C:\Users\Xiaocheng Wang\AppData\Local\Programs\Python\Python38-32\lib\site-packages\flask\_compat.py", line 39, in reraise
    raise value
  File "C:\Users\Xiaocheng Wang\AppData\Local\Programs\Python\Python38-32\lib\site-packages\flask\app.py", line 1950, in full_dispatch_request
    rv = self.dispatch_request()
  File "C:\Users\Xiaocheng Wang\AppData\Local\Programs\Python\Python38-32\lib\site-packages\flask\app.py", line 1936, in dispatch_request
    return self.view_functions[rule.endpoint](**req.view_args)
  File "E:\Study\UWA\Year3\S2\CITS3200\project\SDURI-Admin-Platform\app\routes.py", line 32, in favicon
    return send_from_directory(os.path.join(app.root_path, 'static'),
NameError: name 'send_from_directory' is not defined
INFO:werkzeug:127.0.0.1 - - [14/Sep/2020 19:50:09] "[35m[1mGET /favicon.ico HTTP/1.1[0m" 500 -
INFO:werkzeug:127.0.0.1 - - [14/Sep/2020 19:50:12] "[37mGET /admin/user/ HTTP/1.1[0m" 200 -
ERROR:app:Exception on /favicon.ico [GET]
Traceback (most recent call last):
  File "C:\Users\Xiaocheng Wang\AppData\Local\Programs\Python\Python38-32\lib\site-packages\flask\app.py", line 2447, in wsgi_app
    response = self.full_dispatch_request()
  File "C:\Users\Xiaocheng Wang\AppData\Local\Programs\Python\Python38-32\lib\site-packages\flask\app.py", line 1952, in full_dispatch_request
    rv = self.handle_user_exception(e)
  File "C:\Users\Xiaocheng Wang\AppData\Local\Programs\Python\Python38-32\lib\site-packages\flask\app.py", line 1821, in handle_user_exception
    reraise(exc_type, exc_value, tb)
  File "C:\Users\Xiaocheng Wang\AppData\Local\Programs\Python\Python38-32\lib\site-packages\flask\_compat.py", line 39, in reraise
    raise value
  File "C:\Users\Xiaocheng Wang\AppData\Local\Programs\Python\Python38-32\lib\site-packages\flask\app.py", line 1950, in full_dispatch_request
    rv = self.dispatch_request()
  File "C:\Users\Xiaocheng Wang\AppData\Local\Programs\Python\Python38-32\lib\site-packages\flask\app.py", line 1936, in dispatch_request
    return self.view_functions[rule.endpoint](**req.view_args)
  File "E:\Study\UWA\Year3\S2\CITS3200\project\SDURI-Admin-Platform\app\routes.py", line 32, in favicon
    return send_from_directory(os.path.join(app.root_path, 'static'),
NameError: name 'send_from_directory' is not defined
INFO:werkzeug:127.0.0.1 - - [14/Sep/2020 19:50:12] "[35m[1mGET /favicon.ico HTTP/1.1[0m" 500 -
ERROR:app:Exception on /admin/student/ [GET]
Traceback (most recent call last):
  File "C:\Users\Xiaocheng Wang\AppData\Local\Programs\Python\Python38-32\lib\site-packages\sqlalchemy\engine\base.py", line 1247, in _execute_context
    self.dialect.do_execute(
  File "C:\Users\Xiaocheng Wang\AppData\Local\Programs\Python\Python38-32\lib\site-packages\sqlalchemy\engine\default.py", line 590, in do_execute
    cursor.execute(statement, parameters)
sqlite3.OperationalError: no such column: student.gender

The above exception was the direct cause of the following exception:

Traceback (most recent call last):
  File "C:\Users\Xiaocheng Wang\AppData\Local\Programs\Python\Python38-32\lib\site-packages\flask\app.py", line 2447, in wsgi_app
    response = self.full_dispatch_request()
  File "C:\Users\Xiaocheng Wang\AppData\Local\Programs\Python\Python38-32\lib\site-packages\flask\app.py", line 1952, in full_dispatch_request
    rv = self.handle_user_exception(e)
  File "C:\Users\Xiaocheng Wang\AppData\Local\Programs\Python\Python38-32\lib\site-packages\flask\app.py", line 1821, in handle_user_exception
    reraise(exc_type, exc_value, tb)
  File "C:\Users\Xiaocheng Wang\AppData\Local\Programs\Python\Python38-32\lib\site-packages\flask\_compat.py", line 39, in reraise
    raise value
  File "C:\Users\Xiaocheng Wang\AppData\Local\Programs\Python\Python38-32\lib\site-packages\flask\app.py", line 1950, in full_dispatch_request
    rv = self.dispatch_request()
  File "C:\Users\Xiaocheng Wang\AppData\Local\Programs\Python\Python38-32\lib\site-packages\flask\app.py", line 1936, in dispatch_request
    return self.view_functions[rule.endpoint](**req.view_args)
  File "C:\Users\Xiaocheng Wang\AppData\Local\Programs\Python\Python38-32\lib\site-packages\flask_admin\base.py", line 69, in inner
    return self._run_view(f, *args, **kwargs)
  File "C:\Users\Xiaocheng Wang\AppData\Local\Programs\Python\Python38-32\lib\site-packages\flask_admin\base.py", line 368, in _run_view
    return fn(self, *args, **kwargs)
  File "C:\Users\Xiaocheng Wang\AppData\Local\Programs\Python\Python38-32\lib\site-packages\flask_admin\model\base.py", line 1969, in index_view
    count, data = self.get_list(view_args.page, sort_column, view_args.sort_desc,
  File "C:\Users\Xiaocheng Wang\AppData\Local\Programs\Python\Python38-32\lib\site-packages\flask_admin\contrib\sqla\view.py", line 1079, in get_list
    query = query.all()
  File "C:\Users\Xiaocheng Wang\AppData\Local\Programs\Python\Python38-32\lib\site-packages\sqlalchemy\orm\query.py", line 3246, in all
    return list(self)
  File "C:\Users\Xiaocheng Wang\AppData\Local\Programs\Python\Python38-32\lib\site-packages\sqlalchemy\orm\query.py", line 3405, in __iter__
    return self._execute_and_instances(context)
  File "C:\Users\Xiaocheng Wang\AppData\Local\Programs\Python\Python38-32\lib\site-packages\sqlalchemy\orm\query.py", line 3430, in _execute_and_instances
    result = conn.execute(querycontext.statement, self._params)
  File "C:\Users\Xiaocheng Wang\AppData\Local\Programs\Python\Python38-32\lib\site-packages\sqlalchemy\engine\base.py", line 984, in execute
    return meth(self, multiparams, params)
  File "C:\Users\Xiaocheng Wang\AppData\Local\Programs\Python\Python38-32\lib\site-packages\sqlalchemy\sql\elements.py", line 293, in _execute_on_connection
    return connection._execute_clauseelement(self, multiparams, params)
  File "C:\Users\Xiaocheng Wang\AppData\Local\Programs\Python\Python38-32\lib\site-packages\sqlalchemy\engine\base.py", line 1097, in _execute_clauseelement
    ret = self._execute_context(
  File "C:\Users\Xiaocheng Wang\AppData\Local\Programs\Python\Python38-32\lib\site-packages\sqlalchemy\engine\base.py", line 1287, in _execute_context
    self._handle_dbapi_exception(
  File "C:\Users\Xiaocheng Wang\AppData\Local\Programs\Python\Python38-32\lib\site-packages\sqlalchemy\engine\base.py", line 1481, in _handle_dbapi_exception
    util.raise_(
  File "C:\Users\Xiaocheng Wang\AppData\Local\Programs\Python\Python38-32\lib\site-packages\sqlalchemy\util\compat.py", line 178, in raise_
    raise exception
  File "C:\Users\Xiaocheng Wang\AppData\Local\Programs\Python\Python38-32\lib\site-packages\sqlalchemy\engine\base.py", line 1247, in _execute_context
    self.dialect.do_execute(
  File "C:\Users\Xiaocheng Wang\AppData\Local\Programs\Python\Python38-32\lib\site-packages\sqlalchemy\engine\default.py", line 590, in do_execute
    cursor.execute(statement, parameters)
sqlalchemy.exc.OperationalError: (sqlite3.OperationalError) no such column: student.gender
[SQL: SELECT student.id AS student_id, student.user_id AS student_user_id, student.title AS student_title, student.gender AS student_gender, student.dob AS student_dob, student.ppname AS student_ppname, student.surname AS student_surname, student.firstname AS student_firstname, student.prefname AS student_prefname, student.charname AS student_charname, student.birth_cntry AS student_birth_cntry, student.citizen_cntry AS student_citizen_cntry, student.street_addr AS student_street_addr, student.city_addr AS student_city_addr, student.state_addr AS student_state_addr, student.postcode_addr AS student_postcode_addr, student.cntry_addr AS student_cntry_addr, student.emg_name AS student_emg_name, student.emg_rel AS student_emg_rel, student.emg_ph AS student_emg_ph, student.uni_name AS student_uni_name, student.uni_majors AS student_uni_majors, student.uni_gpa AS student_uni_gpa, student.uni_years AS student_uni_years, student.uni_awards AS student_uni_awards, student.want_eng_prog AS student_want_eng_prog, student.eng_prog_choice AS student_eng_prog_choice, student.native AS student_native, student.ielts_test_sc AS student_ielts_test_sc, student.toefl_test_sc AS student_toefl_test_sc, student.other_test_sc AS student_other_test_sc, student.eng_file AS student_eng_file, student."longQ1" AS "student_longQ1", student."longQ2" AS "student_longQ2", student."longQ3" AS "student_longQ3", student."longQ4" AS "student_longQ4", student.cv_file AS student_cv_file, student.transcr_file AS student_transcr_file, student.tuition_fee AS student_tuition_fee, user_1.id AS user_1_id, user_1.name AS user_1_name, user_1.email AS user_1_email, user_1.password AS user_1_password, user_1.role AS user_1_role 
FROM student LEFT OUTER JOIN user AS user_1 ON user_1.id = student.user_id
 LIMIT ? OFFSET ?]
[parameters: (20, 0)]
(Background on this error at: http://sqlalche.me/e/e3q8)
INFO:werkzeug:127.0.0.1 - - [14/Sep/2020 19:50:13] "[35m[1mGET /admin/student/ HTTP/1.1[0m" 500 -
ERROR:app:Exception on /favicon.ico [GET]
Traceback (most recent call last):
  File "C:\Users\Xiaocheng Wang\AppData\Local\Programs\Python\Python38-32\lib\site-packages\flask\app.py", line 2447, in wsgi_app
    response = self.full_dispatch_request()
  File "C:\Users\Xiaocheng Wang\AppData\Local\Programs\Python\Python38-32\lib\site-packages\flask\app.py", line 1952, in full_dispatch_request
    rv = self.handle_user_exception(e)
  File "C:\Users\Xiaocheng Wang\AppData\Local\Programs\Python\Python38-32\lib\site-packages\flask\app.py", line 1821, in handle_user_exception
    reraise(exc_type, exc_value, tb)
  File "C:\Users\Xiaocheng Wang\AppData\Local\Programs\Python\Python38-32\lib\site-packages\flask\_compat.py", line 39, in reraise
    raise value
  File "C:\Users\Xiaocheng Wang\AppData\Local\Programs\Python\Python38-32\lib\site-packages\flask\app.py", line 1950, in full_dispatch_request
    rv = self.dispatch_request()
  File "C:\Users\Xiaocheng Wang\AppData\Local\Programs\Python\Python38-32\lib\site-packages\flask\app.py", line 1936, in dispatch_request
    return self.view_functions[rule.endpoint](**req.view_args)
  File "E:\Study\UWA\Year3\S2\CITS3200\project\SDURI-Admin-Platform\app\routes.py", line 32, in favicon
    return send_from_directory(os.path.join(app.root_path, 'static'),
NameError: name 'send_from_directory' is not defined
INFO:werkzeug:127.0.0.1 - - [14/Sep/2020 19:50:13] "[35m[1mGET /favicon.ico HTTP/1.1[0m" 500 -
ERROR:app:Exception on /favicon.ico [GET]
Traceback (most recent call last):
  File "C:\Users\Xiaocheng Wang\AppData\Local\Programs\Python\Python38-32\lib\site-packages\flask\app.py", line 2447, in wsgi_app
    response = self.full_dispatch_request()
  File "C:\Users\Xiaocheng Wang\AppData\Local\Programs\Python\Python38-32\lib\site-packages\flask\app.py", line 1952, in full_dispatch_request
    rv = self.handle_user_exception(e)
  File "C:\Users\Xiaocheng Wang\AppData\Local\Programs\Python\Python38-32\lib\site-packages\flask\app.py", line 1821, in handle_user_exception
    reraise(exc_type, exc_value, tb)
  File "C:\Users\Xiaocheng Wang\AppData\Local\Programs\Python\Python38-32\lib\site-packages\flask\_compat.py", line 39, in reraise
    raise value
  File "C:\Users\Xiaocheng Wang\AppData\Local\Programs\Python\Python38-32\lib\site-packages\flask\app.py", line 1950, in full_dispatch_request
    rv = self.dispatch_request()
  File "C:\Users\Xiaocheng Wang\AppData\Local\Programs\Python\Python38-32\lib\site-packages\flask\app.py", line 1936, in dispatch_request
    return self.view_functions[rule.endpoint](**req.view_args)
  File "E:\Study\UWA\Year3\S2\CITS3200\project\SDURI-Admin-Platform\app\routes.py", line 32, in favicon
    return send_from_directory(os.path.join(app.root_path, 'static'),
NameError: name 'send_from_directory' is not defined
INFO:werkzeug:127.0.0.1 - - [14/Sep/2020 19:50:14] "[35m[1mGET /favicon.ico HTTP/1.1[0m" 500 -
ERROR:app:Exception on /admin/supervisor/ [GET]
Traceback (most recent call last):
  File "C:\Users\Xiaocheng Wang\AppData\Local\Programs\Python\Python38-32\lib\site-packages\sqlalchemy\engine\base.py", line 1247, in _execute_context
    self.dialect.do_execute(
  File "C:\Users\Xiaocheng Wang\AppData\Local\Programs\Python\Python38-32\lib\site-packages\sqlalchemy\engine\default.py", line 590, in do_execute
    cursor.execute(statement, parameters)
sqlite3.OperationalError: no such table: supervisor

The above exception was the direct cause of the following exception:

Traceback (most recent call last):
  File "C:\Users\Xiaocheng Wang\AppData\Local\Programs\Python\Python38-32\lib\site-packages\flask\app.py", line 2447, in wsgi_app
    response = self.full_dispatch_request()
  File "C:\Users\Xiaocheng Wang\AppData\Local\Programs\Python\Python38-32\lib\site-packages\flask\app.py", line 1952, in full_dispatch_request
    rv = self.handle_user_exception(e)
  File "C:\Users\Xiaocheng Wang\AppData\Local\Programs\Python\Python38-32\lib\site-packages\flask\app.py", line 1821, in handle_user_exception
    reraise(exc_type, exc_value, tb)
  File "C:\Users\Xiaocheng Wang\AppData\Local\Programs\Python\Python38-32\lib\site-packages\flask\_compat.py", line 39, in reraise
    raise value
  File "C:\Users\Xiaocheng Wang\AppData\Local\Programs\Python\Python38-32\lib\site-packages\flask\app.py", line 1950, in full_dispatch_request
    rv = self.dispatch_request()
  File "C:\Users\Xiaocheng Wang\AppData\Local\Programs\Python\Python38-32\lib\site-packages\flask\app.py", line 1936, in dispatch_request
    return self.view_functions[rule.endpoint](**req.view_args)
  File "C:\Users\Xiaocheng Wang\AppData\Local\Programs\Python\Python38-32\lib\site-packages\flask_admin\base.py", line 69, in inner
    return self._run_view(f, *args, **kwargs)
  File "C:\Users\Xiaocheng Wang\AppData\Local\Programs\Python\Python38-32\lib\site-packages\flask_admin\base.py", line 368, in _run_view
    return fn(self, *args, **kwargs)
  File "C:\Users\Xiaocheng Wang\AppData\Local\Programs\Python\Python38-32\lib\site-packages\flask_admin\model\base.py", line 1969, in index_view
    count, data = self.get_list(view_args.page, sort_column, view_args.sort_desc,
  File "C:\Users\Xiaocheng Wang\AppData\Local\Programs\Python\Python38-32\lib\site-packages\flask_admin\contrib\sqla\view.py", line 1065, in get_list
    count = count_query.scalar() if count_query else None
  File "C:\Users\Xiaocheng Wang\AppData\Local\Programs\Python\Python38-32\lib\site-packages\sqlalchemy\orm\query.py", line 3393, in scalar
    ret = self.one()
  File "C:\Users\Xiaocheng Wang\AppData\Local\Programs\Python\Python38-32\lib\site-packages\sqlalchemy\orm\query.py", line 3360, in one
    ret = self.one_or_none()
  File "C:\Users\Xiaocheng Wang\AppData\Local\Programs\Python\Python38-32\lib\site-packages\sqlalchemy\orm\query.py", line 3329, in one_or_none
    ret = list(self)
  File "C:\Users\Xiaocheng Wang\AppData\Local\Programs\Python\Python38-32\lib\site-packages\sqlalchemy\orm\query.py", line 3405, in __iter__
    return self._execute_and_instances(context)
  File "C:\Users\Xiaocheng Wang\AppData\Local\Programs\Python\Python38-32\lib\site-packages\sqlalchemy\orm\query.py", line 3430, in _execute_and_instances
    result = conn.execute(querycontext.statement, self._params)
  File "C:\Users\Xiaocheng Wang\AppData\Local\Programs\Python\Python38-32\lib\site-packages\sqlalchemy\engine\base.py", line 984, in execute
    return meth(self, multiparams, params)
  File "C:\Users\Xiaocheng Wang\AppData\Local\Programs\Python\Python38-32\lib\site-packages\sqlalchemy\sql\elements.py", line 293, in _execute_on_connection
    return connection._execute_clauseelement(self, multiparams, params)
  File "C:\Users\Xiaocheng Wang\AppData\Local\Programs\Python\Python38-32\lib\site-packages\sqlalchemy\engine\base.py", line 1097, in _execute_clauseelement
    ret = self._execute_context(
  File "C:\Users\Xiaocheng Wang\AppData\Local\Programs\Python\Python38-32\lib\site-packages\sqlalchemy\engine\base.py", line 1287, in _execute_context
    self._handle_dbapi_exception(
  File "C:\Users\Xiaocheng Wang\AppData\Local\Programs\Python\Python38-32\lib\site-packages\sqlalchemy\engine\base.py", line 1481, in _handle_dbapi_exception
    util.raise_(
  File "C:\Users\Xiaocheng Wang\AppData\Local\Programs\Python\Python38-32\lib\site-packages\sqlalchemy\util\compat.py", line 178, in raise_
    raise exception
  File "C:\Users\Xiaocheng Wang\AppData\Local\Programs\Python\Python38-32\lib\site-packages\sqlalchemy\engine\base.py", line 1247, in _execute_context
    self.dialect.do_execute(
  File "C:\Users\Xiaocheng Wang\AppData\Local\Programs\Python\Python38-32\lib\site-packages\sqlalchemy\engine\default.py", line 590, in do_execute
    cursor.execute(statement, parameters)
sqlalchemy.exc.OperationalError: (sqlite3.OperationalError) no such table: supervisor
[SQL: SELECT count(?) AS count_1 
FROM supervisor]
[parameters: ('*',)]
(Background on this error at: http://sqlalche.me/e/e3q8)
INFO:werkzeug:127.0.0.1 - - [14/Sep/2020 19:50:16] "[35m[1mGET /admin/supervisor/ HTTP/1.1[0m" 500 -
ERROR:app:Exception on /favicon.ico [GET]
Traceback (most recent call last):
  File "C:\Users\Xiaocheng Wang\AppData\Local\Programs\Python\Python38-32\lib\site-packages\flask\app.py", line 2447, in wsgi_app
    response = self.full_dispatch_request()
  File "C:\Users\Xiaocheng Wang\AppData\Local\Programs\Python\Python38-32\lib\site-packages\flask\app.py", line 1952, in full_dispatch_request
    rv = self.handle_user_exception(e)
  File "C:\Users\Xiaocheng Wang\AppData\Local\Programs\Python\Python38-32\lib\site-packages\flask\app.py", line 1821, in handle_user_exception
    reraise(exc_type, exc_value, tb)
  File "C:\Users\Xiaocheng Wang\AppData\Local\Programs\Python\Python38-32\lib\site-packages\flask\_compat.py", line 39, in reraise
    raise value
  File "C:\Users\Xiaocheng Wang\AppData\Local\Programs\Python\Python38-32\lib\site-packages\flask\app.py", line 1950, in full_dispatch_request
    rv = self.dispatch_request()
  File "C:\Users\Xiaocheng Wang\AppData\Local\Programs\Python\Python38-32\lib\site-packages\flask\app.py", line 1936, in dispatch_request
    return self.view_functions[rule.endpoint](**req.view_args)
  File "E:\Study\UWA\Year3\S2\CITS3200\project\SDURI-Admin-Platform\app\routes.py", line 32, in favicon
    return send_from_directory(os.path.join(app.root_path, 'static'),
NameError: name 'send_from_directory' is not defined
INFO:werkzeug:127.0.0.1 - - [14/Sep/2020 19:50:16] "[35m[1mGET /favicon.ico HTTP/1.1[0m" 500 -
ERROR:app:Exception on /favicon.ico [GET]
Traceback (most recent call last):
  File "C:\Users\Xiaocheng Wang\AppData\Local\Programs\Python\Python38-32\lib\site-packages\flask\app.py", line 2447, in wsgi_app
    response = self.full_dispatch_request()
  File "C:\Users\Xiaocheng Wang\AppData\Local\Programs\Python\Python38-32\lib\site-packages\flask\app.py", line 1952, in full_dispatch_request
    rv = self.handle_user_exception(e)
  File "C:\Users\Xiaocheng Wang\AppData\Local\Programs\Python\Python38-32\lib\site-packages\flask\app.py", line 1821, in handle_user_exception
    reraise(exc_type, exc_value, tb)
  File "C:\Users\Xiaocheng Wang\AppData\Local\Programs\Python\Python38-32\lib\site-packages\flask\_compat.py", line 39, in reraise
    raise value
  File "C:\Users\Xiaocheng Wang\AppData\Local\Programs\Python\Python38-32\lib\site-packages\flask\app.py", line 1950, in full_dispatch_request
    rv = self.dispatch_request()
  File "C:\Users\Xiaocheng Wang\AppData\Local\Programs\Python\Python38-32\lib\site-packages\flask\app.py", line 1936, in dispatch_request
    return self.view_functions[rule.endpoint](**req.view_args)
  File "E:\Study\UWA\Year3\S2\CITS3200\project\SDURI-Admin-Platform\app\routes.py", line 32, in favicon
    return send_from_directory(os.path.join(app.root_path, 'static'),
NameError: name 'send_from_directory' is not defined
INFO:werkzeug:127.0.0.1 - - [14/Sep/2020 19:50:17] "[35m[1mGET /favicon.ico HTTP/1.1[0m" 500 -
INFO:werkzeug:127.0.0.1 - - [14/Sep/2020 19:52:25] "[37mGET /project_list HTTP/1.1[0m" 200 -
INFO:werkzeug:127.0.0.1 - - [14/Sep/2020 19:53:29] "[37mGET /project_list HTTP/1.1[0m" 200 -
INFO:werkzeug:127.0.0.1 - - [14/Sep/2020 19:53:29] "[37mGET /static/css/style.css HTTP/1.1[0m" 200 -
INFO:werkzeug:127.0.0.1 - - [14/Sep/2020 19:53:29] "[37mGET /static/images/uwa_logo.png HTTP/1.1[0m" 200 -
INFO:werkzeug:127.0.0.1 - - [14/Sep/2020 19:53:31] "[37mGET /static/images/favicon.ico HTTP/1.1[0m" 200 -
INFO:werkzeug:127.0.0.1 - - [14/Sep/2020 19:54:50] "[37mGET /admin/ HTTP/1.1[0m" 200 -
ERROR:app:Exception on /favicon.ico [GET]
Traceback (most recent call last):
  File "C:\Users\Xiaocheng Wang\AppData\Local\Programs\Python\Python38-32\lib\site-packages\flask\app.py", line 2447, in wsgi_app
    response = self.full_dispatch_request()
  File "C:\Users\Xiaocheng Wang\AppData\Local\Programs\Python\Python38-32\lib\site-packages\flask\app.py", line 1952, in full_dispatch_request
    rv = self.handle_user_exception(e)
  File "C:\Users\Xiaocheng Wang\AppData\Local\Programs\Python\Python38-32\lib\site-packages\flask\app.py", line 1821, in handle_user_exception
    reraise(exc_type, exc_value, tb)
  File "C:\Users\Xiaocheng Wang\AppData\Local\Programs\Python\Python38-32\lib\site-packages\flask\_compat.py", line 39, in reraise
    raise value
  File "C:\Users\Xiaocheng Wang\AppData\Local\Programs\Python\Python38-32\lib\site-packages\flask\app.py", line 1950, in full_dispatch_request
    rv = self.dispatch_request()
  File "C:\Users\Xiaocheng Wang\AppData\Local\Programs\Python\Python38-32\lib\site-packages\flask\app.py", line 1936, in dispatch_request
    return self.view_functions[rule.endpoint](**req.view_args)
  File "E:\Study\UWA\Year3\S2\CITS3200\project\SDURI-Admin-Platform\app\routes.py", line 32, in favicon
    return send_from_directory(os.path.join(app.root_path, 'static'),
NameError: name 'send_from_directory' is not defined
INFO:werkzeug:127.0.0.1 - - [14/Sep/2020 19:54:51] "[35m[1mGET /favicon.ico HTTP/1.1[0m" 500 -
INFO:werkzeug:127.0.0.1 - - [14/Sep/2020 19:54:52] "[37mGET /admin/user/ HTTP/1.1[0m" 200 -
ERROR:app:Exception on /favicon.ico [GET]
Traceback (most recent call last):
  File "C:\Users\Xiaocheng Wang\AppData\Local\Programs\Python\Python38-32\lib\site-packages\flask\app.py", line 2447, in wsgi_app
    response = self.full_dispatch_request()
  File "C:\Users\Xiaocheng Wang\AppData\Local\Programs\Python\Python38-32\lib\site-packages\flask\app.py", line 1952, in full_dispatch_request
    rv = self.handle_user_exception(e)
  File "C:\Users\Xiaocheng Wang\AppData\Local\Programs\Python\Python38-32\lib\site-packages\flask\app.py", line 1821, in handle_user_exception
    reraise(exc_type, exc_value, tb)
  File "C:\Users\Xiaocheng Wang\AppData\Local\Programs\Python\Python38-32\lib\site-packages\flask\_compat.py", line 39, in reraise
    raise value
  File "C:\Users\Xiaocheng Wang\AppData\Local\Programs\Python\Python38-32\lib\site-packages\flask\app.py", line 1950, in full_dispatch_request
    rv = self.dispatch_request()
  File "C:\Users\Xiaocheng Wang\AppData\Local\Programs\Python\Python38-32\lib\site-packages\flask\app.py", line 1936, in dispatch_request
    return self.view_functions[rule.endpoint](**req.view_args)
  File "E:\Study\UWA\Year3\S2\CITS3200\project\SDURI-Admin-Platform\app\routes.py", line 32, in favicon
    return send_from_directory(os.path.join(app.root_path, 'static'),
NameError: name 'send_from_directory' is not defined
INFO:werkzeug:127.0.0.1 - - [14/Sep/2020 19:54:54] "[35m[1mGET /favicon.ico HTTP/1.1[0m" 500 -
ERROR:app:Exception on /admin/student/ [GET]
Traceback (most recent call last):
  File "C:\Users\Xiaocheng Wang\AppData\Local\Programs\Python\Python38-32\lib\site-packages\sqlalchemy\engine\base.py", line 1247, in _execute_context
    self.dialect.do_execute(
  File "C:\Users\Xiaocheng Wang\AppData\Local\Programs\Python\Python38-32\lib\site-packages\sqlalchemy\engine\default.py", line 590, in do_execute
    cursor.execute(statement, parameters)
sqlite3.OperationalError: no such column: student.gender

The above exception was the direct cause of the following exception:

Traceback (most recent call last):
  File "C:\Users\Xiaocheng Wang\AppData\Local\Programs\Python\Python38-32\lib\site-packages\flask\app.py", line 2447, in wsgi_app
    response = self.full_dispatch_request()
  File "C:\Users\Xiaocheng Wang\AppData\Local\Programs\Python\Python38-32\lib\site-packages\flask\app.py", line 1952, in full_dispatch_request
    rv = self.handle_user_exception(e)
  File "C:\Users\Xiaocheng Wang\AppData\Local\Programs\Python\Python38-32\lib\site-packages\flask\app.py", line 1821, in handle_user_exception
    reraise(exc_type, exc_value, tb)
  File "C:\Users\Xiaocheng Wang\AppData\Local\Programs\Python\Python38-32\lib\site-packages\flask\_compat.py", line 39, in reraise
    raise value
  File "C:\Users\Xiaocheng Wang\AppData\Local\Programs\Python\Python38-32\lib\site-packages\flask\app.py", line 1950, in full_dispatch_request
    rv = self.dispatch_request()
  File "C:\Users\Xiaocheng Wang\AppData\Local\Programs\Python\Python38-32\lib\site-packages\flask\app.py", line 1936, in dispatch_request
    return self.view_functions[rule.endpoint](**req.view_args)
  File "C:\Users\Xiaocheng Wang\AppData\Local\Programs\Python\Python38-32\lib\site-packages\flask_admin\base.py", line 69, in inner
    return self._run_view(f, *args, **kwargs)
  File "C:\Users\Xiaocheng Wang\AppData\Local\Programs\Python\Python38-32\lib\site-packages\flask_admin\base.py", line 368, in _run_view
    return fn(self, *args, **kwargs)
  File "C:\Users\Xiaocheng Wang\AppData\Local\Programs\Python\Python38-32\lib\site-packages\flask_admin\model\base.py", line 1969, in index_view
    count, data = self.get_list(view_args.page, sort_column, view_args.sort_desc,
  File "C:\Users\Xiaocheng Wang\AppData\Local\Programs\Python\Python38-32\lib\site-packages\flask_admin\contrib\sqla\view.py", line 1079, in get_list
    query = query.all()
  File "C:\Users\Xiaocheng Wang\AppData\Local\Programs\Python\Python38-32\lib\site-packages\sqlalchemy\orm\query.py", line 3246, in all
    return list(self)
  File "C:\Users\Xiaocheng Wang\AppData\Local\Programs\Python\Python38-32\lib\site-packages\sqlalchemy\orm\query.py", line 3405, in __iter__
    return self._execute_and_instances(context)
  File "C:\Users\Xiaocheng Wang\AppData\Local\Programs\Python\Python38-32\lib\site-packages\sqlalchemy\orm\query.py", line 3430, in _execute_and_instances
    result = conn.execute(querycontext.statement, self._params)
  File "C:\Users\Xiaocheng Wang\AppData\Local\Programs\Python\Python38-32\lib\site-packages\sqlalchemy\engine\base.py", line 984, in execute
    return meth(self, multiparams, params)
  File "C:\Users\Xiaocheng Wang\AppData\Local\Programs\Python\Python38-32\lib\site-packages\sqlalchemy\sql\elements.py", line 293, in _execute_on_connection
    return connection._execute_clauseelement(self, multiparams, params)
  File "C:\Users\Xiaocheng Wang\AppData\Local\Programs\Python\Python38-32\lib\site-packages\sqlalchemy\engine\base.py", line 1097, in _execute_clauseelement
    ret = self._execute_context(
  File "C:\Users\Xiaocheng Wang\AppData\Local\Programs\Python\Python38-32\lib\site-packages\sqlalchemy\engine\base.py", line 1287, in _execute_context
    self._handle_dbapi_exception(
  File "C:\Users\Xiaocheng Wang\AppData\Local\Programs\Python\Python38-32\lib\site-packages\sqlalchemy\engine\base.py", line 1481, in _handle_dbapi_exception
    util.raise_(
  File "C:\Users\Xiaocheng Wang\AppData\Local\Programs\Python\Python38-32\lib\site-packages\sqlalchemy\util\compat.py", line 178, in raise_
    raise exception
  File "C:\Users\Xiaocheng Wang\AppData\Local\Programs\Python\Python38-32\lib\site-packages\sqlalchemy\engine\base.py", line 1247, in _execute_context
    self.dialect.do_execute(
  File "C:\Users\Xiaocheng Wang\AppData\Local\Programs\Python\Python38-32\lib\site-packages\sqlalchemy\engine\default.py", line 590, in do_execute
    cursor.execute(statement, parameters)
sqlalchemy.exc.OperationalError: (sqlite3.OperationalError) no such column: student.gender
[SQL: SELECT student.id AS student_id, student.user_id AS student_user_id, student.title AS student_title, student.gender AS student_gender, student.dob AS student_dob, student.ppname AS student_ppname, student.surname AS student_surname, student.firstname AS student_firstname, student.prefname AS student_prefname, student.charname AS student_charname, student.birth_cntry AS student_birth_cntry, student.citizen_cntry AS student_citizen_cntry, student.street_addr AS student_street_addr, student.city_addr AS student_city_addr, student.state_addr AS student_state_addr, student.postcode_addr AS student_postcode_addr, student.cntry_addr AS student_cntry_addr, student.emg_name AS student_emg_name, student.emg_rel AS student_emg_rel, student.emg_ph AS student_emg_ph, student.uni_name AS student_uni_name, student.uni_majors AS student_uni_majors, student.uni_gpa AS student_uni_gpa, student.uni_years AS student_uni_years, student.uni_awards AS student_uni_awards, student.want_eng_prog AS student_want_eng_prog, student.eng_prog_choice AS student_eng_prog_choice, student.native AS student_native, student.ielts_test_sc AS student_ielts_test_sc, student.toefl_test_sc AS student_toefl_test_sc, student.other_test_sc AS student_other_test_sc, student.eng_file AS student_eng_file, student."longQ1" AS "student_longQ1", student."longQ2" AS "student_longQ2", student."longQ3" AS "student_longQ3", student."longQ4" AS "student_longQ4", student.cv_file AS student_cv_file, student.transcr_file AS student_transcr_file, student.tuition_fee AS student_tuition_fee, user_1.id AS user_1_id, user_1.name AS user_1_name, user_1.email AS user_1_email, user_1.password AS user_1_password, user_1.role AS user_1_role 
FROM student LEFT OUTER JOIN user AS user_1 ON user_1.id = student.user_id
 LIMIT ? OFFSET ?]
[parameters: (20, 0)]
(Background on this error at: http://sqlalche.me/e/e3q8)
INFO:werkzeug:127.0.0.1 - - [14/Sep/2020 19:55:00] "[35m[1mGET /admin/student/ HTTP/1.1[0m" 500 -
ERROR:app:Exception on /favicon.ico [GET]
Traceback (most recent call last):
  File "C:\Users\Xiaocheng Wang\AppData\Local\Programs\Python\Python38-32\lib\site-packages\flask\app.py", line 2447, in wsgi_app
    response = self.full_dispatch_request()
  File "C:\Users\Xiaocheng Wang\AppData\Local\Programs\Python\Python38-32\lib\site-packages\flask\app.py", line 1952, in full_dispatch_request
    rv = self.handle_user_exception(e)
  File "C:\Users\Xiaocheng Wang\AppData\Local\Programs\Python\Python38-32\lib\site-packages\flask\app.py", line 1821, in handle_user_exception
    reraise(exc_type, exc_value, tb)
  File "C:\Users\Xiaocheng Wang\AppData\Local\Programs\Python\Python38-32\lib\site-packages\flask\_compat.py", line 39, in reraise
    raise value
  File "C:\Users\Xiaocheng Wang\AppData\Local\Programs\Python\Python38-32\lib\site-packages\flask\app.py", line 1950, in full_dispatch_request
    rv = self.dispatch_request()
  File "C:\Users\Xiaocheng Wang\AppData\Local\Programs\Python\Python38-32\lib\site-packages\flask\app.py", line 1936, in dispatch_request
    return self.view_functions[rule.endpoint](**req.view_args)
  File "E:\Study\UWA\Year3\S2\CITS3200\project\SDURI-Admin-Platform\app\routes.py", line 32, in favicon
    return send_from_directory(os.path.join(app.root_path, 'static'),
NameError: name 'send_from_directory' is not defined
INFO:werkzeug:127.0.0.1 - - [14/Sep/2020 19:55:00] "[35m[1mGET /favicon.ico HTTP/1.1[0m" 500 -
