INFO:werkzeug: * Running on http://127.0.0.1:5000/ (Press CTRL+C to quit)
INFO:werkzeug:127.0.0.1 - - [25/Sep/2020 10:52:20] "[37mGET / HTTP/1.1[0m" 200 -
INFO:werkzeug:127.0.0.1 - - [25/Sep/2020 10:52:20] "[36mGET /static/css/style.css HTTP/1.1[0m" 304 -
INFO:werkzeug:127.0.0.1 - - [25/Sep/2020 10:52:20] "[36mGET /static/images/uwa_logo.png HTTP/1.1[0m" 304 -
INFO:werkzeug:127.0.0.1 - - [25/Sep/2020 10:52:33] "[37mGET /login HTTP/1.1[0m" 200 -
INFO:werkzeug:127.0.0.1 - - [25/Sep/2020 10:52:39] "[32mPOST /login HTTP/1.1[0m" 302 -
INFO:werkzeug:127.0.0.1 - - [25/Sep/2020 10:52:39] "[37mGET /supervisor/Cheng2 HTTP/1.1[0m" 200 -
INFO:werkzeug:127.0.0.1 - - [25/Sep/2020 10:52:43] "[32mGET /admin HTTP/1.1[0m" 308 -
INFO:werkzeug:127.0.0.1 - - [25/Sep/2020 10:52:43] "[37mGET /admin/ HTTP/1.1[0m" 200 -
INFO:werkzeug:127.0.0.1 - - [25/Sep/2020 10:52:43] "[36mGET /admin/static/admin/css/bootstrap3/submenu.css HTTP/1.1[0m" 304 -
INFO:werkzeug:127.0.0.1 - - [25/Sep/2020 10:52:43] "[36mGET /admin/static/admin/css/bootstrap3/admin.css?v=1.1.1 HTTP/1.1[0m" 304 -
INFO:werkzeug:127.0.0.1 - - [25/Sep/2020 10:52:43] "[36mGET /admin/static/bootstrap/bootstrap3/swatch/default/bootstrap.min.css?v=3.3.5 HTTP/1.1[0m" 304 -
INFO:werkzeug:127.0.0.1 - - [25/Sep/2020 10:52:43] "[36mGET /admin/static/bootstrap/bootstrap3/css/bootstrap-theme.min.css?v=3.3.5 HTTP/1.1[0m" 304 -
INFO:werkzeug:127.0.0.1 - - [25/Sep/2020 10:52:43] "[37mGET /admin/static/admin/js/helpers.js?v=1.0.0 HTTP/1.1[0m" 200 -
INFO:werkzeug:127.0.0.1 - - [25/Sep/2020 10:52:43] "[37mGET /admin/static/bootstrap/bootstrap3/js/bootstrap.min.js?v=3.3.5 HTTP/1.1[0m" 200 -
INFO:werkzeug:127.0.0.1 - - [25/Sep/2020 10:52:43] "[37mGET /admin/static/vendor/moment.min.js?v=2.22.2 HTTP/1.1[0m" 200 -
INFO:werkzeug:127.0.0.1 - - [25/Sep/2020 10:52:43] "[37mGET /admin/static/vendor/select2/select2.min.js?v=3.5.2 HTTP/1.1[0m" 200 -
INFO:werkzeug:127.0.0.1 - - [25/Sep/2020 10:52:43] "[37mGET /admin/static/vendor/jquery.min.js?v=3.3.1 HTTP/1.1[0m" 200 -
ERROR:app:Exception on /favicon.ico [GET]
Traceback (most recent call last):
  File "c:\users\xiaocheng wang\appdata\local\programs\python\python38-32\lib\site-packages\flask\app.py", line 2447, in wsgi_app
    response = self.full_dispatch_request()
  File "c:\users\xiaocheng wang\appdata\local\programs\python\python38-32\lib\site-packages\flask\app.py", line 1952, in full_dispatch_request
    rv = self.handle_user_exception(e)
  File "c:\users\xiaocheng wang\appdata\local\programs\python\python38-32\lib\site-packages\flask\app.py", line 1821, in handle_user_exception
    reraise(exc_type, exc_value, tb)
  File "c:\users\xiaocheng wang\appdata\local\programs\python\python38-32\lib\site-packages\flask\_compat.py", line 39, in reraise
    raise value
  File "c:\users\xiaocheng wang\appdata\local\programs\python\python38-32\lib\site-packages\flask\app.py", line 1950, in full_dispatch_request
    rv = self.dispatch_request()
  File "c:\users\xiaocheng wang\appdata\local\programs\python\python38-32\lib\site-packages\flask\app.py", line 1936, in dispatch_request
    return self.view_functions[rule.endpoint](**req.view_args)
  File "E:\Study\UWA\Year3\S2\CITS3200\project\SDURI-Admin-Platform\app\routes.py", line 32, in favicon
    return send_from_directory(os.path.join(app.root_path, 'static'),
NameError: name 'send_from_directory' is not defined
INFO:werkzeug:127.0.0.1 - - [25/Sep/2020 10:52:43] "[35m[1mGET /favicon.ico HTTP/1.1[0m" 500 -
INFO:werkzeug:127.0.0.1 - - [25/Sep/2020 10:52:46] "[37mGET /admin/project/ HTTP/1.1[0m" 200 -
INFO:werkzeug:127.0.0.1 - - [25/Sep/2020 10:52:46] "[36mGET /admin/static/vendor/select2/select2.css?v=3.5.2 HTTP/1.1[0m" 304 -
INFO:werkzeug:127.0.0.1 - - [25/Sep/2020 10:52:46] "[36mGET /admin/static/vendor/select2/select2-bootstrap3.css?v=1.4.6 HTTP/1.1[0m" 304 -
INFO:werkzeug:127.0.0.1 - - [25/Sep/2020 10:52:46] "[36mGET /admin/static/vendor/bootstrap-daterangepicker/daterangepicker-bs3.css?v=1.3.22 HTTP/1.1[0m" 304 -
INFO:werkzeug:127.0.0.1 - - [25/Sep/2020 10:52:46] "[37mGET /admin/static/admin/js/form.js?v=1.0.1 HTTP/1.1[0m" 200 -
INFO:werkzeug:127.0.0.1 - - [25/Sep/2020 10:52:46] "[37mGET /admin/static/admin/js/actions.js?v=1.0.0 HTTP/1.1[0m" 200 -
INFO:werkzeug:127.0.0.1 - - [25/Sep/2020 10:52:46] "[37mGET /admin/static/admin/js/filters.js?v=1.0.0 HTTP/1.1[0m" 200 -
INFO:werkzeug:127.0.0.1 - - [25/Sep/2020 10:52:46] "[37mGET /admin/static/vendor/bootstrap-daterangepicker/daterangepicker.js?v=1.3.22 HTTP/1.1[0m" 200 -
INFO:werkzeug:127.0.0.1 - - [25/Sep/2020 10:52:46] "[37mGET /admin/static/bootstrap/bootstrap3/swatch/fonts/glyphicons-halflings-regular.woff2 HTTP/1.1[0m" 200 -
ERROR:app:Exception on /favicon.ico [GET]
Traceback (most recent call last):
  File "c:\users\xiaocheng wang\appdata\local\programs\python\python38-32\lib\site-packages\flask\app.py", line 2447, in wsgi_app
    response = self.full_dispatch_request()
  File "c:\users\xiaocheng wang\appdata\local\programs\python\python38-32\lib\site-packages\flask\app.py", line 1952, in full_dispatch_request
    rv = self.handle_user_exception(e)
  File "c:\users\xiaocheng wang\appdata\local\programs\python\python38-32\lib\site-packages\flask\app.py", line 1821, in handle_user_exception
    reraise(exc_type, exc_value, tb)
  File "c:\users\xiaocheng wang\appdata\local\programs\python\python38-32\lib\site-packages\flask\_compat.py", line 39, in reraise
    raise value
  File "c:\users\xiaocheng wang\appdata\local\programs\python\python38-32\lib\site-packages\flask\app.py", line 1950, in full_dispatch_request
    rv = self.dispatch_request()
  File "c:\users\xiaocheng wang\appdata\local\programs\python\python38-32\lib\site-packages\flask\app.py", line 1936, in dispatch_request
    return self.view_functions[rule.endpoint](**req.view_args)
  File "E:\Study\UWA\Year3\S2\CITS3200\project\SDURI-Admin-Platform\app\routes.py", line 32, in favicon
    return send_from_directory(os.path.join(app.root_path, 'static'),
NameError: name 'send_from_directory' is not defined
INFO:werkzeug:127.0.0.1 - - [25/Sep/2020 10:52:46] "[35m[1mGET /favicon.ico HTTP/1.1[0m" 500 -
INFO:werkzeug:127.0.0.1 - - [25/Sep/2020 10:53:59] "[32mPOST /admin/project/delete/ HTTP/1.1[0m" 302 -
INFO:werkzeug:127.0.0.1 - - [25/Sep/2020 10:53:59] "[37mGET /admin/project/ HTTP/1.1[0m" 200 -
ERROR:app:Exception on /favicon.ico [GET]
Traceback (most recent call last):
  File "c:\users\xiaocheng wang\appdata\local\programs\python\python38-32\lib\site-packages\flask\app.py", line 2447, in wsgi_app
    response = self.full_dispatch_request()
  File "c:\users\xiaocheng wang\appdata\local\programs\python\python38-32\lib\site-packages\flask\app.py", line 1952, in full_dispatch_request
    rv = self.handle_user_exception(e)
  File "c:\users\xiaocheng wang\appdata\local\programs\python\python38-32\lib\site-packages\flask\app.py", line 1821, in handle_user_exception
    reraise(exc_type, exc_value, tb)
  File "c:\users\xiaocheng wang\appdata\local\programs\python\python38-32\lib\site-packages\flask\_compat.py", line 39, in reraise
    raise value
  File "c:\users\xiaocheng wang\appdata\local\programs\python\python38-32\lib\site-packages\flask\app.py", line 1950, in full_dispatch_request
    rv = self.dispatch_request()
  File "c:\users\xiaocheng wang\appdata\local\programs\python\python38-32\lib\site-packages\flask\app.py", line 1936, in dispatch_request
    return self.view_functions[rule.endpoint](**req.view_args)
  File "E:\Study\UWA\Year3\S2\CITS3200\project\SDURI-Admin-Platform\app\routes.py", line 32, in favicon
    return send_from_directory(os.path.join(app.root_path, 'static'),
NameError: name 'send_from_directory' is not defined
INFO:werkzeug:127.0.0.1 - - [25/Sep/2020 10:53:59] "[35m[1mGET /favicon.ico HTTP/1.1[0m" 500 -
INFO:werkzeug:127.0.0.1 - - [25/Sep/2020 10:57:33] "[37mGET /admin/project/ HTTP/1.1[0m" 200 -
ERROR:app:Exception on /favicon.ico [GET]
Traceback (most recent call last):
  File "c:\users\xiaocheng wang\appdata\local\programs\python\python38-32\lib\site-packages\flask\app.py", line 2447, in wsgi_app
    response = self.full_dispatch_request()
  File "c:\users\xiaocheng wang\appdata\local\programs\python\python38-32\lib\site-packages\flask\app.py", line 1952, in full_dispatch_request
    rv = self.handle_user_exception(e)
  File "c:\users\xiaocheng wang\appdata\local\programs\python\python38-32\lib\site-packages\flask\app.py", line 1821, in handle_user_exception
    reraise(exc_type, exc_value, tb)
  File "c:\users\xiaocheng wang\appdata\local\programs\python\python38-32\lib\site-packages\flask\_compat.py", line 39, in reraise
    raise value
  File "c:\users\xiaocheng wang\appdata\local\programs\python\python38-32\lib\site-packages\flask\app.py", line 1950, in full_dispatch_request
    rv = self.dispatch_request()
  File "c:\users\xiaocheng wang\appdata\local\programs\python\python38-32\lib\site-packages\flask\app.py", line 1936, in dispatch_request
    return self.view_functions[rule.endpoint](**req.view_args)
  File "E:\Study\UWA\Year3\S2\CITS3200\project\SDURI-Admin-Platform\app\routes.py", line 32, in favicon
    return send_from_directory(os.path.join(app.root_path, 'static'),
NameError: name 'send_from_directory' is not defined
INFO:werkzeug:127.0.0.1 - - [25/Sep/2020 10:57:33] "[35m[1mGET /favicon.ico HTTP/1.1[0m" 500 -
INFO:werkzeug:127.0.0.1 - - [25/Sep/2020 10:57:37] "[37mGET /add-project/Cheng2 HTTP/1.1[0m" 200 -
INFO:werkzeug:127.0.0.1 - - [25/Sep/2020 11:13:16] "[32mGET /index HTTP/1.1[0m" 302 -
INFO:werkzeug:127.0.0.1 - - [25/Sep/2020 11:13:16] "[37mGET /supervisor/Cheng2 HTTP/1.1[0m" 200 -
INFO:werkzeug:127.0.0.1 - - [25/Sep/2020 11:23:22] "[37mGET /admin/project/ HTTP/1.1[0m" 200 -
ERROR:app:Exception on /favicon.ico [GET]
Traceback (most recent call last):
  File "c:\users\xiaocheng wang\appdata\local\programs\python\python38-32\lib\site-packages\flask\app.py", line 2447, in wsgi_app
    response = self.full_dispatch_request()
  File "c:\users\xiaocheng wang\appdata\local\programs\python\python38-32\lib\site-packages\flask\app.py", line 1952, in full_dispatch_request
    rv = self.handle_user_exception(e)
  File "c:\users\xiaocheng wang\appdata\local\programs\python\python38-32\lib\site-packages\flask\app.py", line 1821, in handle_user_exception
    reraise(exc_type, exc_value, tb)
  File "c:\users\xiaocheng wang\appdata\local\programs\python\python38-32\lib\site-packages\flask\_compat.py", line 39, in reraise
    raise value
  File "c:\users\xiaocheng wang\appdata\local\programs\python\python38-32\lib\site-packages\flask\app.py", line 1950, in full_dispatch_request
    rv = self.dispatch_request()
  File "c:\users\xiaocheng wang\appdata\local\programs\python\python38-32\lib\site-packages\flask\app.py", line 1936, in dispatch_request
    return self.view_functions[rule.endpoint](**req.view_args)
  File "E:\Study\UWA\Year3\S2\CITS3200\project\SDURI-Admin-Platform\app\routes.py", line 32, in favicon
    return send_from_directory(os.path.join(app.root_path, 'static'),
NameError: name 'send_from_directory' is not defined
INFO:werkzeug:127.0.0.1 - - [25/Sep/2020 11:23:22] "[35m[1mGET /favicon.ico HTTP/1.1[0m" 500 -
INFO:werkzeug:127.0.0.1 - - [25/Sep/2020 11:23:32] "[32mPOST /admin/project/delete/ HTTP/1.1[0m" 302 -
INFO:werkzeug:127.0.0.1 - - [25/Sep/2020 11:23:32] "[37mGET /admin/project/ HTTP/1.1[0m" 200 -
ERROR:app:Exception on /favicon.ico [GET]
Traceback (most recent call last):
  File "c:\users\xiaocheng wang\appdata\local\programs\python\python38-32\lib\site-packages\flask\app.py", line 2447, in wsgi_app
    response = self.full_dispatch_request()
  File "c:\users\xiaocheng wang\appdata\local\programs\python\python38-32\lib\site-packages\flask\app.py", line 1952, in full_dispatch_request
    rv = self.handle_user_exception(e)
  File "c:\users\xiaocheng wang\appdata\local\programs\python\python38-32\lib\site-packages\flask\app.py", line 1821, in handle_user_exception
    reraise(exc_type, exc_value, tb)
  File "c:\users\xiaocheng wang\appdata\local\programs\python\python38-32\lib\site-packages\flask\_compat.py", line 39, in reraise
    raise value
  File "c:\users\xiaocheng wang\appdata\local\programs\python\python38-32\lib\site-packages\flask\app.py", line 1950, in full_dispatch_request
    rv = self.dispatch_request()
  File "c:\users\xiaocheng wang\appdata\local\programs\python\python38-32\lib\site-packages\flask\app.py", line 1936, in dispatch_request
    return self.view_functions[rule.endpoint](**req.view_args)
  File "E:\Study\UWA\Year3\S2\CITS3200\project\SDURI-Admin-Platform\app\routes.py", line 32, in favicon
    return send_from_directory(os.path.join(app.root_path, 'static'),
NameError: name 'send_from_directory' is not defined
INFO:werkzeug:127.0.0.1 - - [25/Sep/2020 11:23:32] "[35m[1mGET /favicon.ico HTTP/1.1[0m" 500 -
INFO:werkzeug:127.0.0.1 - - [25/Sep/2020 11:23:41] "[37mGET /admin/project/ HTTP/1.1[0m" 200 -
ERROR:app:Exception on /favicon.ico [GET]
Traceback (most recent call last):
  File "c:\users\xiaocheng wang\appdata\local\programs\python\python38-32\lib\site-packages\flask\app.py", line 2447, in wsgi_app
    response = self.full_dispatch_request()
  File "c:\users\xiaocheng wang\appdata\local\programs\python\python38-32\lib\site-packages\flask\app.py", line 1952, in full_dispatch_request
    rv = self.handle_user_exception(e)
  File "c:\users\xiaocheng wang\appdata\local\programs\python\python38-32\lib\site-packages\flask\app.py", line 1821, in handle_user_exception
    reraise(exc_type, exc_value, tb)
  File "c:\users\xiaocheng wang\appdata\local\programs\python\python38-32\lib\site-packages\flask\_compat.py", line 39, in reraise
    raise value
  File "c:\users\xiaocheng wang\appdata\local\programs\python\python38-32\lib\site-packages\flask\app.py", line 1950, in full_dispatch_request
    rv = self.dispatch_request()
  File "c:\users\xiaocheng wang\appdata\local\programs\python\python38-32\lib\site-packages\flask\app.py", line 1936, in dispatch_request
    return self.view_functions[rule.endpoint](**req.view_args)
  File "E:\Study\UWA\Year3\S2\CITS3200\project\SDURI-Admin-Platform\app\routes.py", line 32, in favicon
    return send_from_directory(os.path.join(app.root_path, 'static'),
NameError: name 'send_from_directory' is not defined
INFO:werkzeug:127.0.0.1 - - [25/Sep/2020 11:23:41] "[35m[1mGET /favicon.ico HTTP/1.1[0m" 500 -
INFO:werkzeug:127.0.0.1 - - [25/Sep/2020 11:32:49] "[37mGET /add-project/Cheng2 HTTP/1.1[0m" 200 -
INFO:werkzeug:127.0.0.1 - - [25/Sep/2020 11:33:03] "[37mPOST /add-project/Cheng2 HTTP/1.1[0m" 200 -
INFO:werkzeug:127.0.0.1 - - [25/Sep/2020 11:33:12] "[37mGET /admin/project/ HTTP/1.1[0m" 200 -
ERROR:app:Exception on /favicon.ico [GET]
Traceback (most recent call last):
  File "c:\users\xiaocheng wang\appdata\local\programs\python\python38-32\lib\site-packages\flask\app.py", line 2447, in wsgi_app
    response = self.full_dispatch_request()
  File "c:\users\xiaocheng wang\appdata\local\programs\python\python38-32\lib\site-packages\flask\app.py", line 1952, in full_dispatch_request
    rv = self.handle_user_exception(e)
  File "c:\users\xiaocheng wang\appdata\local\programs\python\python38-32\lib\site-packages\flask\app.py", line 1821, in handle_user_exception
    reraise(exc_type, exc_value, tb)
  File "c:\users\xiaocheng wang\appdata\local\programs\python\python38-32\lib\site-packages\flask\_compat.py", line 39, in reraise
    raise value
  File "c:\users\xiaocheng wang\appdata\local\programs\python\python38-32\lib\site-packages\flask\app.py", line 1950, in full_dispatch_request
    rv = self.dispatch_request()
  File "c:\users\xiaocheng wang\appdata\local\programs\python\python38-32\lib\site-packages\flask\app.py", line 1936, in dispatch_request
    return self.view_functions[rule.endpoint](**req.view_args)
  File "E:\Study\UWA\Year3\S2\CITS3200\project\SDURI-Admin-Platform\app\routes.py", line 32, in favicon
    return send_from_directory(os.path.join(app.root_path, 'static'),
NameError: name 'send_from_directory' is not defined
INFO:werkzeug:127.0.0.1 - - [25/Sep/2020 11:33:13] "[35m[1mGET /favicon.ico HTTP/1.1[0m" 500 -
INFO:werkzeug:127.0.0.1 - - [25/Sep/2020 11:34:50] "[37mGET /admin/user/ HTTP/1.1[0m" 200 -
ERROR:app:Exception on /favicon.ico [GET]
Traceback (most recent call last):
  File "c:\users\xiaocheng wang\appdata\local\programs\python\python38-32\lib\site-packages\flask\app.py", line 2447, in wsgi_app
    response = self.full_dispatch_request()
  File "c:\users\xiaocheng wang\appdata\local\programs\python\python38-32\lib\site-packages\flask\app.py", line 1952, in full_dispatch_request
    rv = self.handle_user_exception(e)
  File "c:\users\xiaocheng wang\appdata\local\programs\python\python38-32\lib\site-packages\flask\app.py", line 1821, in handle_user_exception
    reraise(exc_type, exc_value, tb)
  File "c:\users\xiaocheng wang\appdata\local\programs\python\python38-32\lib\site-packages\flask\_compat.py", line 39, in reraise
    raise value
  File "c:\users\xiaocheng wang\appdata\local\programs\python\python38-32\lib\site-packages\flask\app.py", line 1950, in full_dispatch_request
    rv = self.dispatch_request()
  File "c:\users\xiaocheng wang\appdata\local\programs\python\python38-32\lib\site-packages\flask\app.py", line 1936, in dispatch_request
    return self.view_functions[rule.endpoint](**req.view_args)
  File "E:\Study\UWA\Year3\S2\CITS3200\project\SDURI-Admin-Platform\app\routes.py", line 32, in favicon
    return send_from_directory(os.path.join(app.root_path, 'static'),
NameError: name 'send_from_directory' is not defined
INFO:werkzeug:127.0.0.1 - - [25/Sep/2020 11:34:51] "[35m[1mGET /favicon.ico HTTP/1.1[0m" 500 -
INFO:werkzeug:127.0.0.1 - - [25/Sep/2020 11:34:54] "[37mGET /admin/student/ HTTP/1.1[0m" 200 -
ERROR:app:Exception on /favicon.ico [GET]
Traceback (most recent call last):
  File "c:\users\xiaocheng wang\appdata\local\programs\python\python38-32\lib\site-packages\flask\app.py", line 2447, in wsgi_app
    response = self.full_dispatch_request()
  File "c:\users\xiaocheng wang\appdata\local\programs\python\python38-32\lib\site-packages\flask\app.py", line 1952, in full_dispatch_request
    rv = self.handle_user_exception(e)
  File "c:\users\xiaocheng wang\appdata\local\programs\python\python38-32\lib\site-packages\flask\app.py", line 1821, in handle_user_exception
    reraise(exc_type, exc_value, tb)
  File "c:\users\xiaocheng wang\appdata\local\programs\python\python38-32\lib\site-packages\flask\_compat.py", line 39, in reraise
    raise value
  File "c:\users\xiaocheng wang\appdata\local\programs\python\python38-32\lib\site-packages\flask\app.py", line 1950, in full_dispatch_request
    rv = self.dispatch_request()
  File "c:\users\xiaocheng wang\appdata\local\programs\python\python38-32\lib\site-packages\flask\app.py", line 1936, in dispatch_request
    return self.view_functions[rule.endpoint](**req.view_args)
  File "E:\Study\UWA\Year3\S2\CITS3200\project\SDURI-Admin-Platform\app\routes.py", line 32, in favicon
    return send_from_directory(os.path.join(app.root_path, 'static'),
NameError: name 'send_from_directory' is not defined
INFO:werkzeug:127.0.0.1 - - [25/Sep/2020 11:34:54] "[35m[1mGET /favicon.ico HTTP/1.1[0m" 500 -
INFO:werkzeug:127.0.0.1 - - [25/Sep/2020 11:34:55] "[37mGET /admin/user/ HTTP/1.1[0m" 200 -
ERROR:app:Exception on /favicon.ico [GET]
Traceback (most recent call last):
  File "c:\users\xiaocheng wang\appdata\local\programs\python\python38-32\lib\site-packages\flask\app.py", line 2447, in wsgi_app
    response = self.full_dispatch_request()
  File "c:\users\xiaocheng wang\appdata\local\programs\python\python38-32\lib\site-packages\flask\app.py", line 1952, in full_dispatch_request
    rv = self.handle_user_exception(e)
  File "c:\users\xiaocheng wang\appdata\local\programs\python\python38-32\lib\site-packages\flask\app.py", line 1821, in handle_user_exception
    reraise(exc_type, exc_value, tb)
  File "c:\users\xiaocheng wang\appdata\local\programs\python\python38-32\lib\site-packages\flask\_compat.py", line 39, in reraise
    raise value
  File "c:\users\xiaocheng wang\appdata\local\programs\python\python38-32\lib\site-packages\flask\app.py", line 1950, in full_dispatch_request
    rv = self.dispatch_request()
  File "c:\users\xiaocheng wang\appdata\local\programs\python\python38-32\lib\site-packages\flask\app.py", line 1936, in dispatch_request
    return self.view_functions[rule.endpoint](**req.view_args)
  File "E:\Study\UWA\Year3\S2\CITS3200\project\SDURI-Admin-Platform\app\routes.py", line 32, in favicon
    return send_from_directory(os.path.join(app.root_path, 'static'),
NameError: name 'send_from_directory' is not defined
INFO:werkzeug:127.0.0.1 - - [25/Sep/2020 11:34:55] "[35m[1mGET /favicon.ico HTTP/1.1[0m" 500 -
INFO:werkzeug:127.0.0.1 - - [25/Sep/2020 11:35:11] "[37mGET /admin/supervisor/ HTTP/1.1[0m" 200 -
ERROR:app:Exception on /favicon.ico [GET]
Traceback (most recent call last):
  File "c:\users\xiaocheng wang\appdata\local\programs\python\python38-32\lib\site-packages\flask\app.py", line 2447, in wsgi_app
    response = self.full_dispatch_request()
  File "c:\users\xiaocheng wang\appdata\local\programs\python\python38-32\lib\site-packages\flask\app.py", line 1952, in full_dispatch_request
    rv = self.handle_user_exception(e)
  File "c:\users\xiaocheng wang\appdata\local\programs\python\python38-32\lib\site-packages\flask\app.py", line 1821, in handle_user_exception
    reraise(exc_type, exc_value, tb)
  File "c:\users\xiaocheng wang\appdata\local\programs\python\python38-32\lib\site-packages\flask\_compat.py", line 39, in reraise
    raise value
  File "c:\users\xiaocheng wang\appdata\local\programs\python\python38-32\lib\site-packages\flask\app.py", line 1950, in full_dispatch_request
    rv = self.dispatch_request()
  File "c:\users\xiaocheng wang\appdata\local\programs\python\python38-32\lib\site-packages\flask\app.py", line 1936, in dispatch_request
    return self.view_functions[rule.endpoint](**req.view_args)
  File "E:\Study\UWA\Year3\S2\CITS3200\project\SDURI-Admin-Platform\app\routes.py", line 32, in favicon
    return send_from_directory(os.path.join(app.root_path, 'static'),
NameError: name 'send_from_directory' is not defined
INFO:werkzeug:127.0.0.1 - - [25/Sep/2020 11:35:11] "[35m[1mGET /favicon.ico HTTP/1.1[0m" 500 -
INFO:werkzeug:127.0.0.1 - - [25/Sep/2020 11:35:23] "[37mGET /admin/project/ HTTP/1.1[0m" 200 -
ERROR:app:Exception on /favicon.ico [GET]
Traceback (most recent call last):
  File "c:\users\xiaocheng wang\appdata\local\programs\python\python38-32\lib\site-packages\flask\app.py", line 2447, in wsgi_app
    response = self.full_dispatch_request()
  File "c:\users\xiaocheng wang\appdata\local\programs\python\python38-32\lib\site-packages\flask\app.py", line 1952, in full_dispatch_request
    rv = self.handle_user_exception(e)
  File "c:\users\xiaocheng wang\appdata\local\programs\python\python38-32\lib\site-packages\flask\app.py", line 1821, in handle_user_exception
    reraise(exc_type, exc_value, tb)
  File "c:\users\xiaocheng wang\appdata\local\programs\python\python38-32\lib\site-packages\flask\_compat.py", line 39, in reraise
    raise value
  File "c:\users\xiaocheng wang\appdata\local\programs\python\python38-32\lib\site-packages\flask\app.py", line 1950, in full_dispatch_request
    rv = self.dispatch_request()
  File "c:\users\xiaocheng wang\appdata\local\programs\python\python38-32\lib\site-packages\flask\app.py", line 1936, in dispatch_request
    return self.view_functions[rule.endpoint](**req.view_args)
  File "E:\Study\UWA\Year3\S2\CITS3200\project\SDURI-Admin-Platform\app\routes.py", line 32, in favicon
    return send_from_directory(os.path.join(app.root_path, 'static'),
NameError: name 'send_from_directory' is not defined
INFO:werkzeug:127.0.0.1 - - [25/Sep/2020 11:35:23] "[35m[1mGET /favicon.ico HTTP/1.1[0m" 500 -
INFO:werkzeug:127.0.0.1 - - [25/Sep/2020 11:37:03] "[32mGET /index HTTP/1.1[0m" 302 -
INFO:werkzeug:127.0.0.1 - - [25/Sep/2020 11:37:03] "[37mGET /supervisor/Cheng2 HTTP/1.1[0m" 200 -
INFO:werkzeug:127.0.0.1 - - [25/Sep/2020 11:38:19] "[37mGET /add-project/Cheng2 HTTP/1.1[0m" 200 -
INFO:werkzeug:127.0.0.1 - - [25/Sep/2020 11:39:33] "[32mGET /index HTTP/1.1[0m" 302 -
INFO:werkzeug:127.0.0.1 - - [25/Sep/2020 11:39:33] "[37mGET /supervisor/Cheng2 HTTP/1.1[0m" 200 -
