INFO:werkzeug: * Running on http://127.0.0.1:5000/ (Press CTRL+C to quit)
INFO:werkzeug:127.0.0.1 - - [06/Oct/2020 00:51:54] "[37mGET / HTTP/1.1[0m" 200 -
INFO:werkzeug:127.0.0.1 - - [06/Oct/2020 00:51:56] "[37mGET /login HTTP/1.1[0m" 200 -
ERROR:app:Exception on /login [POST]
Traceback (most recent call last):
  File "c:\users\xiaocheng wang\appdata\local\programs\python\python38-32\lib\site-packages\sqlalchemy\engine\base.py", line 1247, in _execute_context
    self.dialect.do_execute(
  File "c:\users\xiaocheng wang\appdata\local\programs\python\python38-32\lib\site-packages\sqlalchemy\engine\default.py", line 590, in do_execute
    cursor.execute(statement, parameters)
sqlite3.OperationalError: no such column: user.confirmed

The above exception was the direct cause of the following exception:

Traceback (most recent call last):
  File "c:\users\xiaocheng wang\appdata\local\programs\python\python38-32\lib\site-packages\flask\app.py", line 2447, in wsgi_app
    response = self.full_dispatch_request()
  File "c:\users\xiaocheng wang\appdata\local\programs\python\python38-32\lib\site-packages\flask\app.py", line 1952, in full_dispatch_request
    rv = self.handle_user_exception(e)
  File "c:\users\xiaocheng wang\appdata\local\programs\python\python38-32\lib\site-packages\flask\app.py", line 1821, in handle_user_exception
    reraise(exc_type, exc_value, tb)
  File "c:\users\xiaocheng wang\appdata\local\programs\python\python38-32\lib\site-packages\flask\_compat.py", line 39, in reraise
    raise value
  File "c:\users\xiaocheng wang\appdata\local\programs\python\python38-32\lib\site-packages\flask\app.py", line 1950, in full_dispatch_request
    rv = self.dispatch_request()
  File "c:\users\xiaocheng wang\appdata\local\programs\python\python38-32\lib\site-packages\flask\app.py", line 1936, in dispatch_request
    return self.view_functions[rule.endpoint](**req.view_args)
  File "E:\Study\UWA\Year3\S2\CITS3200\project\SDURI-Admin-Platform\app\routes.py", line 48, in login
    user = User.query.filter_by(email=form.email.data).first()
  File "c:\users\xiaocheng wang\appdata\local\programs\python\python38-32\lib\site-packages\sqlalchemy\orm\query.py", line 3300, in first
    ret = list(self[0:1])
  File "c:\users\xiaocheng wang\appdata\local\programs\python\python38-32\lib\site-packages\sqlalchemy\orm\query.py", line 3078, in __getitem__
    return list(res)
  File "c:\users\xiaocheng wang\appdata\local\programs\python\python38-32\lib\site-packages\sqlalchemy\orm\query.py", line 3405, in __iter__
    return self._execute_and_instances(context)
  File "c:\users\xiaocheng wang\appdata\local\programs\python\python38-32\lib\site-packages\sqlalchemy\orm\query.py", line 3430, in _execute_and_instances
    result = conn.execute(querycontext.statement, self._params)
  File "c:\users\xiaocheng wang\appdata\local\programs\python\python38-32\lib\site-packages\sqlalchemy\engine\base.py", line 984, in execute
    return meth(self, multiparams, params)
  File "c:\users\xiaocheng wang\appdata\local\programs\python\python38-32\lib\site-packages\sqlalchemy\sql\elements.py", line 293, in _execute_on_connection
    return connection._execute_clauseelement(self, multiparams, params)
  File "c:\users\xiaocheng wang\appdata\local\programs\python\python38-32\lib\site-packages\sqlalchemy\engine\base.py", line 1097, in _execute_clauseelement
    ret = self._execute_context(
  File "c:\users\xiaocheng wang\appdata\local\programs\python\python38-32\lib\site-packages\sqlalchemy\engine\base.py", line 1287, in _execute_context
    self._handle_dbapi_exception(
  File "c:\users\xiaocheng wang\appdata\local\programs\python\python38-32\lib\site-packages\sqlalchemy\engine\base.py", line 1481, in _handle_dbapi_exception
    util.raise_(
  File "c:\users\xiaocheng wang\appdata\local\programs\python\python38-32\lib\site-packages\sqlalchemy\util\compat.py", line 178, in raise_
    raise exception
  File "c:\users\xiaocheng wang\appdata\local\programs\python\python38-32\lib\site-packages\sqlalchemy\engine\base.py", line 1247, in _execute_context
    self.dialect.do_execute(
  File "c:\users\xiaocheng wang\appdata\local\programs\python\python38-32\lib\site-packages\sqlalchemy\engine\default.py", line 590, in do_execute
    cursor.execute(statement, parameters)
sqlalchemy.exc.OperationalError: (sqlite3.OperationalError) no such column: user.confirmed
[SQL: SELECT user.id AS user_id, user.name AS user_name, user.email AS user_email, user.confirmed AS user_confirmed, user.password AS user_password, user.role AS user_role, user.registered_on AS user_registered_on, user.confirmed_on AS user_confirmed_on, user.password_reset_token AS user_password_reset_token 
FROM user 
WHERE user.email = ?
 LIMIT ? OFFSET ?]
[parameters: ('super2@uwa.edu.au', 1, 0)]
(Background on this error at: http://sqlalche.me/e/e3q8)
INFO:werkzeug:127.0.0.1 - - [06/Oct/2020 00:51:59] "[35m[1mPOST /login HTTP/1.1[0m" 500 -
INFO:werkzeug:127.0.0.1 - - [06/Oct/2020 00:52:01] "[37mGET /login HTTP/1.1[0m" 200 -
INFO:werkzeug:127.0.0.1 - - [06/Oct/2020 00:52:03] "[37mPOST /login HTTP/1.1[0m" 200 -
ERROR:app:Exception on /login [POST]
Traceback (most recent call last):
  File "c:\users\xiaocheng wang\appdata\local\programs\python\python38-32\lib\site-packages\sqlalchemy\engine\base.py", line 1247, in _execute_context
    self.dialect.do_execute(
  File "c:\users\xiaocheng wang\appdata\local\programs\python\python38-32\lib\site-packages\sqlalchemy\engine\default.py", line 590, in do_execute
    cursor.execute(statement, parameters)
sqlite3.OperationalError: no such column: user.confirmed

The above exception was the direct cause of the following exception:

Traceback (most recent call last):
  File "c:\users\xiaocheng wang\appdata\local\programs\python\python38-32\lib\site-packages\flask\app.py", line 2447, in wsgi_app
    response = self.full_dispatch_request()
  File "c:\users\xiaocheng wang\appdata\local\programs\python\python38-32\lib\site-packages\flask\app.py", line 1952, in full_dispatch_request
    rv = self.handle_user_exception(e)
  File "c:\users\xiaocheng wang\appdata\local\programs\python\python38-32\lib\site-packages\flask\app.py", line 1821, in handle_user_exception
    reraise(exc_type, exc_value, tb)
  File "c:\users\xiaocheng wang\appdata\local\programs\python\python38-32\lib\site-packages\flask\_compat.py", line 39, in reraise
    raise value
  File "c:\users\xiaocheng wang\appdata\local\programs\python\python38-32\lib\site-packages\flask\app.py", line 1950, in full_dispatch_request
    rv = self.dispatch_request()
  File "c:\users\xiaocheng wang\appdata\local\programs\python\python38-32\lib\site-packages\flask\app.py", line 1936, in dispatch_request
    return self.view_functions[rule.endpoint](**req.view_args)
  File "E:\Study\UWA\Year3\S2\CITS3200\project\SDURI-Admin-Platform\app\routes.py", line 48, in login
    user = User.query.filter_by(email=form.email.data).first()
  File "c:\users\xiaocheng wang\appdata\local\programs\python\python38-32\lib\site-packages\sqlalchemy\orm\query.py", line 3300, in first
    ret = list(self[0:1])
  File "c:\users\xiaocheng wang\appdata\local\programs\python\python38-32\lib\site-packages\sqlalchemy\orm\query.py", line 3078, in __getitem__
    return list(res)
  File "c:\users\xiaocheng wang\appdata\local\programs\python\python38-32\lib\site-packages\sqlalchemy\orm\query.py", line 3405, in __iter__
    return self._execute_and_instances(context)
  File "c:\users\xiaocheng wang\appdata\local\programs\python\python38-32\lib\site-packages\sqlalchemy\orm\query.py", line 3430, in _execute_and_instances
    result = conn.execute(querycontext.statement, self._params)
  File "c:\users\xiaocheng wang\appdata\local\programs\python\python38-32\lib\site-packages\sqlalchemy\engine\base.py", line 984, in execute
    return meth(self, multiparams, params)
  File "c:\users\xiaocheng wang\appdata\local\programs\python\python38-32\lib\site-packages\sqlalchemy\sql\elements.py", line 293, in _execute_on_connection
    return connection._execute_clauseelement(self, multiparams, params)
  File "c:\users\xiaocheng wang\appdata\local\programs\python\python38-32\lib\site-packages\sqlalchemy\engine\base.py", line 1097, in _execute_clauseelement
    ret = self._execute_context(
  File "c:\users\xiaocheng wang\appdata\local\programs\python\python38-32\lib\site-packages\sqlalchemy\engine\base.py", line 1287, in _execute_context
    self._handle_dbapi_exception(
  File "c:\users\xiaocheng wang\appdata\local\programs\python\python38-32\lib\site-packages\sqlalchemy\engine\base.py", line 1481, in _handle_dbapi_exception
    util.raise_(
  File "c:\users\xiaocheng wang\appdata\local\programs\python\python38-32\lib\site-packages\sqlalchemy\util\compat.py", line 178, in raise_
    raise exception
  File "c:\users\xiaocheng wang\appdata\local\programs\python\python38-32\lib\site-packages\sqlalchemy\engine\base.py", line 1247, in _execute_context
    self.dialect.do_execute(
  File "c:\users\xiaocheng wang\appdata\local\programs\python\python38-32\lib\site-packages\sqlalchemy\engine\default.py", line 590, in do_execute
    cursor.execute(statement, parameters)
sqlalchemy.exc.OperationalError: (sqlite3.OperationalError) no such column: user.confirmed
[SQL: SELECT user.id AS user_id, user.name AS user_name, user.email AS user_email, user.confirmed AS user_confirmed, user.password AS user_password, user.role AS user_role, user.registered_on AS user_registered_on, user.confirmed_on AS user_confirmed_on, user.password_reset_token AS user_password_reset_token 
FROM user 
WHERE user.email = ?
 LIMIT ? OFFSET ?]
[parameters: ('super2@uwa.edu.au', 1, 0)]
(Background on this error at: http://sqlalche.me/e/e3q8)
INFO:werkzeug:127.0.0.1 - - [06/Oct/2020 00:52:14] "[35m[1mPOST /login HTTP/1.1[0m" 500 -
INFO:werkzeug:127.0.0.1 - - [06/Oct/2020 00:52:21] "[37mPOST /login HTTP/1.1[0m" 200 -
INFO:werkzeug:127.0.0.1 - - [06/Oct/2020 00:52:22] "[37mGET /index HTTP/1.1[0m" 200 -
INFO:werkzeug:127.0.0.1 - - [06/Oct/2020 00:52:23] "[37mGET /auth/initial-registration HTTP/1.1[0m" 200 -
INFO:werkzeug:127.0.0.1 - - [06/Oct/2020 00:52:36] "[37mGET /index HTTP/1.1[0m" 200 -
INFO:werkzeug:127.0.0.1 - - [06/Oct/2020 00:52:37] "[37mGET /auth/initial-registration HTTP/1.1[0m" 200 -
INFO:werkzeug:127.0.0.1 - - [06/Oct/2020 00:52:38] "[37mGET /index HTTP/1.1[0m" 200 -
INFO:werkzeug:127.0.0.1 - - [06/Oct/2020 00:52:42] "[32mGET /admin HTTP/1.1[0m" 308 -
INFO:werkzeug:127.0.0.1 - - [06/Oct/2020 00:52:42] "[37mGET /admin/ HTTP/1.1[0m" 200 -
INFO:werkzeug:127.0.0.1 - - [06/Oct/2020 00:52:42] "[37mGET /admin/static/bootstrap/bootstrap3/swatch/default/bootstrap.min.css?v=3.3.5 HTTP/1.1[0m" 200 -
INFO:werkzeug:127.0.0.1 - - [06/Oct/2020 00:52:42] "[37mGET /admin/static/bootstrap/bootstrap3/css/bootstrap-theme.min.css?v=3.3.5 HTTP/1.1[0m" 200 -
INFO:werkzeug:127.0.0.1 - - [06/Oct/2020 00:52:42] "[37mGET /admin/static/admin/css/bootstrap3/admin.css?v=1.1.1 HTTP/1.1[0m" 200 -
INFO:werkzeug:127.0.0.1 - - [06/Oct/2020 00:52:42] "[37mGET /admin/static/admin/css/bootstrap3/submenu.css HTTP/1.1[0m" 200 -
INFO:werkzeug:127.0.0.1 - - [06/Oct/2020 00:52:42] "[37mGET /admin/static/admin/js/helpers.js?v=1.0.0 HTTP/1.1[0m" 200 -
INFO:werkzeug:127.0.0.1 - - [06/Oct/2020 00:52:42] "[37mGET /admin/static/bootstrap/bootstrap3/js/bootstrap.min.js?v=3.3.5 HTTP/1.1[0m" 200 -
INFO:werkzeug:127.0.0.1 - - [06/Oct/2020 00:52:42] "[37mGET /admin/static/vendor/moment.min.js?v=2.22.2 HTTP/1.1[0m" 200 -
INFO:werkzeug:127.0.0.1 - - [06/Oct/2020 00:52:42] "[37mGET /admin/static/vendor/jquery.min.js?v=3.3.1 HTTP/1.1[0m" 200 -
INFO:werkzeug:127.0.0.1 - - [06/Oct/2020 00:52:42] "[37mGET /admin/static/vendor/select2/select2.min.js?v=3.5.2 HTTP/1.1[0m" 200 -
ERROR:app:Exception on /admin/user/ [GET]
Traceback (most recent call last):
  File "c:\users\xiaocheng wang\appdata\local\programs\python\python38-32\lib\site-packages\sqlalchemy\engine\base.py", line 1247, in _execute_context
    self.dialect.do_execute(
  File "c:\users\xiaocheng wang\appdata\local\programs\python\python38-32\lib\site-packages\sqlalchemy\engine\default.py", line 590, in do_execute
    cursor.execute(statement, parameters)
sqlite3.OperationalError: no such column: user.confirmed

The above exception was the direct cause of the following exception:

Traceback (most recent call last):
  File "c:\users\xiaocheng wang\appdata\local\programs\python\python38-32\lib\site-packages\flask\app.py", line 2447, in wsgi_app
    response = self.full_dispatch_request()
  File "c:\users\xiaocheng wang\appdata\local\programs\python\python38-32\lib\site-packages\flask\app.py", line 1952, in full_dispatch_request
    rv = self.handle_user_exception(e)
  File "c:\users\xiaocheng wang\appdata\local\programs\python\python38-32\lib\site-packages\flask\app.py", line 1821, in handle_user_exception
    reraise(exc_type, exc_value, tb)
  File "c:\users\xiaocheng wang\appdata\local\programs\python\python38-32\lib\site-packages\flask\_compat.py", line 39, in reraise
    raise value
  File "c:\users\xiaocheng wang\appdata\local\programs\python\python38-32\lib\site-packages\flask\app.py", line 1950, in full_dispatch_request
    rv = self.dispatch_request()
  File "c:\users\xiaocheng wang\appdata\local\programs\python\python38-32\lib\site-packages\flask\app.py", line 1936, in dispatch_request
    return self.view_functions[rule.endpoint](**req.view_args)
  File "c:\users\xiaocheng wang\appdata\local\programs\python\python38-32\lib\site-packages\flask_admin\base.py", line 69, in inner
    return self._run_view(f, *args, **kwargs)
  File "c:\users\xiaocheng wang\appdata\local\programs\python\python38-32\lib\site-packages\flask_admin\base.py", line 368, in _run_view
    return fn(self, *args, **kwargs)
  File "c:\users\xiaocheng wang\appdata\local\programs\python\python38-32\lib\site-packages\flask_admin\model\base.py", line 1969, in index_view
    count, data = self.get_list(view_args.page, sort_column, view_args.sort_desc,
  File "c:\users\xiaocheng wang\appdata\local\programs\python\python38-32\lib\site-packages\flask_admin\contrib\sqla\view.py", line 1079, in get_list
    query = query.all()
  File "c:\users\xiaocheng wang\appdata\local\programs\python\python38-32\lib\site-packages\sqlalchemy\orm\query.py", line 3246, in all
    return list(self)
  File "c:\users\xiaocheng wang\appdata\local\programs\python\python38-32\lib\site-packages\sqlalchemy\orm\query.py", line 3405, in __iter__
    return self._execute_and_instances(context)
  File "c:\users\xiaocheng wang\appdata\local\programs\python\python38-32\lib\site-packages\sqlalchemy\orm\query.py", line 3430, in _execute_and_instances
    result = conn.execute(querycontext.statement, self._params)
  File "c:\users\xiaocheng wang\appdata\local\programs\python\python38-32\lib\site-packages\sqlalchemy\engine\base.py", line 984, in execute
    return meth(self, multiparams, params)
  File "c:\users\xiaocheng wang\appdata\local\programs\python\python38-32\lib\site-packages\sqlalchemy\sql\elements.py", line 293, in _execute_on_connection
    return connection._execute_clauseelement(self, multiparams, params)
  File "c:\users\xiaocheng wang\appdata\local\programs\python\python38-32\lib\site-packages\sqlalchemy\engine\base.py", line 1097, in _execute_clauseelement
    ret = self._execute_context(
  File "c:\users\xiaocheng wang\appdata\local\programs\python\python38-32\lib\site-packages\sqlalchemy\engine\base.py", line 1287, in _execute_context
    self._handle_dbapi_exception(
  File "c:\users\xiaocheng wang\appdata\local\programs\python\python38-32\lib\site-packages\sqlalchemy\engine\base.py", line 1481, in _handle_dbapi_exception
    util.raise_(
  File "c:\users\xiaocheng wang\appdata\local\programs\python\python38-32\lib\site-packages\sqlalchemy\util\compat.py", line 178, in raise_
    raise exception
  File "c:\users\xiaocheng wang\appdata\local\programs\python\python38-32\lib\site-packages\sqlalchemy\engine\base.py", line 1247, in _execute_context
    self.dialect.do_execute(
  File "c:\users\xiaocheng wang\appdata\local\programs\python\python38-32\lib\site-packages\sqlalchemy\engine\default.py", line 590, in do_execute
    cursor.execute(statement, parameters)
sqlalchemy.exc.OperationalError: (sqlite3.OperationalError) no such column: user.confirmed
[SQL: SELECT user.id AS user_id, user.name AS user_name, user.email AS user_email, user.confirmed AS user_confirmed, user.password AS user_password, user.role AS user_role, user.registered_on AS user_registered_on, user.confirmed_on AS user_confirmed_on, user.password_reset_token AS user_password_reset_token 
FROM user
 LIMIT ? OFFSET ?]
[parameters: (20, 0)]
(Background on this error at: http://sqlalche.me/e/e3q8)
INFO:werkzeug:127.0.0.1 - - [06/Oct/2020 00:52:44] "[35m[1mGET /admin/user/ HTTP/1.1[0m" 500 -
INFO:werkzeug:127.0.0.1 - - [06/Oct/2020 00:52:45] "[37mGET /admin/ HTTP/1.1[0m" 200 -
ERROR:app:Exception on /admin/student/ [GET]
Traceback (most recent call last):
  File "c:\users\xiaocheng wang\appdata\local\programs\python\python38-32\lib\site-packages\sqlalchemy\engine\base.py", line 1247, in _execute_context
    self.dialect.do_execute(
  File "c:\users\xiaocheng wang\appdata\local\programs\python\python38-32\lib\site-packages\sqlalchemy\engine\default.py", line 590, in do_execute
    cursor.execute(statement, parameters)
sqlite3.OperationalError: no such column: user_1.confirmed

The above exception was the direct cause of the following exception:

Traceback (most recent call last):
  File "c:\users\xiaocheng wang\appdata\local\programs\python\python38-32\lib\site-packages\flask\app.py", line 2447, in wsgi_app
    response = self.full_dispatch_request()
  File "c:\users\xiaocheng wang\appdata\local\programs\python\python38-32\lib\site-packages\flask\app.py", line 1952, in full_dispatch_request
    rv = self.handle_user_exception(e)
  File "c:\users\xiaocheng wang\appdata\local\programs\python\python38-32\lib\site-packages\flask\app.py", line 1821, in handle_user_exception
    reraise(exc_type, exc_value, tb)
  File "c:\users\xiaocheng wang\appdata\local\programs\python\python38-32\lib\site-packages\flask\_compat.py", line 39, in reraise
    raise value
  File "c:\users\xiaocheng wang\appdata\local\programs\python\python38-32\lib\site-packages\flask\app.py", line 1950, in full_dispatch_request
    rv = self.dispatch_request()
  File "c:\users\xiaocheng wang\appdata\local\programs\python\python38-32\lib\site-packages\flask\app.py", line 1936, in dispatch_request
    return self.view_functions[rule.endpoint](**req.view_args)
  File "c:\users\xiaocheng wang\appdata\local\programs\python\python38-32\lib\site-packages\flask_admin\base.py", line 69, in inner
    return self._run_view(f, *args, **kwargs)
  File "c:\users\xiaocheng wang\appdata\local\programs\python\python38-32\lib\site-packages\flask_admin\base.py", line 368, in _run_view
    return fn(self, *args, **kwargs)
  File "c:\users\xiaocheng wang\appdata\local\programs\python\python38-32\lib\site-packages\flask_admin\model\base.py", line 1969, in index_view
    count, data = self.get_list(view_args.page, sort_column, view_args.sort_desc,
  File "c:\users\xiaocheng wang\appdata\local\programs\python\python38-32\lib\site-packages\flask_admin\contrib\sqla\view.py", line 1079, in get_list
    query = query.all()
  File "c:\users\xiaocheng wang\appdata\local\programs\python\python38-32\lib\site-packages\sqlalchemy\orm\query.py", line 3246, in all
    return list(self)
  File "c:\users\xiaocheng wang\appdata\local\programs\python\python38-32\lib\site-packages\sqlalchemy\orm\query.py", line 3405, in __iter__
    return self._execute_and_instances(context)
  File "c:\users\xiaocheng wang\appdata\local\programs\python\python38-32\lib\site-packages\sqlalchemy\orm\query.py", line 3430, in _execute_and_instances
    result = conn.execute(querycontext.statement, self._params)
  File "c:\users\xiaocheng wang\appdata\local\programs\python\python38-32\lib\site-packages\sqlalchemy\engine\base.py", line 984, in execute
    return meth(self, multiparams, params)
  File "c:\users\xiaocheng wang\appdata\local\programs\python\python38-32\lib\site-packages\sqlalchemy\sql\elements.py", line 293, in _execute_on_connection
    return connection._execute_clauseelement(self, multiparams, params)
  File "c:\users\xiaocheng wang\appdata\local\programs\python\python38-32\lib\site-packages\sqlalchemy\engine\base.py", line 1097, in _execute_clauseelement
    ret = self._execute_context(
  File "c:\users\xiaocheng wang\appdata\local\programs\python\python38-32\lib\site-packages\sqlalchemy\engine\base.py", line 1287, in _execute_context
    self._handle_dbapi_exception(
  File "c:\users\xiaocheng wang\appdata\local\programs\python\python38-32\lib\site-packages\sqlalchemy\engine\base.py", line 1481, in _handle_dbapi_exception
    util.raise_(
  File "c:\users\xiaocheng wang\appdata\local\programs\python\python38-32\lib\site-packages\sqlalchemy\util\compat.py", line 178, in raise_
    raise exception
  File "c:\users\xiaocheng wang\appdata\local\programs\python\python38-32\lib\site-packages\sqlalchemy\engine\base.py", line 1247, in _execute_context
    self.dialect.do_execute(
  File "c:\users\xiaocheng wang\appdata\local\programs\python\python38-32\lib\site-packages\sqlalchemy\engine\default.py", line 590, in do_execute
    cursor.execute(statement, parameters)
sqlalchemy.exc.OperationalError: (sqlite3.OperationalError) no such column: user_1.confirmed
[SQL: SELECT student.id AS student_id, student.user_id AS student_user_id, student.title AS student_title, student.gender AS student_gender, student.dob AS student_dob, student.ppname AS student_ppname, student.surname AS student_surname, student.firstname AS student_firstname, student.prefname AS student_prefname, student.charname AS student_charname, student.birth_cntry AS student_birth_cntry, student.citizen_cntry AS student_citizen_cntry, student.street_addr AS student_street_addr, student.city_addr AS student_city_addr, student.state_addr AS student_state_addr, student.postcode_addr AS student_postcode_addr, student.cntry_addr AS student_cntry_addr, student.emg_name AS student_emg_name, student.emg_rel AS student_emg_rel, student.emg_ph AS student_emg_ph, student.uni_name AS student_uni_name, student.uni_majors AS student_uni_majors, student.uni_gpa AS student_uni_gpa, student.uni_years AS student_uni_years, student.uni_awards AS student_uni_awards, student.eng_prog AS student_eng_prog, student.eng_prog_choice AS student_eng_prog_choice, student.native_sp AS student_native_sp, student.test_sc AS student_test_sc, student.eng_file AS student_eng_file, student."longQ1" AS "student_longQ1", student."longQ2" AS "student_longQ2", student."longQ3" AS "student_longQ3", student."longQ4" AS "student_longQ4", student.cv_file AS student_cv_file, student.transcr_file AS student_transcr_file, student.tuition_fee AS student_tuition_fee, user_1.id AS user_1_id, user_1.name AS user_1_name, user_1.email AS user_1_email, user_1.confirmed AS user_1_confirmed, user_1.password AS user_1_password, user_1.role AS user_1_role, user_1.registered_on AS user_1_registered_on, user_1.confirmed_on AS user_1_confirmed_on, user_1.password_reset_token AS user_1_password_reset_token 
FROM student LEFT OUTER JOIN user AS user_1 ON user_1.id = student.user_id
 LIMIT ? OFFSET ?]
[parameters: (20, 0)]
(Background on this error at: http://sqlalche.me/e/e3q8)
INFO:werkzeug:127.0.0.1 - - [06/Oct/2020 00:52:46] "[35m[1mGET /admin/student/ HTTP/1.1[0m" 500 -
INFO:werkzeug:127.0.0.1 - - [06/Oct/2020 00:52:47] "[37mGET /admin/ HTTP/1.1[0m" 200 -
ERROR:app:Exception on /admin/supervisor/ [GET]
Traceback (most recent call last):
  File "c:\users\xiaocheng wang\appdata\local\programs\python\python38-32\lib\site-packages\sqlalchemy\engine\base.py", line 1247, in _execute_context
    self.dialect.do_execute(
  File "c:\users\xiaocheng wang\appdata\local\programs\python\python38-32\lib\site-packages\sqlalchemy\engine\default.py", line 590, in do_execute
    cursor.execute(statement, parameters)
sqlite3.OperationalError: no such column: user_1.confirmed

The above exception was the direct cause of the following exception:

Traceback (most recent call last):
  File "c:\users\xiaocheng wang\appdata\local\programs\python\python38-32\lib\site-packages\flask\app.py", line 2447, in wsgi_app
    response = self.full_dispatch_request()
  File "c:\users\xiaocheng wang\appdata\local\programs\python\python38-32\lib\site-packages\flask\app.py", line 1952, in full_dispatch_request
    rv = self.handle_user_exception(e)
  File "c:\users\xiaocheng wang\appdata\local\programs\python\python38-32\lib\site-packages\flask\app.py", line 1821, in handle_user_exception
    reraise(exc_type, exc_value, tb)
  File "c:\users\xiaocheng wang\appdata\local\programs\python\python38-32\lib\site-packages\flask\_compat.py", line 39, in reraise
    raise value
  File "c:\users\xiaocheng wang\appdata\local\programs\python\python38-32\lib\site-packages\flask\app.py", line 1950, in full_dispatch_request
    rv = self.dispatch_request()
  File "c:\users\xiaocheng wang\appdata\local\programs\python\python38-32\lib\site-packages\flask\app.py", line 1936, in dispatch_request
    return self.view_functions[rule.endpoint](**req.view_args)
  File "c:\users\xiaocheng wang\appdata\local\programs\python\python38-32\lib\site-packages\flask_admin\base.py", line 69, in inner
    return self._run_view(f, *args, **kwargs)
  File "c:\users\xiaocheng wang\appdata\local\programs\python\python38-32\lib\site-packages\flask_admin\base.py", line 368, in _run_view
    return fn(self, *args, **kwargs)
  File "c:\users\xiaocheng wang\appdata\local\programs\python\python38-32\lib\site-packages\flask_admin\model\base.py", line 1969, in index_view
    count, data = self.get_list(view_args.page, sort_column, view_args.sort_desc,
  File "c:\users\xiaocheng wang\appdata\local\programs\python\python38-32\lib\site-packages\flask_admin\contrib\sqla\view.py", line 1079, in get_list
    query = query.all()
  File "c:\users\xiaocheng wang\appdata\local\programs\python\python38-32\lib\site-packages\sqlalchemy\orm\query.py", line 3246, in all
    return list(self)
  File "c:\users\xiaocheng wang\appdata\local\programs\python\python38-32\lib\site-packages\sqlalchemy\orm\query.py", line 3405, in __iter__
    return self._execute_and_instances(context)
  File "c:\users\xiaocheng wang\appdata\local\programs\python\python38-32\lib\site-packages\sqlalchemy\orm\query.py", line 3430, in _execute_and_instances
    result = conn.execute(querycontext.statement, self._params)
  File "c:\users\xiaocheng wang\appdata\local\programs\python\python38-32\lib\site-packages\sqlalchemy\engine\base.py", line 984, in execute
    return meth(self, multiparams, params)
  File "c:\users\xiaocheng wang\appdata\local\programs\python\python38-32\lib\site-packages\sqlalchemy\sql\elements.py", line 293, in _execute_on_connection
    return connection._execute_clauseelement(self, multiparams, params)
  File "c:\users\xiaocheng wang\appdata\local\programs\python\python38-32\lib\site-packages\sqlalchemy\engine\base.py", line 1097, in _execute_clauseelement
    ret = self._execute_context(
  File "c:\users\xiaocheng wang\appdata\local\programs\python\python38-32\lib\site-packages\sqlalchemy\engine\base.py", line 1287, in _execute_context
    self._handle_dbapi_exception(
  File "c:\users\xiaocheng wang\appdata\local\programs\python\python38-32\lib\site-packages\sqlalchemy\engine\base.py", line 1481, in _handle_dbapi_exception
    util.raise_(
  File "c:\users\xiaocheng wang\appdata\local\programs\python\python38-32\lib\site-packages\sqlalchemy\util\compat.py", line 178, in raise_
    raise exception
  File "c:\users\xiaocheng wang\appdata\local\programs\python\python38-32\lib\site-packages\sqlalchemy\engine\base.py", line 1247, in _execute_context
    self.dialect.do_execute(
  File "c:\users\xiaocheng wang\appdata\local\programs\python\python38-32\lib\site-packages\sqlalchemy\engine\default.py", line 590, in do_execute
    cursor.execute(statement, parameters)
sqlalchemy.exc.OperationalError: (sqlite3.OperationalError) no such column: user_1.confirmed
[SQL: SELECT supervisor.id AS supervisor_id, supervisor.user_id AS supervisor_user_id, supervisor.faculty AS supervisor_faculty, supervisor.school AS supervisor_school, user_1.id AS user_1_id, user_1.name AS user_1_name, user_1.email AS user_1_email, user_1.confirmed AS user_1_confirmed, user_1.password AS user_1_password, user_1.role AS user_1_role, user_1.registered_on AS user_1_registered_on, user_1.confirmed_on AS user_1_confirmed_on, user_1.password_reset_token AS user_1_password_reset_token 
FROM supervisor LEFT OUTER JOIN user AS user_1 ON user_1.id = supervisor.user_id
 LIMIT ? OFFSET ?]
[parameters: (20, 0)]
(Background on this error at: http://sqlalche.me/e/e3q8)
INFO:werkzeug:127.0.0.1 - - [06/Oct/2020 00:52:47] "[35m[1mGET /admin/supervisor/ HTTP/1.1[0m" 500 -
INFO:werkzeug:127.0.0.1 - - [06/Oct/2020 00:53:00] "[37mGET /admin/ HTTP/1.1[0m" 200 -
INFO:werkzeug:127.0.0.1 - - [06/Oct/2020 00:53:02] "[37mGET /admin/admintask/ HTTP/1.1[0m" 200 -
INFO:werkzeug:127.0.0.1 - - [06/Oct/2020 00:53:02] "[37mGET /admin/static/vendor/select2/select2.css?v=3.5.2 HTTP/1.1[0m" 200 -
INFO:werkzeug:127.0.0.1 - - [06/Oct/2020 00:53:02] "[37mGET /admin/static/vendor/select2/select2-bootstrap3.css?v=1.4.6 HTTP/1.1[0m" 200 -
INFO:werkzeug:127.0.0.1 - - [06/Oct/2020 00:53:02] "[37mGET /admin/static/vendor/bootstrap-daterangepicker/daterangepicker-bs3.css?v=1.3.22 HTTP/1.1[0m" 200 -
INFO:werkzeug:127.0.0.1 - - [06/Oct/2020 00:53:02] "[37mGET /admin/static/admin/js/filters.js?v=1.0.0 HTTP/1.1[0m" 200 -
INFO:werkzeug:127.0.0.1 - - [06/Oct/2020 00:53:02] "[37mGET /admin/static/admin/js/form.js?v=1.0.1 HTTP/1.1[0m" 200 -
INFO:werkzeug:127.0.0.1 - - [06/Oct/2020 00:53:02] "[37mGET /admin/static/admin/js/actions.js?v=1.0.0 HTTP/1.1[0m" 200 -
INFO:werkzeug:127.0.0.1 - - [06/Oct/2020 00:53:02] "[37mGET /admin/static/vendor/bootstrap-daterangepicker/daterangepicker.js?v=1.3.22 HTTP/1.1[0m" 200 -
INFO:werkzeug:127.0.0.1 - - [06/Oct/2020 00:53:04] "[37mGET /admin/preference/ HTTP/1.1[0m" 200 -
ERROR:app:Exception on /admin/project/ [GET]
Traceback (most recent call last):
  File "c:\users\xiaocheng wang\appdata\local\programs\python\python38-32\lib\site-packages\sqlalchemy\engine\base.py", line 1247, in _execute_context
    self.dialect.do_execute(
  File "c:\users\xiaocheng wang\appdata\local\programs\python\python38-32\lib\site-packages\sqlalchemy\engine\default.py", line 590, in do_execute
    cursor.execute(statement, parameters)
sqlite3.OperationalError: no such column: user_1.confirmed

The above exception was the direct cause of the following exception:

Traceback (most recent call last):
  File "c:\users\xiaocheng wang\appdata\local\programs\python\python38-32\lib\site-packages\flask\app.py", line 2447, in wsgi_app
    response = self.full_dispatch_request()
  File "c:\users\xiaocheng wang\appdata\local\programs\python\python38-32\lib\site-packages\flask\app.py", line 1952, in full_dispatch_request
    rv = self.handle_user_exception(e)
  File "c:\users\xiaocheng wang\appdata\local\programs\python\python38-32\lib\site-packages\flask\app.py", line 1821, in handle_user_exception
    reraise(exc_type, exc_value, tb)
  File "c:\users\xiaocheng wang\appdata\local\programs\python\python38-32\lib\site-packages\flask\_compat.py", line 39, in reraise
    raise value
  File "c:\users\xiaocheng wang\appdata\local\programs\python\python38-32\lib\site-packages\flask\app.py", line 1950, in full_dispatch_request
    rv = self.dispatch_request()
  File "c:\users\xiaocheng wang\appdata\local\programs\python\python38-32\lib\site-packages\flask\app.py", line 1936, in dispatch_request
    return self.view_functions[rule.endpoint](**req.view_args)
  File "c:\users\xiaocheng wang\appdata\local\programs\python\python38-32\lib\site-packages\flask_admin\base.py", line 69, in inner
    return self._run_view(f, *args, **kwargs)
  File "c:\users\xiaocheng wang\appdata\local\programs\python\python38-32\lib\site-packages\flask_admin\base.py", line 368, in _run_view
    return fn(self, *args, **kwargs)
  File "c:\users\xiaocheng wang\appdata\local\programs\python\python38-32\lib\site-packages\flask_admin\model\base.py", line 1969, in index_view
    count, data = self.get_list(view_args.page, sort_column, view_args.sort_desc,
  File "c:\users\xiaocheng wang\appdata\local\programs\python\python38-32\lib\site-packages\flask_admin\contrib\sqla\view.py", line 1079, in get_list
    query = query.all()
  File "c:\users\xiaocheng wang\appdata\local\programs\python\python38-32\lib\site-packages\sqlalchemy\orm\query.py", line 3246, in all
    return list(self)
  File "c:\users\xiaocheng wang\appdata\local\programs\python\python38-32\lib\site-packages\sqlalchemy\orm\query.py", line 3405, in __iter__
    return self._execute_and_instances(context)
  File "c:\users\xiaocheng wang\appdata\local\programs\python\python38-32\lib\site-packages\sqlalchemy\orm\query.py", line 3430, in _execute_and_instances
    result = conn.execute(querycontext.statement, self._params)
  File "c:\users\xiaocheng wang\appdata\local\programs\python\python38-32\lib\site-packages\sqlalchemy\engine\base.py", line 984, in execute
    return meth(self, multiparams, params)
  File "c:\users\xiaocheng wang\appdata\local\programs\python\python38-32\lib\site-packages\sqlalchemy\sql\elements.py", line 293, in _execute_on_connection
    return connection._execute_clauseelement(self, multiparams, params)
  File "c:\users\xiaocheng wang\appdata\local\programs\python\python38-32\lib\site-packages\sqlalchemy\engine\base.py", line 1097, in _execute_clauseelement
    ret = self._execute_context(
  File "c:\users\xiaocheng wang\appdata\local\programs\python\python38-32\lib\site-packages\sqlalchemy\engine\base.py", line 1287, in _execute_context
    self._handle_dbapi_exception(
  File "c:\users\xiaocheng wang\appdata\local\programs\python\python38-32\lib\site-packages\sqlalchemy\engine\base.py", line 1481, in _handle_dbapi_exception
    util.raise_(
  File "c:\users\xiaocheng wang\appdata\local\programs\python\python38-32\lib\site-packages\sqlalchemy\util\compat.py", line 178, in raise_
    raise exception
  File "c:\users\xiaocheng wang\appdata\local\programs\python\python38-32\lib\site-packages\sqlalchemy\engine\base.py", line 1247, in _execute_context
    self.dialect.do_execute(
  File "c:\users\xiaocheng wang\appdata\local\programs\python\python38-32\lib\site-packages\sqlalchemy\engine\default.py", line 590, in do_execute
    cursor.execute(statement, parameters)
sqlalchemy.exc.OperationalError: (sqlite3.OperationalError) no such column: user_1.confirmed
[SQL: SELECT project.id AS project_id, project.user_id AS project_user_id, project.title AS project_title, project.main_supervisor AS project_main_supervisor, project.co_supervisor AS project_co_supervisor, project.proj_group AS project_proj_group, project.proj_desc AS project_proj_desc, project.skills AS project_skills, project.keywords AS project_keywords, project.contact_email AS project_contact_email, project.location AS project_location, project.specific_uni AS project_specific_uni, project.proj_weeks AS project_proj_weeks, project.max_students AS project_max_students, user_1.id AS user_1_id, user_1.name AS user_1_name, user_1.email AS user_1_email, user_1.confirmed AS user_1_confirmed, user_1.password AS user_1_password, user_1.role AS user_1_role, user_1.registered_on AS user_1_registered_on, user_1.confirmed_on AS user_1_confirmed_on, user_1.password_reset_token AS user_1_password_reset_token 
FROM project LEFT OUTER JOIN user AS user_1 ON user_1.id = project.user_id
 LIMIT ? OFFSET ?]
[parameters: (20, 0)]
(Background on this error at: http://sqlalche.me/e/e3q8)
INFO:werkzeug:127.0.0.1 - - [06/Oct/2020 00:53:05] "[35m[1mGET /admin/project/ HTTP/1.1[0m" 500 -
INFO:werkzeug:127.0.0.1 - - [06/Oct/2020 00:53:06] "[37mGET /admin/preference/ HTTP/1.1[0m" 200 -
ERROR:app:Exception on /admin/supervisor/ [GET]
Traceback (most recent call last):
  File "c:\users\xiaocheng wang\appdata\local\programs\python\python38-32\lib\site-packages\sqlalchemy\engine\base.py", line 1247, in _execute_context
    self.dialect.do_execute(
  File "c:\users\xiaocheng wang\appdata\local\programs\python\python38-32\lib\site-packages\sqlalchemy\engine\default.py", line 590, in do_execute
    cursor.execute(statement, parameters)
sqlite3.OperationalError: no such column: user_1.confirmed

The above exception was the direct cause of the following exception:

Traceback (most recent call last):
  File "c:\users\xiaocheng wang\appdata\local\programs\python\python38-32\lib\site-packages\flask\app.py", line 2447, in wsgi_app
    response = self.full_dispatch_request()
  File "c:\users\xiaocheng wang\appdata\local\programs\python\python38-32\lib\site-packages\flask\app.py", line 1952, in full_dispatch_request
    rv = self.handle_user_exception(e)
  File "c:\users\xiaocheng wang\appdata\local\programs\python\python38-32\lib\site-packages\flask\app.py", line 1821, in handle_user_exception
    reraise(exc_type, exc_value, tb)
  File "c:\users\xiaocheng wang\appdata\local\programs\python\python38-32\lib\site-packages\flask\_compat.py", line 39, in reraise
    raise value
  File "c:\users\xiaocheng wang\appdata\local\programs\python\python38-32\lib\site-packages\flask\app.py", line 1950, in full_dispatch_request
    rv = self.dispatch_request()
  File "c:\users\xiaocheng wang\appdata\local\programs\python\python38-32\lib\site-packages\flask\app.py", line 1936, in dispatch_request
    return self.view_functions[rule.endpoint](**req.view_args)
  File "c:\users\xiaocheng wang\appdata\local\programs\python\python38-32\lib\site-packages\flask_admin\base.py", line 69, in inner
    return self._run_view(f, *args, **kwargs)
  File "c:\users\xiaocheng wang\appdata\local\programs\python\python38-32\lib\site-packages\flask_admin\base.py", line 368, in _run_view
    return fn(self, *args, **kwargs)
  File "c:\users\xiaocheng wang\appdata\local\programs\python\python38-32\lib\site-packages\flask_admin\model\base.py", line 1969, in index_view
    count, data = self.get_list(view_args.page, sort_column, view_args.sort_desc,
  File "c:\users\xiaocheng wang\appdata\local\programs\python\python38-32\lib\site-packages\flask_admin\contrib\sqla\view.py", line 1079, in get_list
    query = query.all()
  File "c:\users\xiaocheng wang\appdata\local\programs\python\python38-32\lib\site-packages\sqlalchemy\orm\query.py", line 3246, in all
    return list(self)
  File "c:\users\xiaocheng wang\appdata\local\programs\python\python38-32\lib\site-packages\sqlalchemy\orm\query.py", line 3405, in __iter__
    return self._execute_and_instances(context)
  File "c:\users\xiaocheng wang\appdata\local\programs\python\python38-32\lib\site-packages\sqlalchemy\orm\query.py", line 3430, in _execute_and_instances
    result = conn.execute(querycontext.statement, self._params)
  File "c:\users\xiaocheng wang\appdata\local\programs\python\python38-32\lib\site-packages\sqlalchemy\engine\base.py", line 984, in execute
    return meth(self, multiparams, params)
  File "c:\users\xiaocheng wang\appdata\local\programs\python\python38-32\lib\site-packages\sqlalchemy\sql\elements.py", line 293, in _execute_on_connection
    return connection._execute_clauseelement(self, multiparams, params)
  File "c:\users\xiaocheng wang\appdata\local\programs\python\python38-32\lib\site-packages\sqlalchemy\engine\base.py", line 1097, in _execute_clauseelement
    ret = self._execute_context(
  File "c:\users\xiaocheng wang\appdata\local\programs\python\python38-32\lib\site-packages\sqlalchemy\engine\base.py", line 1287, in _execute_context
    self._handle_dbapi_exception(
  File "c:\users\xiaocheng wang\appdata\local\programs\python\python38-32\lib\site-packages\sqlalchemy\engine\base.py", line 1481, in _handle_dbapi_exception
    util.raise_(
  File "c:\users\xiaocheng wang\appdata\local\programs\python\python38-32\lib\site-packages\sqlalchemy\util\compat.py", line 178, in raise_
    raise exception
  File "c:\users\xiaocheng wang\appdata\local\programs\python\python38-32\lib\site-packages\sqlalchemy\engine\base.py", line 1247, in _execute_context
    self.dialect.do_execute(
  File "c:\users\xiaocheng wang\appdata\local\programs\python\python38-32\lib\site-packages\sqlalchemy\engine\default.py", line 590, in do_execute
    cursor.execute(statement, parameters)
sqlalchemy.exc.OperationalError: (sqlite3.OperationalError) no such column: user_1.confirmed
[SQL: SELECT supervisor.id AS supervisor_id, supervisor.user_id AS supervisor_user_id, supervisor.faculty AS supervisor_faculty, supervisor.school AS supervisor_school, user_1.id AS user_1_id, user_1.name AS user_1_name, user_1.email AS user_1_email, user_1.confirmed AS user_1_confirmed, user_1.password AS user_1_password, user_1.role AS user_1_role, user_1.registered_on AS user_1_registered_on, user_1.confirmed_on AS user_1_confirmed_on, user_1.password_reset_token AS user_1_password_reset_token 
FROM supervisor LEFT OUTER JOIN user AS user_1 ON user_1.id = supervisor.user_id
 LIMIT ? OFFSET ?]
[parameters: (20, 0)]
(Background on this error at: http://sqlalche.me/e/e3q8)
INFO:werkzeug:127.0.0.1 - - [06/Oct/2020 00:53:07] "[35m[1mGET /admin/supervisor/ HTTP/1.1[0m" 500 -
INFO:werkzeug:127.0.0.1 - - [06/Oct/2020 00:53:09] "[37mGET /admin/preference/ HTTP/1.1[0m" 200 -
ERROR:app:Exception on /admin/student/ [GET]
Traceback (most recent call last):
  File "c:\users\xiaocheng wang\appdata\local\programs\python\python38-32\lib\site-packages\sqlalchemy\engine\base.py", line 1247, in _execute_context
    self.dialect.do_execute(
  File "c:\users\xiaocheng wang\appdata\local\programs\python\python38-32\lib\site-packages\sqlalchemy\engine\default.py", line 590, in do_execute
    cursor.execute(statement, parameters)
sqlite3.OperationalError: no such column: user_1.confirmed

The above exception was the direct cause of the following exception:

Traceback (most recent call last):
  File "c:\users\xiaocheng wang\appdata\local\programs\python\python38-32\lib\site-packages\flask\app.py", line 2447, in wsgi_app
    response = self.full_dispatch_request()
  File "c:\users\xiaocheng wang\appdata\local\programs\python\python38-32\lib\site-packages\flask\app.py", line 1952, in full_dispatch_request
    rv = self.handle_user_exception(e)
  File "c:\users\xiaocheng wang\appdata\local\programs\python\python38-32\lib\site-packages\flask\app.py", line 1821, in handle_user_exception
    reraise(exc_type, exc_value, tb)
  File "c:\users\xiaocheng wang\appdata\local\programs\python\python38-32\lib\site-packages\flask\_compat.py", line 39, in reraise
    raise value
  File "c:\users\xiaocheng wang\appdata\local\programs\python\python38-32\lib\site-packages\flask\app.py", line 1950, in full_dispatch_request
    rv = self.dispatch_request()
  File "c:\users\xiaocheng wang\appdata\local\programs\python\python38-32\lib\site-packages\flask\app.py", line 1936, in dispatch_request
    return self.view_functions[rule.endpoint](**req.view_args)
  File "c:\users\xiaocheng wang\appdata\local\programs\python\python38-32\lib\site-packages\flask_admin\base.py", line 69, in inner
    return self._run_view(f, *args, **kwargs)
  File "c:\users\xiaocheng wang\appdata\local\programs\python\python38-32\lib\site-packages\flask_admin\base.py", line 368, in _run_view
    return fn(self, *args, **kwargs)
  File "c:\users\xiaocheng wang\appdata\local\programs\python\python38-32\lib\site-packages\flask_admin\model\base.py", line 1969, in index_view
    count, data = self.get_list(view_args.page, sort_column, view_args.sort_desc,
  File "c:\users\xiaocheng wang\appdata\local\programs\python\python38-32\lib\site-packages\flask_admin\contrib\sqla\view.py", line 1079, in get_list
    query = query.all()
  File "c:\users\xiaocheng wang\appdata\local\programs\python\python38-32\lib\site-packages\sqlalchemy\orm\query.py", line 3246, in all
    return list(self)
  File "c:\users\xiaocheng wang\appdata\local\programs\python\python38-32\lib\site-packages\sqlalchemy\orm\query.py", line 3405, in __iter__
    return self._execute_and_instances(context)
  File "c:\users\xiaocheng wang\appdata\local\programs\python\python38-32\lib\site-packages\sqlalchemy\orm\query.py", line 3430, in _execute_and_instances
    result = conn.execute(querycontext.statement, self._params)
  File "c:\users\xiaocheng wang\appdata\local\programs\python\python38-32\lib\site-packages\sqlalchemy\engine\base.py", line 984, in execute
    return meth(self, multiparams, params)
  File "c:\users\xiaocheng wang\appdata\local\programs\python\python38-32\lib\site-packages\sqlalchemy\sql\elements.py", line 293, in _execute_on_connection
    return connection._execute_clauseelement(self, multiparams, params)
  File "c:\users\xiaocheng wang\appdata\local\programs\python\python38-32\lib\site-packages\sqlalchemy\engine\base.py", line 1097, in _execute_clauseelement
    ret = self._execute_context(
  File "c:\users\xiaocheng wang\appdata\local\programs\python\python38-32\lib\site-packages\sqlalchemy\engine\base.py", line 1287, in _execute_context
    self._handle_dbapi_exception(
  File "c:\users\xiaocheng wang\appdata\local\programs\python\python38-32\lib\site-packages\sqlalchemy\engine\base.py", line 1481, in _handle_dbapi_exception
    util.raise_(
  File "c:\users\xiaocheng wang\appdata\local\programs\python\python38-32\lib\site-packages\sqlalchemy\util\compat.py", line 178, in raise_
    raise exception
  File "c:\users\xiaocheng wang\appdata\local\programs\python\python38-32\lib\site-packages\sqlalchemy\engine\base.py", line 1247, in _execute_context
    self.dialect.do_execute(
  File "c:\users\xiaocheng wang\appdata\local\programs\python\python38-32\lib\site-packages\sqlalchemy\engine\default.py", line 590, in do_execute
    cursor.execute(statement, parameters)
sqlalchemy.exc.OperationalError: (sqlite3.OperationalError) no such column: user_1.confirmed
[SQL: SELECT student.id AS student_id, student.user_id AS student_user_id, student.title AS student_title, student.gender AS student_gender, student.dob AS student_dob, student.ppname AS student_ppname, student.surname AS student_surname, student.firstname AS student_firstname, student.prefname AS student_prefname, student.charname AS student_charname, student.birth_cntry AS student_birth_cntry, student.citizen_cntry AS student_citizen_cntry, student.street_addr AS student_street_addr, student.city_addr AS student_city_addr, student.state_addr AS student_state_addr, student.postcode_addr AS student_postcode_addr, student.cntry_addr AS student_cntry_addr, student.emg_name AS student_emg_name, student.emg_rel AS student_emg_rel, student.emg_ph AS student_emg_ph, student.uni_name AS student_uni_name, student.uni_majors AS student_uni_majors, student.uni_gpa AS student_uni_gpa, student.uni_years AS student_uni_years, student.uni_awards AS student_uni_awards, student.eng_prog AS student_eng_prog, student.eng_prog_choice AS student_eng_prog_choice, student.native_sp AS student_native_sp, student.test_sc AS student_test_sc, student.eng_file AS student_eng_file, student."longQ1" AS "student_longQ1", student."longQ2" AS "student_longQ2", student."longQ3" AS "student_longQ3", student."longQ4" AS "student_longQ4", student.cv_file AS student_cv_file, student.transcr_file AS student_transcr_file, student.tuition_fee AS student_tuition_fee, user_1.id AS user_1_id, user_1.name AS user_1_name, user_1.email AS user_1_email, user_1.confirmed AS user_1_confirmed, user_1.password AS user_1_password, user_1.role AS user_1_role, user_1.registered_on AS user_1_registered_on, user_1.confirmed_on AS user_1_confirmed_on, user_1.password_reset_token AS user_1_password_reset_token 
FROM student LEFT OUTER JOIN user AS user_1 ON user_1.id = student.user_id
 LIMIT ? OFFSET ?]
[parameters: (20, 0)]
(Background on this error at: http://sqlalche.me/e/e3q8)
INFO:werkzeug:127.0.0.1 - - [06/Oct/2020 00:53:11] "[35m[1mGET /admin/student/ HTTP/1.1[0m" 500 -
INFO:werkzeug:127.0.0.1 - - [06/Oct/2020 00:53:12] "[37mGET /admin/preference/ HTTP/1.1[0m" 200 -
ERROR:app:Exception on /admin/project/ [GET]
Traceback (most recent call last):
  File "c:\users\xiaocheng wang\appdata\local\programs\python\python38-32\lib\site-packages\sqlalchemy\engine\base.py", line 1247, in _execute_context
    self.dialect.do_execute(
  File "c:\users\xiaocheng wang\appdata\local\programs\python\python38-32\lib\site-packages\sqlalchemy\engine\default.py", line 590, in do_execute
    cursor.execute(statement, parameters)
sqlite3.OperationalError: no such column: user_1.confirmed

The above exception was the direct cause of the following exception:

Traceback (most recent call last):
  File "c:\users\xiaocheng wang\appdata\local\programs\python\python38-32\lib\site-packages\flask\app.py", line 2447, in wsgi_app
    response = self.full_dispatch_request()
  File "c:\users\xiaocheng wang\appdata\local\programs\python\python38-32\lib\site-packages\flask\app.py", line 1952, in full_dispatch_request
    rv = self.handle_user_exception(e)
  File "c:\users\xiaocheng wang\appdata\local\programs\python\python38-32\lib\site-packages\flask\app.py", line 1821, in handle_user_exception
    reraise(exc_type, exc_value, tb)
  File "c:\users\xiaocheng wang\appdata\local\programs\python\python38-32\lib\site-packages\flask\_compat.py", line 39, in reraise
    raise value
  File "c:\users\xiaocheng wang\appdata\local\programs\python\python38-32\lib\site-packages\flask\app.py", line 1950, in full_dispatch_request
    rv = self.dispatch_request()
  File "c:\users\xiaocheng wang\appdata\local\programs\python\python38-32\lib\site-packages\flask\app.py", line 1936, in dispatch_request
    return self.view_functions[rule.endpoint](**req.view_args)
  File "c:\users\xiaocheng wang\appdata\local\programs\python\python38-32\lib\site-packages\flask_admin\base.py", line 69, in inner
    return self._run_view(f, *args, **kwargs)
  File "c:\users\xiaocheng wang\appdata\local\programs\python\python38-32\lib\site-packages\flask_admin\base.py", line 368, in _run_view
    return fn(self, *args, **kwargs)
  File "c:\users\xiaocheng wang\appdata\local\programs\python\python38-32\lib\site-packages\flask_admin\model\base.py", line 1969, in index_view
    count, data = self.get_list(view_args.page, sort_column, view_args.sort_desc,
  File "c:\users\xiaocheng wang\appdata\local\programs\python\python38-32\lib\site-packages\flask_admin\contrib\sqla\view.py", line 1079, in get_list
    query = query.all()
  File "c:\users\xiaocheng wang\appdata\local\programs\python\python38-32\lib\site-packages\sqlalchemy\orm\query.py", line 3246, in all
    return list(self)
  File "c:\users\xiaocheng wang\appdata\local\programs\python\python38-32\lib\site-packages\sqlalchemy\orm\query.py", line 3405, in __iter__
    return self._execute_and_instances(context)
  File "c:\users\xiaocheng wang\appdata\local\programs\python\python38-32\lib\site-packages\sqlalchemy\orm\query.py", line 3430, in _execute_and_instances
    result = conn.execute(querycontext.statement, self._params)
  File "c:\users\xiaocheng wang\appdata\local\programs\python\python38-32\lib\site-packages\sqlalchemy\engine\base.py", line 984, in execute
    return meth(self, multiparams, params)
  File "c:\users\xiaocheng wang\appdata\local\programs\python\python38-32\lib\site-packages\sqlalchemy\sql\elements.py", line 293, in _execute_on_connection
    return connection._execute_clauseelement(self, multiparams, params)
  File "c:\users\xiaocheng wang\appdata\local\programs\python\python38-32\lib\site-packages\sqlalchemy\engine\base.py", line 1097, in _execute_clauseelement
    ret = self._execute_context(
  File "c:\users\xiaocheng wang\appdata\local\programs\python\python38-32\lib\site-packages\sqlalchemy\engine\base.py", line 1287, in _execute_context
    self._handle_dbapi_exception(
  File "c:\users\xiaocheng wang\appdata\local\programs\python\python38-32\lib\site-packages\sqlalchemy\engine\base.py", line 1481, in _handle_dbapi_exception
    util.raise_(
  File "c:\users\xiaocheng wang\appdata\local\programs\python\python38-32\lib\site-packages\sqlalchemy\util\compat.py", line 178, in raise_
    raise exception
  File "c:\users\xiaocheng wang\appdata\local\programs\python\python38-32\lib\site-packages\sqlalchemy\engine\base.py", line 1247, in _execute_context
    self.dialect.do_execute(
  File "c:\users\xiaocheng wang\appdata\local\programs\python\python38-32\lib\site-packages\sqlalchemy\engine\default.py", line 590, in do_execute
    cursor.execute(statement, parameters)
sqlalchemy.exc.OperationalError: (sqlite3.OperationalError) no such column: user_1.confirmed
[SQL: SELECT project.id AS project_id, project.user_id AS project_user_id, project.title AS project_title, project.main_supervisor AS project_main_supervisor, project.co_supervisor AS project_co_supervisor, project.proj_group AS project_proj_group, project.proj_desc AS project_proj_desc, project.skills AS project_skills, project.keywords AS project_keywords, project.contact_email AS project_contact_email, project.location AS project_location, project.specific_uni AS project_specific_uni, project.proj_weeks AS project_proj_weeks, project.max_students AS project_max_students, user_1.id AS user_1_id, user_1.name AS user_1_name, user_1.email AS user_1_email, user_1.confirmed AS user_1_confirmed, user_1.password AS user_1_password, user_1.role AS user_1_role, user_1.registered_on AS user_1_registered_on, user_1.confirmed_on AS user_1_confirmed_on, user_1.password_reset_token AS user_1_password_reset_token 
FROM project LEFT OUTER JOIN user AS user_1 ON user_1.id = project.user_id
 LIMIT ? OFFSET ?]
[parameters: (20, 0)]
(Background on this error at: http://sqlalche.me/e/e3q8)
INFO:werkzeug:127.0.0.1 - - [06/Oct/2020 00:53:50] "[35m[1mGET /admin/project/ HTTP/1.1[0m" 500 -
INFO:werkzeug:127.0.0.1 - - [06/Oct/2020 00:53:52] "[37mGET /admin/preference/ HTTP/1.1[0m" 200 -
ERROR:app:Exception on /admin/student/ [GET]
Traceback (most recent call last):
  File "c:\users\xiaocheng wang\appdata\local\programs\python\python38-32\lib\site-packages\sqlalchemy\engine\base.py", line 1247, in _execute_context
    self.dialect.do_execute(
  File "c:\users\xiaocheng wang\appdata\local\programs\python\python38-32\lib\site-packages\sqlalchemy\engine\default.py", line 590, in do_execute
    cursor.execute(statement, parameters)
sqlite3.OperationalError: no such column: user_1.confirmed

The above exception was the direct cause of the following exception:

Traceback (most recent call last):
  File "c:\users\xiaocheng wang\appdata\local\programs\python\python38-32\lib\site-packages\flask\app.py", line 2447, in wsgi_app
    response = self.full_dispatch_request()
  File "c:\users\xiaocheng wang\appdata\local\programs\python\python38-32\lib\site-packages\flask\app.py", line 1952, in full_dispatch_request
    rv = self.handle_user_exception(e)
  File "c:\users\xiaocheng wang\appdata\local\programs\python\python38-32\lib\site-packages\flask\app.py", line 1821, in handle_user_exception
    reraise(exc_type, exc_value, tb)
  File "c:\users\xiaocheng wang\appdata\local\programs\python\python38-32\lib\site-packages\flask\_compat.py", line 39, in reraise
    raise value
  File "c:\users\xiaocheng wang\appdata\local\programs\python\python38-32\lib\site-packages\flask\app.py", line 1950, in full_dispatch_request
    rv = self.dispatch_request()
  File "c:\users\xiaocheng wang\appdata\local\programs\python\python38-32\lib\site-packages\flask\app.py", line 1936, in dispatch_request
    return self.view_functions[rule.endpoint](**req.view_args)
  File "c:\users\xiaocheng wang\appdata\local\programs\python\python38-32\lib\site-packages\flask_admin\base.py", line 69, in inner
    return self._run_view(f, *args, **kwargs)
  File "c:\users\xiaocheng wang\appdata\local\programs\python\python38-32\lib\site-packages\flask_admin\base.py", line 368, in _run_view
    return fn(self, *args, **kwargs)
  File "c:\users\xiaocheng wang\appdata\local\programs\python\python38-32\lib\site-packages\flask_admin\model\base.py", line 1969, in index_view
    count, data = self.get_list(view_args.page, sort_column, view_args.sort_desc,
  File "c:\users\xiaocheng wang\appdata\local\programs\python\python38-32\lib\site-packages\flask_admin\contrib\sqla\view.py", line 1079, in get_list
    query = query.all()
  File "c:\users\xiaocheng wang\appdata\local\programs\python\python38-32\lib\site-packages\sqlalchemy\orm\query.py", line 3246, in all
    return list(self)
  File "c:\users\xiaocheng wang\appdata\local\programs\python\python38-32\lib\site-packages\sqlalchemy\orm\query.py", line 3405, in __iter__
    return self._execute_and_instances(context)
  File "c:\users\xiaocheng wang\appdata\local\programs\python\python38-32\lib\site-packages\sqlalchemy\orm\query.py", line 3430, in _execute_and_instances
    result = conn.execute(querycontext.statement, self._params)
  File "c:\users\xiaocheng wang\appdata\local\programs\python\python38-32\lib\site-packages\sqlalchemy\engine\base.py", line 984, in execute
    return meth(self, multiparams, params)
  File "c:\users\xiaocheng wang\appdata\local\programs\python\python38-32\lib\site-packages\sqlalchemy\sql\elements.py", line 293, in _execute_on_connection
    return connection._execute_clauseelement(self, multiparams, params)
  File "c:\users\xiaocheng wang\appdata\local\programs\python\python38-32\lib\site-packages\sqlalchemy\engine\base.py", line 1097, in _execute_clauseelement
    ret = self._execute_context(
  File "c:\users\xiaocheng wang\appdata\local\programs\python\python38-32\lib\site-packages\sqlalchemy\engine\base.py", line 1287, in _execute_context
    self._handle_dbapi_exception(
  File "c:\users\xiaocheng wang\appdata\local\programs\python\python38-32\lib\site-packages\sqlalchemy\engine\base.py", line 1481, in _handle_dbapi_exception
    util.raise_(
  File "c:\users\xiaocheng wang\appdata\local\programs\python\python38-32\lib\site-packages\sqlalchemy\util\compat.py", line 178, in raise_
    raise exception
  File "c:\users\xiaocheng wang\appdata\local\programs\python\python38-32\lib\site-packages\sqlalchemy\engine\base.py", line 1247, in _execute_context
    self.dialect.do_execute(
  File "c:\users\xiaocheng wang\appdata\local\programs\python\python38-32\lib\site-packages\sqlalchemy\engine\default.py", line 590, in do_execute
    cursor.execute(statement, parameters)
sqlalchemy.exc.OperationalError: (sqlite3.OperationalError) no such column: user_1.confirmed
[SQL: SELECT student.id AS student_id, student.user_id AS student_user_id, student.title AS student_title, student.gender AS student_gender, student.dob AS student_dob, student.ppname AS student_ppname, student.surname AS student_surname, student.firstname AS student_firstname, student.prefname AS student_prefname, student.charname AS student_charname, student.birth_cntry AS student_birth_cntry, student.citizen_cntry AS student_citizen_cntry, student.street_addr AS student_street_addr, student.city_addr AS student_city_addr, student.state_addr AS student_state_addr, student.postcode_addr AS student_postcode_addr, student.cntry_addr AS student_cntry_addr, student.emg_name AS student_emg_name, student.emg_rel AS student_emg_rel, student.emg_ph AS student_emg_ph, student.uni_name AS student_uni_name, student.uni_majors AS student_uni_majors, student.uni_gpa AS student_uni_gpa, student.uni_years AS student_uni_years, student.uni_awards AS student_uni_awards, student.eng_prog AS student_eng_prog, student.eng_prog_choice AS student_eng_prog_choice, student.native_sp AS student_native_sp, student.test_sc AS student_test_sc, student.eng_file AS student_eng_file, student."longQ1" AS "student_longQ1", student."longQ2" AS "student_longQ2", student."longQ3" AS "student_longQ3", student."longQ4" AS "student_longQ4", student.cv_file AS student_cv_file, student.transcr_file AS student_transcr_file, student.tuition_fee AS student_tuition_fee, user_1.id AS user_1_id, user_1.name AS user_1_name, user_1.email AS user_1_email, user_1.confirmed AS user_1_confirmed, user_1.password AS user_1_password, user_1.role AS user_1_role, user_1.registered_on AS user_1_registered_on, user_1.confirmed_on AS user_1_confirmed_on, user_1.password_reset_token AS user_1_password_reset_token 
FROM student LEFT OUTER JOIN user AS user_1 ON user_1.id = student.user_id
 LIMIT ? OFFSET ?]
[parameters: (20, 0)]
(Background on this error at: http://sqlalche.me/e/e3q8)
INFO:werkzeug:127.0.0.1 - - [06/Oct/2020 00:53:52] "[35m[1mGET /admin/student/ HTTP/1.1[0m" 500 -
INFO:werkzeug:127.0.0.1 - - [06/Oct/2020 00:53:53] "[37mGET /admin/preference/ HTTP/1.1[0m" 200 -
ERROR:app:Exception on /admin/user/ [GET]
Traceback (most recent call last):
  File "c:\users\xiaocheng wang\appdata\local\programs\python\python38-32\lib\site-packages\sqlalchemy\engine\base.py", line 1247, in _execute_context
    self.dialect.do_execute(
  File "c:\users\xiaocheng wang\appdata\local\programs\python\python38-32\lib\site-packages\sqlalchemy\engine\default.py", line 590, in do_execute
    cursor.execute(statement, parameters)
sqlite3.OperationalError: no such column: user.confirmed

The above exception was the direct cause of the following exception:

Traceback (most recent call last):
  File "c:\users\xiaocheng wang\appdata\local\programs\python\python38-32\lib\site-packages\flask\app.py", line 2447, in wsgi_app
    response = self.full_dispatch_request()
  File "c:\users\xiaocheng wang\appdata\local\programs\python\python38-32\lib\site-packages\flask\app.py", line 1952, in full_dispatch_request
    rv = self.handle_user_exception(e)
  File "c:\users\xiaocheng wang\appdata\local\programs\python\python38-32\lib\site-packages\flask\app.py", line 1821, in handle_user_exception
    reraise(exc_type, exc_value, tb)
  File "c:\users\xiaocheng wang\appdata\local\programs\python\python38-32\lib\site-packages\flask\_compat.py", line 39, in reraise
    raise value
  File "c:\users\xiaocheng wang\appdata\local\programs\python\python38-32\lib\site-packages\flask\app.py", line 1950, in full_dispatch_request
    rv = self.dispatch_request()
  File "c:\users\xiaocheng wang\appdata\local\programs\python\python38-32\lib\site-packages\flask\app.py", line 1936, in dispatch_request
    return self.view_functions[rule.endpoint](**req.view_args)
  File "c:\users\xiaocheng wang\appdata\local\programs\python\python38-32\lib\site-packages\flask_admin\base.py", line 69, in inner
    return self._run_view(f, *args, **kwargs)
  File "c:\users\xiaocheng wang\appdata\local\programs\python\python38-32\lib\site-packages\flask_admin\base.py", line 368, in _run_view
    return fn(self, *args, **kwargs)
  File "c:\users\xiaocheng wang\appdata\local\programs\python\python38-32\lib\site-packages\flask_admin\model\base.py", line 1969, in index_view
    count, data = self.get_list(view_args.page, sort_column, view_args.sort_desc,
  File "c:\users\xiaocheng wang\appdata\local\programs\python\python38-32\lib\site-packages\flask_admin\contrib\sqla\view.py", line 1079, in get_list
    query = query.all()
  File "c:\users\xiaocheng wang\appdata\local\programs\python\python38-32\lib\site-packages\sqlalchemy\orm\query.py", line 3246, in all
    return list(self)
  File "c:\users\xiaocheng wang\appdata\local\programs\python\python38-32\lib\site-packages\sqlalchemy\orm\query.py", line 3405, in __iter__
    return self._execute_and_instances(context)
  File "c:\users\xiaocheng wang\appdata\local\programs\python\python38-32\lib\site-packages\sqlalchemy\orm\query.py", line 3430, in _execute_and_instances
    result = conn.execute(querycontext.statement, self._params)
  File "c:\users\xiaocheng wang\appdata\local\programs\python\python38-32\lib\site-packages\sqlalchemy\engine\base.py", line 984, in execute
    return meth(self, multiparams, params)
  File "c:\users\xiaocheng wang\appdata\local\programs\python\python38-32\lib\site-packages\sqlalchemy\sql\elements.py", line 293, in _execute_on_connection
    return connection._execute_clauseelement(self, multiparams, params)
  File "c:\users\xiaocheng wang\appdata\local\programs\python\python38-32\lib\site-packages\sqlalchemy\engine\base.py", line 1097, in _execute_clauseelement
    ret = self._execute_context(
  File "c:\users\xiaocheng wang\appdata\local\programs\python\python38-32\lib\site-packages\sqlalchemy\engine\base.py", line 1287, in _execute_context
    self._handle_dbapi_exception(
  File "c:\users\xiaocheng wang\appdata\local\programs\python\python38-32\lib\site-packages\sqlalchemy\engine\base.py", line 1481, in _handle_dbapi_exception
    util.raise_(
  File "c:\users\xiaocheng wang\appdata\local\programs\python\python38-32\lib\site-packages\sqlalchemy\util\compat.py", line 178, in raise_
    raise exception
  File "c:\users\xiaocheng wang\appdata\local\programs\python\python38-32\lib\site-packages\sqlalchemy\engine\base.py", line 1247, in _execute_context
    self.dialect.do_execute(
  File "c:\users\xiaocheng wang\appdata\local\programs\python\python38-32\lib\site-packages\sqlalchemy\engine\default.py", line 590, in do_execute
    cursor.execute(statement, parameters)
sqlalchemy.exc.OperationalError: (sqlite3.OperationalError) no such column: user.confirmed
[SQL: SELECT user.id AS user_id, user.name AS user_name, user.email AS user_email, user.confirmed AS user_confirmed, user.password AS user_password, user.role AS user_role, user.registered_on AS user_registered_on, user.confirmed_on AS user_confirmed_on, user.password_reset_token AS user_password_reset_token 
FROM user
 LIMIT ? OFFSET ?]
[parameters: (20, 0)]
(Background on this error at: http://sqlalche.me/e/e3q8)
INFO:werkzeug:127.0.0.1 - - [06/Oct/2020 00:53:54] "[35m[1mGET /admin/user/ HTTP/1.1[0m" 500 -
INFO:werkzeug:127.0.0.1 - - [06/Oct/2020 00:53:54] "[37mGET /admin/preference/ HTTP/1.1[0m" 200 -
ERROR:app:Exception on /admin/supervisor/ [GET]
Traceback (most recent call last):
  File "c:\users\xiaocheng wang\appdata\local\programs\python\python38-32\lib\site-packages\sqlalchemy\engine\base.py", line 1247, in _execute_context
    self.dialect.do_execute(
  File "c:\users\xiaocheng wang\appdata\local\programs\python\python38-32\lib\site-packages\sqlalchemy\engine\default.py", line 590, in do_execute
    cursor.execute(statement, parameters)
sqlite3.OperationalError: no such column: user_1.confirmed

The above exception was the direct cause of the following exception:

Traceback (most recent call last):
  File "c:\users\xiaocheng wang\appdata\local\programs\python\python38-32\lib\site-packages\flask\app.py", line 2447, in wsgi_app
    response = self.full_dispatch_request()
  File "c:\users\xiaocheng wang\appdata\local\programs\python\python38-32\lib\site-packages\flask\app.py", line 1952, in full_dispatch_request
    rv = self.handle_user_exception(e)
  File "c:\users\xiaocheng wang\appdata\local\programs\python\python38-32\lib\site-packages\flask\app.py", line 1821, in handle_user_exception
    reraise(exc_type, exc_value, tb)
  File "c:\users\xiaocheng wang\appdata\local\programs\python\python38-32\lib\site-packages\flask\_compat.py", line 39, in reraise
    raise value
  File "c:\users\xiaocheng wang\appdata\local\programs\python\python38-32\lib\site-packages\flask\app.py", line 1950, in full_dispatch_request
    rv = self.dispatch_request()
  File "c:\users\xiaocheng wang\appdata\local\programs\python\python38-32\lib\site-packages\flask\app.py", line 1936, in dispatch_request
    return self.view_functions[rule.endpoint](**req.view_args)
  File "c:\users\xiaocheng wang\appdata\local\programs\python\python38-32\lib\site-packages\flask_admin\base.py", line 69, in inner
    return self._run_view(f, *args, **kwargs)
  File "c:\users\xiaocheng wang\appdata\local\programs\python\python38-32\lib\site-packages\flask_admin\base.py", line 368, in _run_view
    return fn(self, *args, **kwargs)
  File "c:\users\xiaocheng wang\appdata\local\programs\python\python38-32\lib\site-packages\flask_admin\model\base.py", line 1969, in index_view
    count, data = self.get_list(view_args.page, sort_column, view_args.sort_desc,
  File "c:\users\xiaocheng wang\appdata\local\programs\python\python38-32\lib\site-packages\flask_admin\contrib\sqla\view.py", line 1079, in get_list
    query = query.all()
  File "c:\users\xiaocheng wang\appdata\local\programs\python\python38-32\lib\site-packages\sqlalchemy\orm\query.py", line 3246, in all
    return list(self)
  File "c:\users\xiaocheng wang\appdata\local\programs\python\python38-32\lib\site-packages\sqlalchemy\orm\query.py", line 3405, in __iter__
    return self._execute_and_instances(context)
  File "c:\users\xiaocheng wang\appdata\local\programs\python\python38-32\lib\site-packages\sqlalchemy\orm\query.py", line 3430, in _execute_and_instances
    result = conn.execute(querycontext.statement, self._params)
  File "c:\users\xiaocheng wang\appdata\local\programs\python\python38-32\lib\site-packages\sqlalchemy\engine\base.py", line 984, in execute
    return meth(self, multiparams, params)
  File "c:\users\xiaocheng wang\appdata\local\programs\python\python38-32\lib\site-packages\sqlalchemy\sql\elements.py", line 293, in _execute_on_connection
    return connection._execute_clauseelement(self, multiparams, params)
  File "c:\users\xiaocheng wang\appdata\local\programs\python\python38-32\lib\site-packages\sqlalchemy\engine\base.py", line 1097, in _execute_clauseelement
    ret = self._execute_context(
  File "c:\users\xiaocheng wang\appdata\local\programs\python\python38-32\lib\site-packages\sqlalchemy\engine\base.py", line 1287, in _execute_context
    self._handle_dbapi_exception(
  File "c:\users\xiaocheng wang\appdata\local\programs\python\python38-32\lib\site-packages\sqlalchemy\engine\base.py", line 1481, in _handle_dbapi_exception
    util.raise_(
  File "c:\users\xiaocheng wang\appdata\local\programs\python\python38-32\lib\site-packages\sqlalchemy\util\compat.py", line 178, in raise_
    raise exception
  File "c:\users\xiaocheng wang\appdata\local\programs\python\python38-32\lib\site-packages\sqlalchemy\engine\base.py", line 1247, in _execute_context
    self.dialect.do_execute(
  File "c:\users\xiaocheng wang\appdata\local\programs\python\python38-32\lib\site-packages\sqlalchemy\engine\default.py", line 590, in do_execute
    cursor.execute(statement, parameters)
sqlalchemy.exc.OperationalError: (sqlite3.OperationalError) no such column: user_1.confirmed
[SQL: SELECT supervisor.id AS supervisor_id, supervisor.user_id AS supervisor_user_id, supervisor.faculty AS supervisor_faculty, supervisor.school AS supervisor_school, user_1.id AS user_1_id, user_1.name AS user_1_name, user_1.email AS user_1_email, user_1.confirmed AS user_1_confirmed, user_1.password AS user_1_password, user_1.role AS user_1_role, user_1.registered_on AS user_1_registered_on, user_1.confirmed_on AS user_1_confirmed_on, user_1.password_reset_token AS user_1_password_reset_token 
FROM supervisor LEFT OUTER JOIN user AS user_1 ON user_1.id = supervisor.user_id
 LIMIT ? OFFSET ?]
[parameters: (20, 0)]
(Background on this error at: http://sqlalche.me/e/e3q8)
INFO:werkzeug:127.0.0.1 - - [06/Oct/2020 00:53:55] "[35m[1mGET /admin/supervisor/ HTTP/1.1[0m" 500 -
INFO:werkzeug:127.0.0.1 - - [06/Oct/2020 00:53:56] "[37mGET /admin/preference/ HTTP/1.1[0m" 200 -
ERROR:app:Exception on /admin/project/ [GET]
Traceback (most recent call last):
  File "c:\users\xiaocheng wang\appdata\local\programs\python\python38-32\lib\site-packages\sqlalchemy\engine\base.py", line 1247, in _execute_context
    self.dialect.do_execute(
  File "c:\users\xiaocheng wang\appdata\local\programs\python\python38-32\lib\site-packages\sqlalchemy\engine\default.py", line 590, in do_execute
    cursor.execute(statement, parameters)
sqlite3.OperationalError: no such column: user_1.confirmed

The above exception was the direct cause of the following exception:

Traceback (most recent call last):
  File "c:\users\xiaocheng wang\appdata\local\programs\python\python38-32\lib\site-packages\flask\app.py", line 2447, in wsgi_app
    response = self.full_dispatch_request()
  File "c:\users\xiaocheng wang\appdata\local\programs\python\python38-32\lib\site-packages\flask\app.py", line 1952, in full_dispatch_request
    rv = self.handle_user_exception(e)
  File "c:\users\xiaocheng wang\appdata\local\programs\python\python38-32\lib\site-packages\flask\app.py", line 1821, in handle_user_exception
    reraise(exc_type, exc_value, tb)
  File "c:\users\xiaocheng wang\appdata\local\programs\python\python38-32\lib\site-packages\flask\_compat.py", line 39, in reraise
    raise value
  File "c:\users\xiaocheng wang\appdata\local\programs\python\python38-32\lib\site-packages\flask\app.py", line 1950, in full_dispatch_request
    rv = self.dispatch_request()
  File "c:\users\xiaocheng wang\appdata\local\programs\python\python38-32\lib\site-packages\flask\app.py", line 1936, in dispatch_request
    return self.view_functions[rule.endpoint](**req.view_args)
  File "c:\users\xiaocheng wang\appdata\local\programs\python\python38-32\lib\site-packages\flask_admin\base.py", line 69, in inner
    return self._run_view(f, *args, **kwargs)
  File "c:\users\xiaocheng wang\appdata\local\programs\python\python38-32\lib\site-packages\flask_admin\base.py", line 368, in _run_view
    return fn(self, *args, **kwargs)
  File "c:\users\xiaocheng wang\appdata\local\programs\python\python38-32\lib\site-packages\flask_admin\model\base.py", line 1969, in index_view
    count, data = self.get_list(view_args.page, sort_column, view_args.sort_desc,
  File "c:\users\xiaocheng wang\appdata\local\programs\python\python38-32\lib\site-packages\flask_admin\contrib\sqla\view.py", line 1079, in get_list
    query = query.all()
  File "c:\users\xiaocheng wang\appdata\local\programs\python\python38-32\lib\site-packages\sqlalchemy\orm\query.py", line 3246, in all
    return list(self)
  File "c:\users\xiaocheng wang\appdata\local\programs\python\python38-32\lib\site-packages\sqlalchemy\orm\query.py", line 3405, in __iter__
    return self._execute_and_instances(context)
  File "c:\users\xiaocheng wang\appdata\local\programs\python\python38-32\lib\site-packages\sqlalchemy\orm\query.py", line 3430, in _execute_and_instances
    result = conn.execute(querycontext.statement, self._params)
  File "c:\users\xiaocheng wang\appdata\local\programs\python\python38-32\lib\site-packages\sqlalchemy\engine\base.py", line 984, in execute
    return meth(self, multiparams, params)
  File "c:\users\xiaocheng wang\appdata\local\programs\python\python38-32\lib\site-packages\sqlalchemy\sql\elements.py", line 293, in _execute_on_connection
    return connection._execute_clauseelement(self, multiparams, params)
  File "c:\users\xiaocheng wang\appdata\local\programs\python\python38-32\lib\site-packages\sqlalchemy\engine\base.py", line 1097, in _execute_clauseelement
    ret = self._execute_context(
  File "c:\users\xiaocheng wang\appdata\local\programs\python\python38-32\lib\site-packages\sqlalchemy\engine\base.py", line 1287, in _execute_context
    self._handle_dbapi_exception(
  File "c:\users\xiaocheng wang\appdata\local\programs\python\python38-32\lib\site-packages\sqlalchemy\engine\base.py", line 1481, in _handle_dbapi_exception
    util.raise_(
  File "c:\users\xiaocheng wang\appdata\local\programs\python\python38-32\lib\site-packages\sqlalchemy\util\compat.py", line 178, in raise_
    raise exception
  File "c:\users\xiaocheng wang\appdata\local\programs\python\python38-32\lib\site-packages\sqlalchemy\engine\base.py", line 1247, in _execute_context
    self.dialect.do_execute(
  File "c:\users\xiaocheng wang\appdata\local\programs\python\python38-32\lib\site-packages\sqlalchemy\engine\default.py", line 590, in do_execute
    cursor.execute(statement, parameters)
sqlalchemy.exc.OperationalError: (sqlite3.OperationalError) no such column: user_1.confirmed
[SQL: SELECT project.id AS project_id, project.user_id AS project_user_id, project.title AS project_title, project.main_supervisor AS project_main_supervisor, project.co_supervisor AS project_co_supervisor, project.proj_group AS project_proj_group, project.proj_desc AS project_proj_desc, project.skills AS project_skills, project.keywords AS project_keywords, project.contact_email AS project_contact_email, project.location AS project_location, project.specific_uni AS project_specific_uni, project.proj_weeks AS project_proj_weeks, project.max_students AS project_max_students, user_1.id AS user_1_id, user_1.name AS user_1_name, user_1.email AS user_1_email, user_1.confirmed AS user_1_confirmed, user_1.password AS user_1_password, user_1.role AS user_1_role, user_1.registered_on AS user_1_registered_on, user_1.confirmed_on AS user_1_confirmed_on, user_1.password_reset_token AS user_1_password_reset_token 
FROM project LEFT OUTER JOIN user AS user_1 ON user_1.id = project.user_id
 LIMIT ? OFFSET ?]
[parameters: (20, 0)]
(Background on this error at: http://sqlalche.me/e/e3q8)
INFO:werkzeug:127.0.0.1 - - [06/Oct/2020 00:53:56] "[35m[1mGET /admin/project/ HTTP/1.1[0m" 500 -
INFO:werkzeug:127.0.0.1 - - [06/Oct/2020 00:53:57] "[37mGET /admin/preference/ HTTP/1.1[0m" 200 -
INFO:werkzeug:127.0.0.1 - - [06/Oct/2020 00:53:58] "[37mGET /admin/ HTTP/1.1[0m" 200 -
INFO:werkzeug:127.0.0.1 - - [06/Oct/2020 00:55:21] "[37mGET / HTTP/1.1[0m" 200 -
INFO:werkzeug:127.0.0.1 - - [06/Oct/2020 00:55:22] "[37mGET /auth/initial-registration HTTP/1.1[0m" 200 -
INFO:werkzeug:127.0.0.1 - - [06/Oct/2020 00:55:48] "[37mGET /index HTTP/1.1[0m" 200 -
INFO:werkzeug:127.0.0.1 - - [06/Oct/2020 00:55:49] "[37mGET /login HTTP/1.1[0m" 200 -
ERROR:app:Exception on /login [POST]
Traceback (most recent call last):
  File "c:\users\xiaocheng wang\appdata\local\programs\python\python38-32\lib\site-packages\sqlalchemy\engine\base.py", line 1247, in _execute_context
    self.dialect.do_execute(
  File "c:\users\xiaocheng wang\appdata\local\programs\python\python38-32\lib\site-packages\sqlalchemy\engine\default.py", line 590, in do_execute
    cursor.execute(statement, parameters)
sqlite3.OperationalError: no such column: user.confirmed

The above exception was the direct cause of the following exception:

Traceback (most recent call last):
  File "c:\users\xiaocheng wang\appdata\local\programs\python\python38-32\lib\site-packages\flask\app.py", line 2447, in wsgi_app
    response = self.full_dispatch_request()
  File "c:\users\xiaocheng wang\appdata\local\programs\python\python38-32\lib\site-packages\flask\app.py", line 1952, in full_dispatch_request
    rv = self.handle_user_exception(e)
  File "c:\users\xiaocheng wang\appdata\local\programs\python\python38-32\lib\site-packages\flask\app.py", line 1821, in handle_user_exception
    reraise(exc_type, exc_value, tb)
  File "c:\users\xiaocheng wang\appdata\local\programs\python\python38-32\lib\site-packages\flask\_compat.py", line 39, in reraise
    raise value
  File "c:\users\xiaocheng wang\appdata\local\programs\python\python38-32\lib\site-packages\flask\app.py", line 1950, in full_dispatch_request
    rv = self.dispatch_request()
  File "c:\users\xiaocheng wang\appdata\local\programs\python\python38-32\lib\site-packages\flask\app.py", line 1936, in dispatch_request
    return self.view_functions[rule.endpoint](**req.view_args)
  File "E:\Study\UWA\Year3\S2\CITS3200\project\SDURI-Admin-Platform\app\routes.py", line 48, in login
    user = User.query.filter_by(email=form.email.data).first()
  File "c:\users\xiaocheng wang\appdata\local\programs\python\python38-32\lib\site-packages\sqlalchemy\orm\query.py", line 3300, in first
    ret = list(self[0:1])
  File "c:\users\xiaocheng wang\appdata\local\programs\python\python38-32\lib\site-packages\sqlalchemy\orm\query.py", line 3078, in __getitem__
    return list(res)
  File "c:\users\xiaocheng wang\appdata\local\programs\python\python38-32\lib\site-packages\sqlalchemy\orm\query.py", line 3405, in __iter__
    return self._execute_and_instances(context)
  File "c:\users\xiaocheng wang\appdata\local\programs\python\python38-32\lib\site-packages\sqlalchemy\orm\query.py", line 3430, in _execute_and_instances
    result = conn.execute(querycontext.statement, self._params)
  File "c:\users\xiaocheng wang\appdata\local\programs\python\python38-32\lib\site-packages\sqlalchemy\engine\base.py", line 984, in execute
    return meth(self, multiparams, params)
  File "c:\users\xiaocheng wang\appdata\local\programs\python\python38-32\lib\site-packages\sqlalchemy\sql\elements.py", line 293, in _execute_on_connection
    return connection._execute_clauseelement(self, multiparams, params)
  File "c:\users\xiaocheng wang\appdata\local\programs\python\python38-32\lib\site-packages\sqlalchemy\engine\base.py", line 1097, in _execute_clauseelement
    ret = self._execute_context(
  File "c:\users\xiaocheng wang\appdata\local\programs\python\python38-32\lib\site-packages\sqlalchemy\engine\base.py", line 1287, in _execute_context
    self._handle_dbapi_exception(
  File "c:\users\xiaocheng wang\appdata\local\programs\python\python38-32\lib\site-packages\sqlalchemy\engine\base.py", line 1481, in _handle_dbapi_exception
    util.raise_(
  File "c:\users\xiaocheng wang\appdata\local\programs\python\python38-32\lib\site-packages\sqlalchemy\util\compat.py", line 178, in raise_
    raise exception
  File "c:\users\xiaocheng wang\appdata\local\programs\python\python38-32\lib\site-packages\sqlalchemy\engine\base.py", line 1247, in _execute_context
    self.dialect.do_execute(
  File "c:\users\xiaocheng wang\appdata\local\programs\python\python38-32\lib\site-packages\sqlalchemy\engine\default.py", line 590, in do_execute
    cursor.execute(statement, parameters)
sqlalchemy.exc.OperationalError: (sqlite3.OperationalError) no such column: user.confirmed
[SQL: SELECT user.id AS user_id, user.name AS user_name, user.email AS user_email, user.confirmed AS user_confirmed, user.password AS user_password, user.role AS user_role, user.registered_on AS user_registered_on, user.confirmed_on AS user_confirmed_on, user.password_reset_token AS user_password_reset_token 
FROM user 
WHERE user.email = ?
 LIMIT ? OFFSET ?]
[parameters: ('test1@cheng.com', 1, 0)]
(Background on this error at: http://sqlalche.me/e/e3q8)
INFO:werkzeug:127.0.0.1 - - [06/Oct/2020 00:55:55] "[35m[1mPOST /login HTTP/1.1[0m" 500 -
INFO:werkzeug:127.0.0.1 - - [06/Oct/2020 00:55:56] "[37mGET /login HTTP/1.1[0m" 200 -
ERROR:app:Exception on /login [POST]
Traceback (most recent call last):
  File "c:\users\xiaocheng wang\appdata\local\programs\python\python38-32\lib\site-packages\sqlalchemy\engine\base.py", line 1247, in _execute_context
    self.dialect.do_execute(
  File "c:\users\xiaocheng wang\appdata\local\programs\python\python38-32\lib\site-packages\sqlalchemy\engine\default.py", line 590, in do_execute
    cursor.execute(statement, parameters)
sqlite3.OperationalError: no such column: user.confirmed

The above exception was the direct cause of the following exception:

Traceback (most recent call last):
  File "c:\users\xiaocheng wang\appdata\local\programs\python\python38-32\lib\site-packages\flask\app.py", line 2447, in wsgi_app
    response = self.full_dispatch_request()
  File "c:\users\xiaocheng wang\appdata\local\programs\python\python38-32\lib\site-packages\flask\app.py", line 1952, in full_dispatch_request
    rv = self.handle_user_exception(e)
  File "c:\users\xiaocheng wang\appdata\local\programs\python\python38-32\lib\site-packages\flask\app.py", line 1821, in handle_user_exception
    reraise(exc_type, exc_value, tb)
  File "c:\users\xiaocheng wang\appdata\local\programs\python\python38-32\lib\site-packages\flask\_compat.py", line 39, in reraise
    raise value
  File "c:\users\xiaocheng wang\appdata\local\programs\python\python38-32\lib\site-packages\flask\app.py", line 1950, in full_dispatch_request
    rv = self.dispatch_request()
  File "c:\users\xiaocheng wang\appdata\local\programs\python\python38-32\lib\site-packages\flask\app.py", line 1936, in dispatch_request
    return self.view_functions[rule.endpoint](**req.view_args)
  File "E:\Study\UWA\Year3\S2\CITS3200\project\SDURI-Admin-Platform\app\routes.py", line 48, in login
    user = User.query.filter_by(email=form.email.data).first()
  File "c:\users\xiaocheng wang\appdata\local\programs\python\python38-32\lib\site-packages\sqlalchemy\orm\query.py", line 3300, in first
    ret = list(self[0:1])
  File "c:\users\xiaocheng wang\appdata\local\programs\python\python38-32\lib\site-packages\sqlalchemy\orm\query.py", line 3078, in __getitem__
    return list(res)
  File "c:\users\xiaocheng wang\appdata\local\programs\python\python38-32\lib\site-packages\sqlalchemy\orm\query.py", line 3405, in __iter__
    return self._execute_and_instances(context)
  File "c:\users\xiaocheng wang\appdata\local\programs\python\python38-32\lib\site-packages\sqlalchemy\orm\query.py", line 3430, in _execute_and_instances
    result = conn.execute(querycontext.statement, self._params)
  File "c:\users\xiaocheng wang\appdata\local\programs\python\python38-32\lib\site-packages\sqlalchemy\engine\base.py", line 984, in execute
    return meth(self, multiparams, params)
  File "c:\users\xiaocheng wang\appdata\local\programs\python\python38-32\lib\site-packages\sqlalchemy\sql\elements.py", line 293, in _execute_on_connection
    return connection._execute_clauseelement(self, multiparams, params)
  File "c:\users\xiaocheng wang\appdata\local\programs\python\python38-32\lib\site-packages\sqlalchemy\engine\base.py", line 1097, in _execute_clauseelement
    ret = self._execute_context(
  File "c:\users\xiaocheng wang\appdata\local\programs\python\python38-32\lib\site-packages\sqlalchemy\engine\base.py", line 1287, in _execute_context
    self._handle_dbapi_exception(
  File "c:\users\xiaocheng wang\appdata\local\programs\python\python38-32\lib\site-packages\sqlalchemy\engine\base.py", line 1481, in _handle_dbapi_exception
    util.raise_(
  File "c:\users\xiaocheng wang\appdata\local\programs\python\python38-32\lib\site-packages\sqlalchemy\util\compat.py", line 178, in raise_
    raise exception
  File "c:\users\xiaocheng wang\appdata\local\programs\python\python38-32\lib\site-packages\sqlalchemy\engine\base.py", line 1247, in _execute_context
    self.dialect.do_execute(
  File "c:\users\xiaocheng wang\appdata\local\programs\python\python38-32\lib\site-packages\sqlalchemy\engine\default.py", line 590, in do_execute
    cursor.execute(statement, parameters)
sqlalchemy.exc.OperationalError: (sqlite3.OperationalError) no such column: user.confirmed
[SQL: SELECT user.id AS user_id, user.name AS user_name, user.email AS user_email, user.confirmed AS user_confirmed, user.password AS user_password, user.role AS user_role, user.registered_on AS user_registered_on, user.confirmed_on AS user_confirmed_on, user.password_reset_token AS user_password_reset_token 
FROM user 
WHERE user.email = ?
 LIMIT ? OFFSET ?]
[parameters: ('wxc991216@163.com', 1, 0)]
(Background on this error at: http://sqlalche.me/e/e3q8)
INFO:werkzeug:127.0.0.1 - - [06/Oct/2020 00:55:59] "[35m[1mPOST /login HTTP/1.1[0m" 500 -
INFO:werkzeug:127.0.0.1 - - [06/Oct/2020 00:56:00] "[37mGET /login HTTP/1.1[0m" 200 -
INFO:werkzeug:127.0.0.1 - - [06/Oct/2020 00:56:07] "[37mPOST /login HTTP/1.1[0m" 200 -
ERROR:app:Exception on /login [POST]
Traceback (most recent call last):
  File "c:\users\xiaocheng wang\appdata\local\programs\python\python38-32\lib\site-packages\sqlalchemy\engine\base.py", line 1247, in _execute_context
    self.dialect.do_execute(
  File "c:\users\xiaocheng wang\appdata\local\programs\python\python38-32\lib\site-packages\sqlalchemy\engine\default.py", line 590, in do_execute
    cursor.execute(statement, parameters)
sqlite3.OperationalError: no such column: user.confirmed

The above exception was the direct cause of the following exception:

Traceback (most recent call last):
  File "c:\users\xiaocheng wang\appdata\local\programs\python\python38-32\lib\site-packages\flask\app.py", line 2447, in wsgi_app
    response = self.full_dispatch_request()
  File "c:\users\xiaocheng wang\appdata\local\programs\python\python38-32\lib\site-packages\flask\app.py", line 1952, in full_dispatch_request
    rv = self.handle_user_exception(e)
  File "c:\users\xiaocheng wang\appdata\local\programs\python\python38-32\lib\site-packages\flask\app.py", line 1821, in handle_user_exception
    reraise(exc_type, exc_value, tb)
  File "c:\users\xiaocheng wang\appdata\local\programs\python\python38-32\lib\site-packages\flask\_compat.py", line 39, in reraise
    raise value
  File "c:\users\xiaocheng wang\appdata\local\programs\python\python38-32\lib\site-packages\flask\app.py", line 1950, in full_dispatch_request
    rv = self.dispatch_request()
  File "c:\users\xiaocheng wang\appdata\local\programs\python\python38-32\lib\site-packages\flask\app.py", line 1936, in dispatch_request
    return self.view_functions[rule.endpoint](**req.view_args)
  File "E:\Study\UWA\Year3\S2\CITS3200\project\SDURI-Admin-Platform\app\routes.py", line 48, in login
    user = User.query.filter_by(email=form.email.data).first()
  File "c:\users\xiaocheng wang\appdata\local\programs\python\python38-32\lib\site-packages\sqlalchemy\orm\query.py", line 3300, in first
    ret = list(self[0:1])
  File "c:\users\xiaocheng wang\appdata\local\programs\python\python38-32\lib\site-packages\sqlalchemy\orm\query.py", line 3078, in __getitem__
    return list(res)
  File "c:\users\xiaocheng wang\appdata\local\programs\python\python38-32\lib\site-packages\sqlalchemy\orm\query.py", line 3405, in __iter__
    return self._execute_and_instances(context)
  File "c:\users\xiaocheng wang\appdata\local\programs\python\python38-32\lib\site-packages\sqlalchemy\orm\query.py", line 3430, in _execute_and_instances
    result = conn.execute(querycontext.statement, self._params)
  File "c:\users\xiaocheng wang\appdata\local\programs\python\python38-32\lib\site-packages\sqlalchemy\engine\base.py", line 984, in execute
    return meth(self, multiparams, params)
  File "c:\users\xiaocheng wang\appdata\local\programs\python\python38-32\lib\site-packages\sqlalchemy\sql\elements.py", line 293, in _execute_on_connection
    return connection._execute_clauseelement(self, multiparams, params)
  File "c:\users\xiaocheng wang\appdata\local\programs\python\python38-32\lib\site-packages\sqlalchemy\engine\base.py", line 1097, in _execute_clauseelement
    ret = self._execute_context(
  File "c:\users\xiaocheng wang\appdata\local\programs\python\python38-32\lib\site-packages\sqlalchemy\engine\base.py", line 1287, in _execute_context
    self._handle_dbapi_exception(
  File "c:\users\xiaocheng wang\appdata\local\programs\python\python38-32\lib\site-packages\sqlalchemy\engine\base.py", line 1481, in _handle_dbapi_exception
    util.raise_(
  File "c:\users\xiaocheng wang\appdata\local\programs\python\python38-32\lib\site-packages\sqlalchemy\util\compat.py", line 178, in raise_
    raise exception
  File "c:\users\xiaocheng wang\appdata\local\programs\python\python38-32\lib\site-packages\sqlalchemy\engine\base.py", line 1247, in _execute_context
    self.dialect.do_execute(
  File "c:\users\xiaocheng wang\appdata\local\programs\python\python38-32\lib\site-packages\sqlalchemy\engine\default.py", line 590, in do_execute
    cursor.execute(statement, parameters)
sqlalchemy.exc.OperationalError: (sqlite3.OperationalError) no such column: user.confirmed
[SQL: SELECT user.id AS user_id, user.name AS user_name, user.email AS user_email, user.confirmed AS user_confirmed, user.password AS user_password, user.role AS user_role, user.registered_on AS user_registered_on, user.confirmed_on AS user_confirmed_on, user.password_reset_token AS user_password_reset_token 
FROM user 
WHERE user.email = ?
 LIMIT ? OFFSET ?]
[parameters: ('wxc991216@gmail.com', 1, 0)]
(Background on this error at: http://sqlalche.me/e/e3q8)
INFO:werkzeug:127.0.0.1 - - [06/Oct/2020 00:56:13] "[35m[1mPOST /login HTTP/1.1[0m" 500 -
