INFO:werkzeug: * Running on http://127.0.0.1:5000/ (Press CTRL+C to quit)
INFO:werkzeug:127.0.0.1 - - [23/Sep/2020 05:43:07] "[32mGET / HTTP/1.1[0m" 302 -
INFO:werkzeug:127.0.0.1 - - [23/Sep/2020 05:43:08] "[37mGET /supervisor/Cheng2 HTTP/1.1[0m" 200 -
INFO:werkzeug:127.0.0.1 - - [23/Sep/2020 05:43:08] "[37mGET /static/css/style.css HTTP/1.1[0m" 200 -
INFO:werkzeug:127.0.0.1 - - [23/Sep/2020 05:43:08] "[37mGET /static/images/uwa_logo.png HTTP/1.1[0m" 200 -
INFO:werkzeug:127.0.0.1 - - [23/Sep/2020 05:43:09] "[37mGET /add-project/Cheng2 HTTP/1.1[0m" 200 -
INFO:werkzeug:127.0.0.1 - - [23/Sep/2020 05:43:22] "[32mGET /admin HTTP/1.1[0m" 308 -
INFO:werkzeug:127.0.0.1 - - [23/Sep/2020 05:43:22] "[37mGET /admin/ HTTP/1.1[0m" 200 -
INFO:werkzeug:127.0.0.1 - - [23/Sep/2020 05:43:22] "[36mGET /admin/static/bootstrap/bootstrap3/css/bootstrap-theme.min.css?v=3.3.5 HTTP/1.1[0m" 304 -
INFO:werkzeug:127.0.0.1 - - [23/Sep/2020 05:43:22] "[36mGET /admin/static/bootstrap/bootstrap3/swatch/default/bootstrap.min.css?v=3.3.5 HTTP/1.1[0m" 304 -
INFO:werkzeug:127.0.0.1 - - [23/Sep/2020 05:43:22] "[36mGET /admin/static/admin/css/bootstrap3/admin.css?v=1.1.1 HTTP/1.1[0m" 304 -
INFO:werkzeug:127.0.0.1 - - [23/Sep/2020 05:43:22] "[36mGET /admin/static/admin/css/bootstrap3/submenu.css HTTP/1.1[0m" 304 -
INFO:werkzeug:127.0.0.1 - - [23/Sep/2020 05:43:22] "[37mGET /admin/static/admin/js/helpers.js?v=1.0.0 HTTP/1.1[0m" 200 -
INFO:werkzeug:127.0.0.1 - - [23/Sep/2020 05:43:22] "[37mGET /admin/static/vendor/moment.min.js?v=2.22.2 HTTP/1.1[0m" 200 -
INFO:werkzeug:127.0.0.1 - - [23/Sep/2020 05:43:22] "[37mGET /admin/static/bootstrap/bootstrap3/js/bootstrap.min.js?v=3.3.5 HTTP/1.1[0m" 200 -
INFO:werkzeug:127.0.0.1 - - [23/Sep/2020 05:43:22] "[37mGET /admin/static/vendor/select2/select2.min.js?v=3.5.2 HTTP/1.1[0m" 200 -
INFO:werkzeug:127.0.0.1 - - [23/Sep/2020 05:43:22] "[37mGET /admin/static/vendor/jquery.min.js?v=3.3.1 HTTP/1.1[0m" 200 -
ERROR:app:Exception on /favicon.ico [GET]
Traceback (most recent call last):
  File "c:\users\xiaocheng wang\appdata\local\programs\python\python38-32\lib\site-packages\flask\app.py", line 2447, in wsgi_app
    response = self.full_dispatch_request()
  File "c:\users\xiaocheng wang\appdata\local\programs\python\python38-32\lib\site-packages\flask\app.py", line 1952, in full_dispatch_request
    rv = self.handle_user_exception(e)
  File "c:\users\xiaocheng wang\appdata\local\programs\python\python38-32\lib\site-packages\flask\app.py", line 1821, in handle_user_exception
    reraise(exc_type, exc_value, tb)
  File "c:\users\xiaocheng wang\appdata\local\programs\python\python38-32\lib\site-packages\flask\_compat.py", line 39, in reraise
    raise value
  File "c:\users\xiaocheng wang\appdata\local\programs\python\python38-32\lib\site-packages\flask\app.py", line 1950, in full_dispatch_request
    rv = self.dispatch_request()
  File "c:\users\xiaocheng wang\appdata\local\programs\python\python38-32\lib\site-packages\flask\app.py", line 1936, in dispatch_request
    return self.view_functions[rule.endpoint](**req.view_args)
  File "E:\Study\UWA\Year3\S2\CITS3200\project\SDURI-Admin-Platform\app\routes.py", line 32, in favicon
    return send_from_directory(os.path.join(app.root_path, 'static'),
NameError: name 'send_from_directory' is not defined
INFO:werkzeug:127.0.0.1 - - [23/Sep/2020 05:43:23] "[35m[1mGET /favicon.ico HTTP/1.1[0m" 500 -
INFO:werkzeug:127.0.0.1 - - [23/Sep/2020 05:43:24] "[37mGET /admin/project/ HTTP/1.1[0m" 200 -
INFO:werkzeug:127.0.0.1 - - [23/Sep/2020 05:43:24] "[36mGET /admin/static/vendor/select2/select2.css?v=3.5.2 HTTP/1.1[0m" 304 -
INFO:werkzeug:127.0.0.1 - - [23/Sep/2020 05:43:24] "[36mGET /admin/static/vendor/select2/select2-bootstrap3.css?v=1.4.6 HTTP/1.1[0m" 304 -
INFO:werkzeug:127.0.0.1 - - [23/Sep/2020 05:43:24] "[36mGET /admin/static/vendor/bootstrap-daterangepicker/daterangepicker-bs3.css?v=1.3.22 HTTP/1.1[0m" 304 -
INFO:werkzeug:127.0.0.1 - - [23/Sep/2020 05:43:24] "[37mGET /admin/static/admin/js/filters.js?v=1.0.0 HTTP/1.1[0m" 200 -
INFO:werkzeug:127.0.0.1 - - [23/Sep/2020 05:43:24] "[37mGET /admin/static/admin/js/actions.js?v=1.0.0 HTTP/1.1[0m" 200 -
INFO:werkzeug:127.0.0.1 - - [23/Sep/2020 05:43:24] "[37mGET /admin/static/admin/js/form.js?v=1.0.1 HTTP/1.1[0m" 200 -
INFO:werkzeug:127.0.0.1 - - [23/Sep/2020 05:43:24] "[37mGET /admin/static/vendor/bootstrap-daterangepicker/daterangepicker.js?v=1.3.22 HTTP/1.1[0m" 200 -
ERROR:app:Exception on /favicon.ico [GET]
Traceback (most recent call last):
  File "c:\users\xiaocheng wang\appdata\local\programs\python\python38-32\lib\site-packages\flask\app.py", line 2447, in wsgi_app
    response = self.full_dispatch_request()
  File "c:\users\xiaocheng wang\appdata\local\programs\python\python38-32\lib\site-packages\flask\app.py", line 1952, in full_dispatch_request
    rv = self.handle_user_exception(e)
  File "c:\users\xiaocheng wang\appdata\local\programs\python\python38-32\lib\site-packages\flask\app.py", line 1821, in handle_user_exception
    reraise(exc_type, exc_value, tb)
  File "c:\users\xiaocheng wang\appdata\local\programs\python\python38-32\lib\site-packages\flask\_compat.py", line 39, in reraise
    raise value
  File "c:\users\xiaocheng wang\appdata\local\programs\python\python38-32\lib\site-packages\flask\app.py", line 1950, in full_dispatch_request
    rv = self.dispatch_request()
  File "c:\users\xiaocheng wang\appdata\local\programs\python\python38-32\lib\site-packages\flask\app.py", line 1936, in dispatch_request
    return self.view_functions[rule.endpoint](**req.view_args)
  File "E:\Study\UWA\Year3\S2\CITS3200\project\SDURI-Admin-Platform\app\routes.py", line 32, in favicon
    return send_from_directory(os.path.join(app.root_path, 'static'),
NameError: name 'send_from_directory' is not defined
INFO:werkzeug:127.0.0.1 - - [23/Sep/2020 05:43:24] "[35m[1mGET /favicon.ico HTTP/1.1[0m" 500 -
INFO:werkzeug:127.0.0.1 - - [23/Sep/2020 05:43:26] "[37mPOST /add-project/Cheng2 HTTP/1.1[0m" 200 -
INFO:werkzeug:127.0.0.1 - - [23/Sep/2020 05:43:28] "[37mGET /admin/supervisor/ HTTP/1.1[0m" 200 -
INFO:werkzeug:127.0.0.1 - - [23/Sep/2020 05:43:28] "[37mGET /admin/static/bootstrap/bootstrap3/swatch/fonts/glyphicons-halflings-regular.woff2 HTTP/1.1[0m" 200 -
ERROR:app:Exception on /favicon.ico [GET]
Traceback (most recent call last):
  File "c:\users\xiaocheng wang\appdata\local\programs\python\python38-32\lib\site-packages\flask\app.py", line 2447, in wsgi_app
    response = self.full_dispatch_request()
  File "c:\users\xiaocheng wang\appdata\local\programs\python\python38-32\lib\site-packages\flask\app.py", line 1952, in full_dispatch_request
    rv = self.handle_user_exception(e)
  File "c:\users\xiaocheng wang\appdata\local\programs\python\python38-32\lib\site-packages\flask\app.py", line 1821, in handle_user_exception
    reraise(exc_type, exc_value, tb)
  File "c:\users\xiaocheng wang\appdata\local\programs\python\python38-32\lib\site-packages\flask\_compat.py", line 39, in reraise
    raise value
  File "c:\users\xiaocheng wang\appdata\local\programs\python\python38-32\lib\site-packages\flask\app.py", line 1950, in full_dispatch_request
    rv = self.dispatch_request()
  File "c:\users\xiaocheng wang\appdata\local\programs\python\python38-32\lib\site-packages\flask\app.py", line 1936, in dispatch_request
    return self.view_functions[rule.endpoint](**req.view_args)
  File "E:\Study\UWA\Year3\S2\CITS3200\project\SDURI-Admin-Platform\app\routes.py", line 32, in favicon
    return send_from_directory(os.path.join(app.root_path, 'static'),
NameError: name 'send_from_directory' is not defined
INFO:werkzeug:127.0.0.1 - - [23/Sep/2020 05:43:28] "[35m[1mGET /favicon.ico HTTP/1.1[0m" 500 -
INFO:werkzeug:127.0.0.1 - - [23/Sep/2020 05:43:29] "[37mGET /admin/project/ HTTP/1.1[0m" 200 -
ERROR:app:Exception on /favicon.ico [GET]
Traceback (most recent call last):
  File "c:\users\xiaocheng wang\appdata\local\programs\python\python38-32\lib\site-packages\flask\app.py", line 2447, in wsgi_app
    response = self.full_dispatch_request()
  File "c:\users\xiaocheng wang\appdata\local\programs\python\python38-32\lib\site-packages\flask\app.py", line 1952, in full_dispatch_request
    rv = self.handle_user_exception(e)
  File "c:\users\xiaocheng wang\appdata\local\programs\python\python38-32\lib\site-packages\flask\app.py", line 1821, in handle_user_exception
    reraise(exc_type, exc_value, tb)
  File "c:\users\xiaocheng wang\appdata\local\programs\python\python38-32\lib\site-packages\flask\_compat.py", line 39, in reraise
    raise value
  File "c:\users\xiaocheng wang\appdata\local\programs\python\python38-32\lib\site-packages\flask\app.py", line 1950, in full_dispatch_request
    rv = self.dispatch_request()
  File "c:\users\xiaocheng wang\appdata\local\programs\python\python38-32\lib\site-packages\flask\app.py", line 1936, in dispatch_request
    return self.view_functions[rule.endpoint](**req.view_args)
  File "E:\Study\UWA\Year3\S2\CITS3200\project\SDURI-Admin-Platform\app\routes.py", line 32, in favicon
    return send_from_directory(os.path.join(app.root_path, 'static'),
NameError: name 'send_from_directory' is not defined
INFO:werkzeug:127.0.0.1 - - [23/Sep/2020 05:43:29] "[35m[1mGET /favicon.ico HTTP/1.1[0m" 500 -
INFO:werkzeug:127.0.0.1 - - [23/Sep/2020 05:43:29] "[37mGET /admin/supervisor/ HTTP/1.1[0m" 200 -
ERROR:app:Exception on /favicon.ico [GET]
Traceback (most recent call last):
  File "c:\users\xiaocheng wang\appdata\local\programs\python\python38-32\lib\site-packages\flask\app.py", line 2447, in wsgi_app
    response = self.full_dispatch_request()
  File "c:\users\xiaocheng wang\appdata\local\programs\python\python38-32\lib\site-packages\flask\app.py", line 1952, in full_dispatch_request
    rv = self.handle_user_exception(e)
  File "c:\users\xiaocheng wang\appdata\local\programs\python\python38-32\lib\site-packages\flask\app.py", line 1821, in handle_user_exception
    reraise(exc_type, exc_value, tb)
  File "c:\users\xiaocheng wang\appdata\local\programs\python\python38-32\lib\site-packages\flask\_compat.py", line 39, in reraise
    raise value
  File "c:\users\xiaocheng wang\appdata\local\programs\python\python38-32\lib\site-packages\flask\app.py", line 1950, in full_dispatch_request
    rv = self.dispatch_request()
  File "c:\users\xiaocheng wang\appdata\local\programs\python\python38-32\lib\site-packages\flask\app.py", line 1936, in dispatch_request
    return self.view_functions[rule.endpoint](**req.view_args)
  File "E:\Study\UWA\Year3\S2\CITS3200\project\SDURI-Admin-Platform\app\routes.py", line 32, in favicon
    return send_from_directory(os.path.join(app.root_path, 'static'),
NameError: name 'send_from_directory' is not defined
INFO:werkzeug:127.0.0.1 - - [23/Sep/2020 05:43:29] "[35m[1mGET /favicon.ico HTTP/1.1[0m" 500 -
INFO:werkzeug:127.0.0.1 - - [23/Sep/2020 05:43:30] "[37mGET /admin/student/ HTTP/1.1[0m" 200 -
ERROR:app:Exception on /favicon.ico [GET]
Traceback (most recent call last):
  File "c:\users\xiaocheng wang\appdata\local\programs\python\python38-32\lib\site-packages\flask\app.py", line 2447, in wsgi_app
    response = self.full_dispatch_request()
  File "c:\users\xiaocheng wang\appdata\local\programs\python\python38-32\lib\site-packages\flask\app.py", line 1952, in full_dispatch_request
    rv = self.handle_user_exception(e)
  File "c:\users\xiaocheng wang\appdata\local\programs\python\python38-32\lib\site-packages\flask\app.py", line 1821, in handle_user_exception
    reraise(exc_type, exc_value, tb)
  File "c:\users\xiaocheng wang\appdata\local\programs\python\python38-32\lib\site-packages\flask\_compat.py", line 39, in reraise
    raise value
  File "c:\users\xiaocheng wang\appdata\local\programs\python\python38-32\lib\site-packages\flask\app.py", line 1950, in full_dispatch_request
    rv = self.dispatch_request()
  File "c:\users\xiaocheng wang\appdata\local\programs\python\python38-32\lib\site-packages\flask\app.py", line 1936, in dispatch_request
    return self.view_functions[rule.endpoint](**req.view_args)
  File "E:\Study\UWA\Year3\S2\CITS3200\project\SDURI-Admin-Platform\app\routes.py", line 32, in favicon
    return send_from_directory(os.path.join(app.root_path, 'static'),
NameError: name 'send_from_directory' is not defined
INFO:werkzeug:127.0.0.1 - - [23/Sep/2020 05:43:30] "[35m[1mGET /favicon.ico HTTP/1.1[0m" 500 -
INFO:werkzeug:127.0.0.1 - - [23/Sep/2020 05:43:30] "[37mGET /admin/user/ HTTP/1.1[0m" 200 -
ERROR:app:Exception on /favicon.ico [GET]
Traceback (most recent call last):
  File "c:\users\xiaocheng wang\appdata\local\programs\python\python38-32\lib\site-packages\flask\app.py", line 2447, in wsgi_app
    response = self.full_dispatch_request()
  File "c:\users\xiaocheng wang\appdata\local\programs\python\python38-32\lib\site-packages\flask\app.py", line 1952, in full_dispatch_request
    rv = self.handle_user_exception(e)
  File "c:\users\xiaocheng wang\appdata\local\programs\python\python38-32\lib\site-packages\flask\app.py", line 1821, in handle_user_exception
    reraise(exc_type, exc_value, tb)
  File "c:\users\xiaocheng wang\appdata\local\programs\python\python38-32\lib\site-packages\flask\_compat.py", line 39, in reraise
    raise value
  File "c:\users\xiaocheng wang\appdata\local\programs\python\python38-32\lib\site-packages\flask\app.py", line 1950, in full_dispatch_request
    rv = self.dispatch_request()
  File "c:\users\xiaocheng wang\appdata\local\programs\python\python38-32\lib\site-packages\flask\app.py", line 1936, in dispatch_request
    return self.view_functions[rule.endpoint](**req.view_args)
  File "E:\Study\UWA\Year3\S2\CITS3200\project\SDURI-Admin-Platform\app\routes.py", line 32, in favicon
    return send_from_directory(os.path.join(app.root_path, 'static'),
NameError: name 'send_from_directory' is not defined
INFO:werkzeug:127.0.0.1 - - [23/Sep/2020 05:43:31] "[35m[1mGET /favicon.ico HTTP/1.1[0m" 500 -
INFO:werkzeug:127.0.0.1 - - [23/Sep/2020 05:43:31] "[37mGET /admin/ HTTP/1.1[0m" 200 -
ERROR:app:Exception on /favicon.ico [GET]
Traceback (most recent call last):
  File "c:\users\xiaocheng wang\appdata\local\programs\python\python38-32\lib\site-packages\flask\app.py", line 2447, in wsgi_app
    response = self.full_dispatch_request()
  File "c:\users\xiaocheng wang\appdata\local\programs\python\python38-32\lib\site-packages\flask\app.py", line 1952, in full_dispatch_request
    rv = self.handle_user_exception(e)
  File "c:\users\xiaocheng wang\appdata\local\programs\python\python38-32\lib\site-packages\flask\app.py", line 1821, in handle_user_exception
    reraise(exc_type, exc_value, tb)
  File "c:\users\xiaocheng wang\appdata\local\programs\python\python38-32\lib\site-packages\flask\_compat.py", line 39, in reraise
    raise value
  File "c:\users\xiaocheng wang\appdata\local\programs\python\python38-32\lib\site-packages\flask\app.py", line 1950, in full_dispatch_request
    rv = self.dispatch_request()
  File "c:\users\xiaocheng wang\appdata\local\programs\python\python38-32\lib\site-packages\flask\app.py", line 1936, in dispatch_request
    return self.view_functions[rule.endpoint](**req.view_args)
  File "E:\Study\UWA\Year3\S2\CITS3200\project\SDURI-Admin-Platform\app\routes.py", line 32, in favicon
    return send_from_directory(os.path.join(app.root_path, 'static'),
NameError: name 'send_from_directory' is not defined
INFO:werkzeug:127.0.0.1 - - [23/Sep/2020 05:43:31] "[35m[1mGET /favicon.ico HTTP/1.1[0m" 500 -
INFO:werkzeug:127.0.0.1 - - [23/Sep/2020 05:43:32] "[37mGET /admin/user/ HTTP/1.1[0m" 200 -
ERROR:app:Exception on /favicon.ico [GET]
Traceback (most recent call last):
  File "c:\users\xiaocheng wang\appdata\local\programs\python\python38-32\lib\site-packages\flask\app.py", line 2447, in wsgi_app
    response = self.full_dispatch_request()
  File "c:\users\xiaocheng wang\appdata\local\programs\python\python38-32\lib\site-packages\flask\app.py", line 1952, in full_dispatch_request
    rv = self.handle_user_exception(e)
  File "c:\users\xiaocheng wang\appdata\local\programs\python\python38-32\lib\site-packages\flask\app.py", line 1821, in handle_user_exception
    reraise(exc_type, exc_value, tb)
  File "c:\users\xiaocheng wang\appdata\local\programs\python\python38-32\lib\site-packages\flask\_compat.py", line 39, in reraise
    raise value
  File "c:\users\xiaocheng wang\appdata\local\programs\python\python38-32\lib\site-packages\flask\app.py", line 1950, in full_dispatch_request
    rv = self.dispatch_request()
  File "c:\users\xiaocheng wang\appdata\local\programs\python\python38-32\lib\site-packages\flask\app.py", line 1936, in dispatch_request
    return self.view_functions[rule.endpoint](**req.view_args)
  File "E:\Study\UWA\Year3\S2\CITS3200\project\SDURI-Admin-Platform\app\routes.py", line 32, in favicon
    return send_from_directory(os.path.join(app.root_path, 'static'),
NameError: name 'send_from_directory' is not defined
INFO:werkzeug:127.0.0.1 - - [23/Sep/2020 05:43:32] "[35m[1mGET /favicon.ico HTTP/1.1[0m" 500 -
INFO:werkzeug:127.0.0.1 - - [23/Sep/2020 05:43:32] "[37mGET /admin/student/ HTTP/1.1[0m" 200 -
ERROR:app:Exception on /favicon.ico [GET]
Traceback (most recent call last):
  File "c:\users\xiaocheng wang\appdata\local\programs\python\python38-32\lib\site-packages\flask\app.py", line 2447, in wsgi_app
    response = self.full_dispatch_request()
  File "c:\users\xiaocheng wang\appdata\local\programs\python\python38-32\lib\site-packages\flask\app.py", line 1952, in full_dispatch_request
    rv = self.handle_user_exception(e)
  File "c:\users\xiaocheng wang\appdata\local\programs\python\python38-32\lib\site-packages\flask\app.py", line 1821, in handle_user_exception
    reraise(exc_type, exc_value, tb)
  File "c:\users\xiaocheng wang\appdata\local\programs\python\python38-32\lib\site-packages\flask\_compat.py", line 39, in reraise
    raise value
  File "c:\users\xiaocheng wang\appdata\local\programs\python\python38-32\lib\site-packages\flask\app.py", line 1950, in full_dispatch_request
    rv = self.dispatch_request()
  File "c:\users\xiaocheng wang\appdata\local\programs\python\python38-32\lib\site-packages\flask\app.py", line 1936, in dispatch_request
    return self.view_functions[rule.endpoint](**req.view_args)
  File "E:\Study\UWA\Year3\S2\CITS3200\project\SDURI-Admin-Platform\app\routes.py", line 32, in favicon
    return send_from_directory(os.path.join(app.root_path, 'static'),
NameError: name 'send_from_directory' is not defined
INFO:werkzeug:127.0.0.1 - - [23/Sep/2020 05:43:32] "[35m[1mGET /favicon.ico HTTP/1.1[0m" 500 -
INFO:werkzeug:127.0.0.1 - - [23/Sep/2020 05:43:32] "[37mGET /admin/supervisor/ HTTP/1.1[0m" 200 -
ERROR:app:Exception on /favicon.ico [GET]
Traceback (most recent call last):
  File "c:\users\xiaocheng wang\appdata\local\programs\python\python38-32\lib\site-packages\flask\app.py", line 2447, in wsgi_app
    response = self.full_dispatch_request()
  File "c:\users\xiaocheng wang\appdata\local\programs\python\python38-32\lib\site-packages\flask\app.py", line 1952, in full_dispatch_request
    rv = self.handle_user_exception(e)
  File "c:\users\xiaocheng wang\appdata\local\programs\python\python38-32\lib\site-packages\flask\app.py", line 1821, in handle_user_exception
    reraise(exc_type, exc_value, tb)
  File "c:\users\xiaocheng wang\appdata\local\programs\python\python38-32\lib\site-packages\flask\_compat.py", line 39, in reraise
    raise value
  File "c:\users\xiaocheng wang\appdata\local\programs\python\python38-32\lib\site-packages\flask\app.py", line 1950, in full_dispatch_request
    rv = self.dispatch_request()
  File "c:\users\xiaocheng wang\appdata\local\programs\python\python38-32\lib\site-packages\flask\app.py", line 1936, in dispatch_request
    return self.view_functions[rule.endpoint](**req.view_args)
  File "E:\Study\UWA\Year3\S2\CITS3200\project\SDURI-Admin-Platform\app\routes.py", line 32, in favicon
    return send_from_directory(os.path.join(app.root_path, 'static'),
NameError: name 'send_from_directory' is not defined
INFO:werkzeug:127.0.0.1 - - [23/Sep/2020 05:43:32] "[35m[1mGET /favicon.ico HTTP/1.1[0m" 500 -
INFO:werkzeug:127.0.0.1 - - [23/Sep/2020 05:43:33] "[37mGET /admin/project/ HTTP/1.1[0m" 200 -
ERROR:app:Exception on /favicon.ico [GET]
Traceback (most recent call last):
  File "c:\users\xiaocheng wang\appdata\local\programs\python\python38-32\lib\site-packages\flask\app.py", line 2447, in wsgi_app
    response = self.full_dispatch_request()
  File "c:\users\xiaocheng wang\appdata\local\programs\python\python38-32\lib\site-packages\flask\app.py", line 1952, in full_dispatch_request
    rv = self.handle_user_exception(e)
  File "c:\users\xiaocheng wang\appdata\local\programs\python\python38-32\lib\site-packages\flask\app.py", line 1821, in handle_user_exception
    reraise(exc_type, exc_value, tb)
  File "c:\users\xiaocheng wang\appdata\local\programs\python\python38-32\lib\site-packages\flask\_compat.py", line 39, in reraise
    raise value
  File "c:\users\xiaocheng wang\appdata\local\programs\python\python38-32\lib\site-packages\flask\app.py", line 1950, in full_dispatch_request
    rv = self.dispatch_request()
  File "c:\users\xiaocheng wang\appdata\local\programs\python\python38-32\lib\site-packages\flask\app.py", line 1936, in dispatch_request
    return self.view_functions[rule.endpoint](**req.view_args)
  File "E:\Study\UWA\Year3\S2\CITS3200\project\SDURI-Admin-Platform\app\routes.py", line 32, in favicon
    return send_from_directory(os.path.join(app.root_path, 'static'),
NameError: name 'send_from_directory' is not defined
INFO:werkzeug:127.0.0.1 - - [23/Sep/2020 05:43:33] "[35m[1mGET /favicon.ico HTTP/1.1[0m" 500 -
INFO:werkzeug:127.0.0.1 - - [23/Sep/2020 05:43:45] "[37mPOST /add-project/Cheng2 HTTP/1.1[0m" 200 -
INFO:werkzeug:127.0.0.1 - - [23/Sep/2020 05:44:37] "[37mGET /admin/user/ HTTP/1.1[0m" 200 -
ERROR:app:Exception on /favicon.ico [GET]
Traceback (most recent call last):
  File "c:\users\xiaocheng wang\appdata\local\programs\python\python38-32\lib\site-packages\flask\app.py", line 2447, in wsgi_app
    response = self.full_dispatch_request()
  File "c:\users\xiaocheng wang\appdata\local\programs\python\python38-32\lib\site-packages\flask\app.py", line 1952, in full_dispatch_request
    rv = self.handle_user_exception(e)
  File "c:\users\xiaocheng wang\appdata\local\programs\python\python38-32\lib\site-packages\flask\app.py", line 1821, in handle_user_exception
    reraise(exc_type, exc_value, tb)
  File "c:\users\xiaocheng wang\appdata\local\programs\python\python38-32\lib\site-packages\flask\_compat.py", line 39, in reraise
    raise value
  File "c:\users\xiaocheng wang\appdata\local\programs\python\python38-32\lib\site-packages\flask\app.py", line 1950, in full_dispatch_request
    rv = self.dispatch_request()
  File "c:\users\xiaocheng wang\appdata\local\programs\python\python38-32\lib\site-packages\flask\app.py", line 1936, in dispatch_request
    return self.view_functions[rule.endpoint](**req.view_args)
  File "E:\Study\UWA\Year3\S2\CITS3200\project\SDURI-Admin-Platform\app\routes.py", line 32, in favicon
    return send_from_directory(os.path.join(app.root_path, 'static'),
NameError: name 'send_from_directory' is not defined
INFO:werkzeug:127.0.0.1 - - [23/Sep/2020 05:44:38] "[35m[1mGET /favicon.ico HTTP/1.1[0m" 500 -
INFO:werkzeug:127.0.0.1 - - [23/Sep/2020 05:44:42] "[37mGET /admin/ HTTP/1.1[0m" 200 -
ERROR:app:Exception on /favicon.ico [GET]
Traceback (most recent call last):
  File "c:\users\xiaocheng wang\appdata\local\programs\python\python38-32\lib\site-packages\flask\app.py", line 2447, in wsgi_app
    response = self.full_dispatch_request()
  File "c:\users\xiaocheng wang\appdata\local\programs\python\python38-32\lib\site-packages\flask\app.py", line 1952, in full_dispatch_request
    rv = self.handle_user_exception(e)
  File "c:\users\xiaocheng wang\appdata\local\programs\python\python38-32\lib\site-packages\flask\app.py", line 1821, in handle_user_exception
    reraise(exc_type, exc_value, tb)
  File "c:\users\xiaocheng wang\appdata\local\programs\python\python38-32\lib\site-packages\flask\_compat.py", line 39, in reraise
    raise value
  File "c:\users\xiaocheng wang\appdata\local\programs\python\python38-32\lib\site-packages\flask\app.py", line 1950, in full_dispatch_request
    rv = self.dispatch_request()
  File "c:\users\xiaocheng wang\appdata\local\programs\python\python38-32\lib\site-packages\flask\app.py", line 1936, in dispatch_request
    return self.view_functions[rule.endpoint](**req.view_args)
  File "E:\Study\UWA\Year3\S2\CITS3200\project\SDURI-Admin-Platform\app\routes.py", line 32, in favicon
    return send_from_directory(os.path.join(app.root_path, 'static'),
NameError: name 'send_from_directory' is not defined
INFO:werkzeug:127.0.0.1 - - [23/Sep/2020 05:44:42] "[35m[1mGET /favicon.ico HTTP/1.1[0m" 500 -
INFO:werkzeug:127.0.0.1 - - [23/Sep/2020 05:44:43] "[37mGET /admin/user/ HTTP/1.1[0m" 200 -
ERROR:app:Exception on /favicon.ico [GET]
Traceback (most recent call last):
  File "c:\users\xiaocheng wang\appdata\local\programs\python\python38-32\lib\site-packages\flask\app.py", line 2447, in wsgi_app
    response = self.full_dispatch_request()
  File "c:\users\xiaocheng wang\appdata\local\programs\python\python38-32\lib\site-packages\flask\app.py", line 1952, in full_dispatch_request
    rv = self.handle_user_exception(e)
  File "c:\users\xiaocheng wang\appdata\local\programs\python\python38-32\lib\site-packages\flask\app.py", line 1821, in handle_user_exception
    reraise(exc_type, exc_value, tb)
  File "c:\users\xiaocheng wang\appdata\local\programs\python\python38-32\lib\site-packages\flask\_compat.py", line 39, in reraise
    raise value
  File "c:\users\xiaocheng wang\appdata\local\programs\python\python38-32\lib\site-packages\flask\app.py", line 1950, in full_dispatch_request
    rv = self.dispatch_request()
  File "c:\users\xiaocheng wang\appdata\local\programs\python\python38-32\lib\site-packages\flask\app.py", line 1936, in dispatch_request
    return self.view_functions[rule.endpoint](**req.view_args)
  File "E:\Study\UWA\Year3\S2\CITS3200\project\SDURI-Admin-Platform\app\routes.py", line 32, in favicon
    return send_from_directory(os.path.join(app.root_path, 'static'),
NameError: name 'send_from_directory' is not defined
INFO:werkzeug:127.0.0.1 - - [23/Sep/2020 05:44:43] "[35m[1mGET /favicon.ico HTTP/1.1[0m" 500 -
INFO:werkzeug:127.0.0.1 - - [23/Sep/2020 05:46:02] "[37mGET /admin/project/ HTTP/1.1[0m" 200 -
ERROR:app:Exception on /favicon.ico [GET]
Traceback (most recent call last):
  File "c:\users\xiaocheng wang\appdata\local\programs\python\python38-32\lib\site-packages\flask\app.py", line 2447, in wsgi_app
    response = self.full_dispatch_request()
  File "c:\users\xiaocheng wang\appdata\local\programs\python\python38-32\lib\site-packages\flask\app.py", line 1952, in full_dispatch_request
    rv = self.handle_user_exception(e)
  File "c:\users\xiaocheng wang\appdata\local\programs\python\python38-32\lib\site-packages\flask\app.py", line 1821, in handle_user_exception
    reraise(exc_type, exc_value, tb)
  File "c:\users\xiaocheng wang\appdata\local\programs\python\python38-32\lib\site-packages\flask\_compat.py", line 39, in reraise
    raise value
  File "c:\users\xiaocheng wang\appdata\local\programs\python\python38-32\lib\site-packages\flask\app.py", line 1950, in full_dispatch_request
    rv = self.dispatch_request()
  File "c:\users\xiaocheng wang\appdata\local\programs\python\python38-32\lib\site-packages\flask\app.py", line 1936, in dispatch_request
    return self.view_functions[rule.endpoint](**req.view_args)
  File "E:\Study\UWA\Year3\S2\CITS3200\project\SDURI-Admin-Platform\app\routes.py", line 32, in favicon
    return send_from_directory(os.path.join(app.root_path, 'static'),
NameError: name 'send_from_directory' is not defined
INFO:werkzeug:127.0.0.1 - - [23/Sep/2020 05:46:02] "[35m[1mGET /favicon.ico HTTP/1.1[0m" 500 -
INFO:werkzeug:127.0.0.1 - - [23/Sep/2020 05:46:04] "[37mGET /admin/user/ HTTP/1.1[0m" 200 -
ERROR:app:Exception on /favicon.ico [GET]
Traceback (most recent call last):
  File "c:\users\xiaocheng wang\appdata\local\programs\python\python38-32\lib\site-packages\flask\app.py", line 2447, in wsgi_app
    response = self.full_dispatch_request()
  File "c:\users\xiaocheng wang\appdata\local\programs\python\python38-32\lib\site-packages\flask\app.py", line 1952, in full_dispatch_request
    rv = self.handle_user_exception(e)
  File "c:\users\xiaocheng wang\appdata\local\programs\python\python38-32\lib\site-packages\flask\app.py", line 1821, in handle_user_exception
    reraise(exc_type, exc_value, tb)
  File "c:\users\xiaocheng wang\appdata\local\programs\python\python38-32\lib\site-packages\flask\_compat.py", line 39, in reraise
    raise value
  File "c:\users\xiaocheng wang\appdata\local\programs\python\python38-32\lib\site-packages\flask\app.py", line 1950, in full_dispatch_request
    rv = self.dispatch_request()
  File "c:\users\xiaocheng wang\appdata\local\programs\python\python38-32\lib\site-packages\flask\app.py", line 1936, in dispatch_request
    return self.view_functions[rule.endpoint](**req.view_args)
  File "E:\Study\UWA\Year3\S2\CITS3200\project\SDURI-Admin-Platform\app\routes.py", line 32, in favicon
    return send_from_directory(os.path.join(app.root_path, 'static'),
NameError: name 'send_from_directory' is not defined
INFO:werkzeug:127.0.0.1 - - [23/Sep/2020 05:46:05] "[35m[1mGET /favicon.ico HTTP/1.1[0m" 500 -
INFO:werkzeug:127.0.0.1 - - [23/Sep/2020 05:46:12] "[37mGET /admin/supervisor/ HTTP/1.1[0m" 200 -
ERROR:app:Exception on /favicon.ico [GET]
Traceback (most recent call last):
  File "c:\users\xiaocheng wang\appdata\local\programs\python\python38-32\lib\site-packages\flask\app.py", line 2447, in wsgi_app
    response = self.full_dispatch_request()
  File "c:\users\xiaocheng wang\appdata\local\programs\python\python38-32\lib\site-packages\flask\app.py", line 1952, in full_dispatch_request
    rv = self.handle_user_exception(e)
  File "c:\users\xiaocheng wang\appdata\local\programs\python\python38-32\lib\site-packages\flask\app.py", line 1821, in handle_user_exception
    reraise(exc_type, exc_value, tb)
  File "c:\users\xiaocheng wang\appdata\local\programs\python\python38-32\lib\site-packages\flask\_compat.py", line 39, in reraise
    raise value
  File "c:\users\xiaocheng wang\appdata\local\programs\python\python38-32\lib\site-packages\flask\app.py", line 1950, in full_dispatch_request
    rv = self.dispatch_request()
  File "c:\users\xiaocheng wang\appdata\local\programs\python\python38-32\lib\site-packages\flask\app.py", line 1936, in dispatch_request
    return self.view_functions[rule.endpoint](**req.view_args)
  File "E:\Study\UWA\Year3\S2\CITS3200\project\SDURI-Admin-Platform\app\routes.py", line 32, in favicon
    return send_from_directory(os.path.join(app.root_path, 'static'),
NameError: name 'send_from_directory' is not defined
INFO:werkzeug:127.0.0.1 - - [23/Sep/2020 05:46:13] "[35m[1mGET /favicon.ico HTTP/1.1[0m" 500 -
INFO:werkzeug:127.0.0.1 - - [23/Sep/2020 05:46:13] "[37mGET /admin/student/ HTTP/1.1[0m" 200 -
ERROR:app:Exception on /favicon.ico [GET]
Traceback (most recent call last):
  File "c:\users\xiaocheng wang\appdata\local\programs\python\python38-32\lib\site-packages\flask\app.py", line 2447, in wsgi_app
    response = self.full_dispatch_request()
  File "c:\users\xiaocheng wang\appdata\local\programs\python\python38-32\lib\site-packages\flask\app.py", line 1952, in full_dispatch_request
    rv = self.handle_user_exception(e)
  File "c:\users\xiaocheng wang\appdata\local\programs\python\python38-32\lib\site-packages\flask\app.py", line 1821, in handle_user_exception
    reraise(exc_type, exc_value, tb)
  File "c:\users\xiaocheng wang\appdata\local\programs\python\python38-32\lib\site-packages\flask\_compat.py", line 39, in reraise
    raise value
  File "c:\users\xiaocheng wang\appdata\local\programs\python\python38-32\lib\site-packages\flask\app.py", line 1950, in full_dispatch_request
    rv = self.dispatch_request()
  File "c:\users\xiaocheng wang\appdata\local\programs\python\python38-32\lib\site-packages\flask\app.py", line 1936, in dispatch_request
    return self.view_functions[rule.endpoint](**req.view_args)
  File "E:\Study\UWA\Year3\S2\CITS3200\project\SDURI-Admin-Platform\app\routes.py", line 32, in favicon
    return send_from_directory(os.path.join(app.root_path, 'static'),
NameError: name 'send_from_directory' is not defined
INFO:werkzeug:127.0.0.1 - - [23/Sep/2020 05:46:13] "[35m[1mGET /favicon.ico HTTP/1.1[0m" 500 -
INFO:werkzeug:127.0.0.1 - - [23/Sep/2020 05:46:15] "[37mGET /admin/user/ HTTP/1.1[0m" 200 -
ERROR:app:Exception on /favicon.ico [GET]
Traceback (most recent call last):
  File "c:\users\xiaocheng wang\appdata\local\programs\python\python38-32\lib\site-packages\flask\app.py", line 2447, in wsgi_app
    response = self.full_dispatch_request()
  File "c:\users\xiaocheng wang\appdata\local\programs\python\python38-32\lib\site-packages\flask\app.py", line 1952, in full_dispatch_request
    rv = self.handle_user_exception(e)
  File "c:\users\xiaocheng wang\appdata\local\programs\python\python38-32\lib\site-packages\flask\app.py", line 1821, in handle_user_exception
    reraise(exc_type, exc_value, tb)
  File "c:\users\xiaocheng wang\appdata\local\programs\python\python38-32\lib\site-packages\flask\_compat.py", line 39, in reraise
    raise value
  File "c:\users\xiaocheng wang\appdata\local\programs\python\python38-32\lib\site-packages\flask\app.py", line 1950, in full_dispatch_request
    rv = self.dispatch_request()
  File "c:\users\xiaocheng wang\appdata\local\programs\python\python38-32\lib\site-packages\flask\app.py", line 1936, in dispatch_request
    return self.view_functions[rule.endpoint](**req.view_args)
  File "E:\Study\UWA\Year3\S2\CITS3200\project\SDURI-Admin-Platform\app\routes.py", line 32, in favicon
    return send_from_directory(os.path.join(app.root_path, 'static'),
NameError: name 'send_from_directory' is not defined
INFO:werkzeug:127.0.0.1 - - [23/Sep/2020 05:46:15] "[35m[1mGET /favicon.ico HTTP/1.1[0m" 500 -
INFO:werkzeug:127.0.0.1 - - [23/Sep/2020 05:46:16] "[37mGET /admin/student/ HTTP/1.1[0m" 200 -
ERROR:app:Exception on /favicon.ico [GET]
Traceback (most recent call last):
  File "c:\users\xiaocheng wang\appdata\local\programs\python\python38-32\lib\site-packages\flask\app.py", line 2447, in wsgi_app
    response = self.full_dispatch_request()
  File "c:\users\xiaocheng wang\appdata\local\programs\python\python38-32\lib\site-packages\flask\app.py", line 1952, in full_dispatch_request
    rv = self.handle_user_exception(e)
  File "c:\users\xiaocheng wang\appdata\local\programs\python\python38-32\lib\site-packages\flask\app.py", line 1821, in handle_user_exception
    reraise(exc_type, exc_value, tb)
  File "c:\users\xiaocheng wang\appdata\local\programs\python\python38-32\lib\site-packages\flask\_compat.py", line 39, in reraise
    raise value
  File "c:\users\xiaocheng wang\appdata\local\programs\python\python38-32\lib\site-packages\flask\app.py", line 1950, in full_dispatch_request
    rv = self.dispatch_request()
  File "c:\users\xiaocheng wang\appdata\local\programs\python\python38-32\lib\site-packages\flask\app.py", line 1936, in dispatch_request
    return self.view_functions[rule.endpoint](**req.view_args)
  File "E:\Study\UWA\Year3\S2\CITS3200\project\SDURI-Admin-Platform\app\routes.py", line 32, in favicon
    return send_from_directory(os.path.join(app.root_path, 'static'),
NameError: name 'send_from_directory' is not defined
INFO:werkzeug:127.0.0.1 - - [23/Sep/2020 05:46:16] "[35m[1mGET /favicon.ico HTTP/1.1[0m" 500 -
INFO:werkzeug:127.0.0.1 - - [23/Sep/2020 05:46:17] "[37mGET /admin/supervisor/ HTTP/1.1[0m" 200 -
ERROR:app:Exception on /favicon.ico [GET]
Traceback (most recent call last):
  File "c:\users\xiaocheng wang\appdata\local\programs\python\python38-32\lib\site-packages\flask\app.py", line 2447, in wsgi_app
    response = self.full_dispatch_request()
  File "c:\users\xiaocheng wang\appdata\local\programs\python\python38-32\lib\site-packages\flask\app.py", line 1952, in full_dispatch_request
    rv = self.handle_user_exception(e)
  File "c:\users\xiaocheng wang\appdata\local\programs\python\python38-32\lib\site-packages\flask\app.py", line 1821, in handle_user_exception
    reraise(exc_type, exc_value, tb)
  File "c:\users\xiaocheng wang\appdata\local\programs\python\python38-32\lib\site-packages\flask\_compat.py", line 39, in reraise
    raise value
  File "c:\users\xiaocheng wang\appdata\local\programs\python\python38-32\lib\site-packages\flask\app.py", line 1950, in full_dispatch_request
    rv = self.dispatch_request()
  File "c:\users\xiaocheng wang\appdata\local\programs\python\python38-32\lib\site-packages\flask\app.py", line 1936, in dispatch_request
    return self.view_functions[rule.endpoint](**req.view_args)
  File "E:\Study\UWA\Year3\S2\CITS3200\project\SDURI-Admin-Platform\app\routes.py", line 32, in favicon
    return send_from_directory(os.path.join(app.root_path, 'static'),
NameError: name 'send_from_directory' is not defined
INFO:werkzeug:127.0.0.1 - - [23/Sep/2020 05:46:17] "[35m[1mGET /favicon.ico HTTP/1.1[0m" 500 -
INFO:werkzeug:127.0.0.1 - - [23/Sep/2020 05:46:24] "[37mGET /admin/project/ HTTP/1.1[0m" 200 -
ERROR:app:Exception on /favicon.ico [GET]
Traceback (most recent call last):
  File "c:\users\xiaocheng wang\appdata\local\programs\python\python38-32\lib\site-packages\flask\app.py", line 2447, in wsgi_app
    response = self.full_dispatch_request()
  File "c:\users\xiaocheng wang\appdata\local\programs\python\python38-32\lib\site-packages\flask\app.py", line 1952, in full_dispatch_request
    rv = self.handle_user_exception(e)
  File "c:\users\xiaocheng wang\appdata\local\programs\python\python38-32\lib\site-packages\flask\app.py", line 1821, in handle_user_exception
    reraise(exc_type, exc_value, tb)
  File "c:\users\xiaocheng wang\appdata\local\programs\python\python38-32\lib\site-packages\flask\_compat.py", line 39, in reraise
    raise value
  File "c:\users\xiaocheng wang\appdata\local\programs\python\python38-32\lib\site-packages\flask\app.py", line 1950, in full_dispatch_request
    rv = self.dispatch_request()
  File "c:\users\xiaocheng wang\appdata\local\programs\python\python38-32\lib\site-packages\flask\app.py", line 1936, in dispatch_request
    return self.view_functions[rule.endpoint](**req.view_args)
  File "E:\Study\UWA\Year3\S2\CITS3200\project\SDURI-Admin-Platform\app\routes.py", line 32, in favicon
    return send_from_directory(os.path.join(app.root_path, 'static'),
NameError: name 'send_from_directory' is not defined
INFO:werkzeug:127.0.0.1 - - [23/Sep/2020 05:46:24] "[35m[1mGET /favicon.ico HTTP/1.1[0m" 500 -
INFO:werkzeug:127.0.0.1 - - [23/Sep/2020 05:46:26] "[37mGET /admin/supervisor/ HTTP/1.1[0m" 200 -
ERROR:app:Exception on /favicon.ico [GET]
Traceback (most recent call last):
  File "c:\users\xiaocheng wang\appdata\local\programs\python\python38-32\lib\site-packages\flask\app.py", line 2447, in wsgi_app
    response = self.full_dispatch_request()
  File "c:\users\xiaocheng wang\appdata\local\programs\python\python38-32\lib\site-packages\flask\app.py", line 1952, in full_dispatch_request
    rv = self.handle_user_exception(e)
  File "c:\users\xiaocheng wang\appdata\local\programs\python\python38-32\lib\site-packages\flask\app.py", line 1821, in handle_user_exception
    reraise(exc_type, exc_value, tb)
  File "c:\users\xiaocheng wang\appdata\local\programs\python\python38-32\lib\site-packages\flask\_compat.py", line 39, in reraise
    raise value
  File "c:\users\xiaocheng wang\appdata\local\programs\python\python38-32\lib\site-packages\flask\app.py", line 1950, in full_dispatch_request
    rv = self.dispatch_request()
  File "c:\users\xiaocheng wang\appdata\local\programs\python\python38-32\lib\site-packages\flask\app.py", line 1936, in dispatch_request
    return self.view_functions[rule.endpoint](**req.view_args)
  File "E:\Study\UWA\Year3\S2\CITS3200\project\SDURI-Admin-Platform\app\routes.py", line 32, in favicon
    return send_from_directory(os.path.join(app.root_path, 'static'),
NameError: name 'send_from_directory' is not defined
INFO:werkzeug:127.0.0.1 - - [23/Sep/2020 05:46:27] "[35m[1mGET /favicon.ico HTTP/1.1[0m" 500 -
INFO:werkzeug:127.0.0.1 - - [23/Sep/2020 05:46:27] "[37mGET /admin/project/ HTTP/1.1[0m" 200 -
ERROR:app:Exception on /favicon.ico [GET]
Traceback (most recent call last):
  File "c:\users\xiaocheng wang\appdata\local\programs\python\python38-32\lib\site-packages\flask\app.py", line 2447, in wsgi_app
    response = self.full_dispatch_request()
  File "c:\users\xiaocheng wang\appdata\local\programs\python\python38-32\lib\site-packages\flask\app.py", line 1952, in full_dispatch_request
    rv = self.handle_user_exception(e)
  File "c:\users\xiaocheng wang\appdata\local\programs\python\python38-32\lib\site-packages\flask\app.py", line 1821, in handle_user_exception
    reraise(exc_type, exc_value, tb)
  File "c:\users\xiaocheng wang\appdata\local\programs\python\python38-32\lib\site-packages\flask\_compat.py", line 39, in reraise
    raise value
  File "c:\users\xiaocheng wang\appdata\local\programs\python\python38-32\lib\site-packages\flask\app.py", line 1950, in full_dispatch_request
    rv = self.dispatch_request()
  File "c:\users\xiaocheng wang\appdata\local\programs\python\python38-32\lib\site-packages\flask\app.py", line 1936, in dispatch_request
    return self.view_functions[rule.endpoint](**req.view_args)
  File "E:\Study\UWA\Year3\S2\CITS3200\project\SDURI-Admin-Platform\app\routes.py", line 32, in favicon
    return send_from_directory(os.path.join(app.root_path, 'static'),
NameError: name 'send_from_directory' is not defined
INFO:werkzeug:127.0.0.1 - - [23/Sep/2020 05:46:27] "[35m[1mGET /favicon.ico HTTP/1.1[0m" 500 -
INFO:werkzeug:127.0.0.1 - - [23/Sep/2020 05:46:29] "[37mGET /admin/supervisor/ HTTP/1.1[0m" 200 -
ERROR:app:Exception on /favicon.ico [GET]
Traceback (most recent call last):
  File "c:\users\xiaocheng wang\appdata\local\programs\python\python38-32\lib\site-packages\flask\app.py", line 2447, in wsgi_app
    response = self.full_dispatch_request()
  File "c:\users\xiaocheng wang\appdata\local\programs\python\python38-32\lib\site-packages\flask\app.py", line 1952, in full_dispatch_request
    rv = self.handle_user_exception(e)
  File "c:\users\xiaocheng wang\appdata\local\programs\python\python38-32\lib\site-packages\flask\app.py", line 1821, in handle_user_exception
    reraise(exc_type, exc_value, tb)
  File "c:\users\xiaocheng wang\appdata\local\programs\python\python38-32\lib\site-packages\flask\_compat.py", line 39, in reraise
    raise value
  File "c:\users\xiaocheng wang\appdata\local\programs\python\python38-32\lib\site-packages\flask\app.py", line 1950, in full_dispatch_request
    rv = self.dispatch_request()
  File "c:\users\xiaocheng wang\appdata\local\programs\python\python38-32\lib\site-packages\flask\app.py", line 1936, in dispatch_request
    return self.view_functions[rule.endpoint](**req.view_args)
  File "E:\Study\UWA\Year3\S2\CITS3200\project\SDURI-Admin-Platform\app\routes.py", line 32, in favicon
    return send_from_directory(os.path.join(app.root_path, 'static'),
NameError: name 'send_from_directory' is not defined
INFO:werkzeug:127.0.0.1 - - [23/Sep/2020 05:46:30] "[35m[1mGET /favicon.ico HTTP/1.1[0m" 500 -
INFO:werkzeug:127.0.0.1 - - [23/Sep/2020 05:46:48] "[37mGET /admin/student/ HTTP/1.1[0m" 200 -
ERROR:app:Exception on /favicon.ico [GET]
Traceback (most recent call last):
  File "c:\users\xiaocheng wang\appdata\local\programs\python\python38-32\lib\site-packages\flask\app.py", line 2447, in wsgi_app
    response = self.full_dispatch_request()
  File "c:\users\xiaocheng wang\appdata\local\programs\python\python38-32\lib\site-packages\flask\app.py", line 1952, in full_dispatch_request
    rv = self.handle_user_exception(e)
  File "c:\users\xiaocheng wang\appdata\local\programs\python\python38-32\lib\site-packages\flask\app.py", line 1821, in handle_user_exception
    reraise(exc_type, exc_value, tb)
  File "c:\users\xiaocheng wang\appdata\local\programs\python\python38-32\lib\site-packages\flask\_compat.py", line 39, in reraise
    raise value
  File "c:\users\xiaocheng wang\appdata\local\programs\python\python38-32\lib\site-packages\flask\app.py", line 1950, in full_dispatch_request
    rv = self.dispatch_request()
  File "c:\users\xiaocheng wang\appdata\local\programs\python\python38-32\lib\site-packages\flask\app.py", line 1936, in dispatch_request
    return self.view_functions[rule.endpoint](**req.view_args)
  File "E:\Study\UWA\Year3\S2\CITS3200\project\SDURI-Admin-Platform\app\routes.py", line 32, in favicon
    return send_from_directory(os.path.join(app.root_path, 'static'),
NameError: name 'send_from_directory' is not defined
INFO:werkzeug:127.0.0.1 - - [23/Sep/2020 05:46:48] "[35m[1mGET /favicon.ico HTTP/1.1[0m" 500 -
INFO:werkzeug:127.0.0.1 - - [23/Sep/2020 05:47:21] "[37mPOST /add-project/Cheng2 HTTP/1.1[0m" 200 -
INFO:werkzeug:127.0.0.1 - - [23/Sep/2020 05:47:28] "[37mGET /admin/project/ HTTP/1.1[0m" 200 -
ERROR:app:Exception on /favicon.ico [GET]
Traceback (most recent call last):
  File "c:\users\xiaocheng wang\appdata\local\programs\python\python38-32\lib\site-packages\flask\app.py", line 2447, in wsgi_app
    response = self.full_dispatch_request()
  File "c:\users\xiaocheng wang\appdata\local\programs\python\python38-32\lib\site-packages\flask\app.py", line 1952, in full_dispatch_request
    rv = self.handle_user_exception(e)
  File "c:\users\xiaocheng wang\appdata\local\programs\python\python38-32\lib\site-packages\flask\app.py", line 1821, in handle_user_exception
    reraise(exc_type, exc_value, tb)
  File "c:\users\xiaocheng wang\appdata\local\programs\python\python38-32\lib\site-packages\flask\_compat.py", line 39, in reraise
    raise value
  File "c:\users\xiaocheng wang\appdata\local\programs\python\python38-32\lib\site-packages\flask\app.py", line 1950, in full_dispatch_request
    rv = self.dispatch_request()
  File "c:\users\xiaocheng wang\appdata\local\programs\python\python38-32\lib\site-packages\flask\app.py", line 1936, in dispatch_request
    return self.view_functions[rule.endpoint](**req.view_args)
  File "E:\Study\UWA\Year3\S2\CITS3200\project\SDURI-Admin-Platform\app\routes.py", line 32, in favicon
    return send_from_directory(os.path.join(app.root_path, 'static'),
NameError: name 'send_from_directory' is not defined
INFO:werkzeug:127.0.0.1 - - [23/Sep/2020 05:47:28] "[35m[1mGET /favicon.ico HTTP/1.1[0m" 500 -
INFO:werkzeug:127.0.0.1 - - [23/Sep/2020 05:47:31] "[37mGET /admin/project/new/?url=%2Fadmin%2Fproject%2F HTTP/1.1[0m" 200 -
INFO:werkzeug:127.0.0.1 - - [23/Sep/2020 05:47:31] "[37mGET /admin/static/vendor/select2/select2.png HTTP/1.1[0m" 200 -
ERROR:app:Exception on /favicon.ico [GET]
Traceback (most recent call last):
  File "c:\users\xiaocheng wang\appdata\local\programs\python\python38-32\lib\site-packages\flask\app.py", line 2447, in wsgi_app
    response = self.full_dispatch_request()
  File "c:\users\xiaocheng wang\appdata\local\programs\python\python38-32\lib\site-packages\flask\app.py", line 1952, in full_dispatch_request
    rv = self.handle_user_exception(e)
  File "c:\users\xiaocheng wang\appdata\local\programs\python\python38-32\lib\site-packages\flask\app.py", line 1821, in handle_user_exception
    reraise(exc_type, exc_value, tb)
  File "c:\users\xiaocheng wang\appdata\local\programs\python\python38-32\lib\site-packages\flask\_compat.py", line 39, in reraise
    raise value
  File "c:\users\xiaocheng wang\appdata\local\programs\python\python38-32\lib\site-packages\flask\app.py", line 1950, in full_dispatch_request
    rv = self.dispatch_request()
  File "c:\users\xiaocheng wang\appdata\local\programs\python\python38-32\lib\site-packages\flask\app.py", line 1936, in dispatch_request
    return self.view_functions[rule.endpoint](**req.view_args)
  File "E:\Study\UWA\Year3\S2\CITS3200\project\SDURI-Admin-Platform\app\routes.py", line 32, in favicon
    return send_from_directory(os.path.join(app.root_path, 'static'),
NameError: name 'send_from_directory' is not defined
INFO:werkzeug:127.0.0.1 - - [23/Sep/2020 05:47:31] "[35m[1mGET /favicon.ico HTTP/1.1[0m" 500 -
INFO:werkzeug:127.0.0.1 - - [23/Sep/2020 05:47:36] "[37mGET /admin/project/ HTTP/1.1[0m" 200 -
ERROR:app:Exception on /favicon.ico [GET]
Traceback (most recent call last):
  File "c:\users\xiaocheng wang\appdata\local\programs\python\python38-32\lib\site-packages\flask\app.py", line 2447, in wsgi_app
    response = self.full_dispatch_request()
  File "c:\users\xiaocheng wang\appdata\local\programs\python\python38-32\lib\site-packages\flask\app.py", line 1952, in full_dispatch_request
    rv = self.handle_user_exception(e)
  File "c:\users\xiaocheng wang\appdata\local\programs\python\python38-32\lib\site-packages\flask\app.py", line 1821, in handle_user_exception
    reraise(exc_type, exc_value, tb)
  File "c:\users\xiaocheng wang\appdata\local\programs\python\python38-32\lib\site-packages\flask\_compat.py", line 39, in reraise
    raise value
  File "c:\users\xiaocheng wang\appdata\local\programs\python\python38-32\lib\site-packages\flask\app.py", line 1950, in full_dispatch_request
    rv = self.dispatch_request()
  File "c:\users\xiaocheng wang\appdata\local\programs\python\python38-32\lib\site-packages\flask\app.py", line 1936, in dispatch_request
    return self.view_functions[rule.endpoint](**req.view_args)
  File "E:\Study\UWA\Year3\S2\CITS3200\project\SDURI-Admin-Platform\app\routes.py", line 32, in favicon
    return send_from_directory(os.path.join(app.root_path, 'static'),
NameError: name 'send_from_directory' is not defined
INFO:werkzeug:127.0.0.1 - - [23/Sep/2020 05:47:36] "[35m[1mGET /favicon.ico HTTP/1.1[0m" 500 -
INFO:werkzeug:127.0.0.1 - - [23/Sep/2020 05:47:36] "[37mGET /admin/project/new/?url=%2Fadmin%2Fproject%2F HTTP/1.1[0m" 200 -
ERROR:app:Exception on /favicon.ico [GET]
Traceback (most recent call last):
  File "c:\users\xiaocheng wang\appdata\local\programs\python\python38-32\lib\site-packages\flask\app.py", line 2447, in wsgi_app
    response = self.full_dispatch_request()
  File "c:\users\xiaocheng wang\appdata\local\programs\python\python38-32\lib\site-packages\flask\app.py", line 1952, in full_dispatch_request
    rv = self.handle_user_exception(e)
  File "c:\users\xiaocheng wang\appdata\local\programs\python\python38-32\lib\site-packages\flask\app.py", line 1821, in handle_user_exception
    reraise(exc_type, exc_value, tb)
  File "c:\users\xiaocheng wang\appdata\local\programs\python\python38-32\lib\site-packages\flask\_compat.py", line 39, in reraise
    raise value
  File "c:\users\xiaocheng wang\appdata\local\programs\python\python38-32\lib\site-packages\flask\app.py", line 1950, in full_dispatch_request
    rv = self.dispatch_request()
  File "c:\users\xiaocheng wang\appdata\local\programs\python\python38-32\lib\site-packages\flask\app.py", line 1936, in dispatch_request
    return self.view_functions[rule.endpoint](**req.view_args)
  File "E:\Study\UWA\Year3\S2\CITS3200\project\SDURI-Admin-Platform\app\routes.py", line 32, in favicon
    return send_from_directory(os.path.join(app.root_path, 'static'),
NameError: name 'send_from_directory' is not defined
INFO:werkzeug:127.0.0.1 - - [23/Sep/2020 05:47:37] "[35m[1mGET /favicon.ico HTTP/1.1[0m" 500 -
INFO:werkzeug:127.0.0.1 - - [23/Sep/2020 05:47:37] "[37mGET /admin/project/ HTTP/1.1[0m" 200 -
ERROR:app:Exception on /favicon.ico [GET]
Traceback (most recent call last):
  File "c:\users\xiaocheng wang\appdata\local\programs\python\python38-32\lib\site-packages\flask\app.py", line 2447, in wsgi_app
    response = self.full_dispatch_request()
  File "c:\users\xiaocheng wang\appdata\local\programs\python\python38-32\lib\site-packages\flask\app.py", line 1952, in full_dispatch_request
    rv = self.handle_user_exception(e)
  File "c:\users\xiaocheng wang\appdata\local\programs\python\python38-32\lib\site-packages\flask\app.py", line 1821, in handle_user_exception
    reraise(exc_type, exc_value, tb)
  File "c:\users\xiaocheng wang\appdata\local\programs\python\python38-32\lib\site-packages\flask\_compat.py", line 39, in reraise
    raise value
  File "c:\users\xiaocheng wang\appdata\local\programs\python\python38-32\lib\site-packages\flask\app.py", line 1950, in full_dispatch_request
    rv = self.dispatch_request()
  File "c:\users\xiaocheng wang\appdata\local\programs\python\python38-32\lib\site-packages\flask\app.py", line 1936, in dispatch_request
    return self.view_functions[rule.endpoint](**req.view_args)
  File "E:\Study\UWA\Year3\S2\CITS3200\project\SDURI-Admin-Platform\app\routes.py", line 32, in favicon
    return send_from_directory(os.path.join(app.root_path, 'static'),
NameError: name 'send_from_directory' is not defined
INFO:werkzeug:127.0.0.1 - - [23/Sep/2020 05:47:38] "[35m[1mGET /favicon.ico HTTP/1.1[0m" 500 -
INFO:werkzeug:127.0.0.1 - - [23/Sep/2020 05:47:38] "[37mGET /admin/supervisor/ HTTP/1.1[0m" 200 -
ERROR:app:Exception on /favicon.ico [GET]
Traceback (most recent call last):
  File "c:\users\xiaocheng wang\appdata\local\programs\python\python38-32\lib\site-packages\flask\app.py", line 2447, in wsgi_app
    response = self.full_dispatch_request()
  File "c:\users\xiaocheng wang\appdata\local\programs\python\python38-32\lib\site-packages\flask\app.py", line 1952, in full_dispatch_request
    rv = self.handle_user_exception(e)
  File "c:\users\xiaocheng wang\appdata\local\programs\python\python38-32\lib\site-packages\flask\app.py", line 1821, in handle_user_exception
    reraise(exc_type, exc_value, tb)
  File "c:\users\xiaocheng wang\appdata\local\programs\python\python38-32\lib\site-packages\flask\_compat.py", line 39, in reraise
    raise value
  File "c:\users\xiaocheng wang\appdata\local\programs\python\python38-32\lib\site-packages\flask\app.py", line 1950, in full_dispatch_request
    rv = self.dispatch_request()
  File "c:\users\xiaocheng wang\appdata\local\programs\python\python38-32\lib\site-packages\flask\app.py", line 1936, in dispatch_request
    return self.view_functions[rule.endpoint](**req.view_args)
  File "E:\Study\UWA\Year3\S2\CITS3200\project\SDURI-Admin-Platform\app\routes.py", line 32, in favicon
    return send_from_directory(os.path.join(app.root_path, 'static'),
NameError: name 'send_from_directory' is not defined
INFO:werkzeug:127.0.0.1 - - [23/Sep/2020 05:47:39] "[35m[1mGET /favicon.ico HTTP/1.1[0m" 500 -
INFO:werkzeug:127.0.0.1 - - [23/Sep/2020 05:47:40] "[37mGET /admin/supervisor/edit/?id=1&url=%2Fadmin%2Fsupervisor%2F HTTP/1.1[0m" 200 -
ERROR:app:Exception on /favicon.ico [GET]
Traceback (most recent call last):
  File "c:\users\xiaocheng wang\appdata\local\programs\python\python38-32\lib\site-packages\flask\app.py", line 2447, in wsgi_app
    response = self.full_dispatch_request()
  File "c:\users\xiaocheng wang\appdata\local\programs\python\python38-32\lib\site-packages\flask\app.py", line 1952, in full_dispatch_request
    rv = self.handle_user_exception(e)
  File "c:\users\xiaocheng wang\appdata\local\programs\python\python38-32\lib\site-packages\flask\app.py", line 1821, in handle_user_exception
    reraise(exc_type, exc_value, tb)
  File "c:\users\xiaocheng wang\appdata\local\programs\python\python38-32\lib\site-packages\flask\_compat.py", line 39, in reraise
    raise value
  File "c:\users\xiaocheng wang\appdata\local\programs\python\python38-32\lib\site-packages\flask\app.py", line 1950, in full_dispatch_request
    rv = self.dispatch_request()
  File "c:\users\xiaocheng wang\appdata\local\programs\python\python38-32\lib\site-packages\flask\app.py", line 1936, in dispatch_request
    return self.view_functions[rule.endpoint](**req.view_args)
  File "E:\Study\UWA\Year3\S2\CITS3200\project\SDURI-Admin-Platform\app\routes.py", line 32, in favicon
    return send_from_directory(os.path.join(app.root_path, 'static'),
NameError: name 'send_from_directory' is not defined
INFO:werkzeug:127.0.0.1 - - [23/Sep/2020 05:47:40] "[35m[1mGET /favicon.ico HTTP/1.1[0m" 500 -
INFO:werkzeug:127.0.0.1 - - [23/Sep/2020 05:47:42] "[37mGET /admin/supervisor/ HTTP/1.1[0m" 200 -
ERROR:app:Exception on /favicon.ico [GET]
Traceback (most recent call last):
  File "c:\users\xiaocheng wang\appdata\local\programs\python\python38-32\lib\site-packages\flask\app.py", line 2447, in wsgi_app
    response = self.full_dispatch_request()
  File "c:\users\xiaocheng wang\appdata\local\programs\python\python38-32\lib\site-packages\flask\app.py", line 1952, in full_dispatch_request
    rv = self.handle_user_exception(e)
  File "c:\users\xiaocheng wang\appdata\local\programs\python\python38-32\lib\site-packages\flask\app.py", line 1821, in handle_user_exception
    reraise(exc_type, exc_value, tb)
  File "c:\users\xiaocheng wang\appdata\local\programs\python\python38-32\lib\site-packages\flask\_compat.py", line 39, in reraise
    raise value
  File "c:\users\xiaocheng wang\appdata\local\programs\python\python38-32\lib\site-packages\flask\app.py", line 1950, in full_dispatch_request
    rv = self.dispatch_request()
  File "c:\users\xiaocheng wang\appdata\local\programs\python\python38-32\lib\site-packages\flask\app.py", line 1936, in dispatch_request
    return self.view_functions[rule.endpoint](**req.view_args)
  File "E:\Study\UWA\Year3\S2\CITS3200\project\SDURI-Admin-Platform\app\routes.py", line 32, in favicon
    return send_from_directory(os.path.join(app.root_path, 'static'),
NameError: name 'send_from_directory' is not defined
INFO:werkzeug:127.0.0.1 - - [23/Sep/2020 05:47:42] "[35m[1mGET /favicon.ico HTTP/1.1[0m" 500 -
INFO:werkzeug:127.0.0.1 - - [23/Sep/2020 05:47:42] "[37mGET /admin/project/ HTTP/1.1[0m" 200 -
ERROR:app:Exception on /favicon.ico [GET]
Traceback (most recent call last):
  File "c:\users\xiaocheng wang\appdata\local\programs\python\python38-32\lib\site-packages\flask\app.py", line 2447, in wsgi_app
    response = self.full_dispatch_request()
  File "c:\users\xiaocheng wang\appdata\local\programs\python\python38-32\lib\site-packages\flask\app.py", line 1952, in full_dispatch_request
    rv = self.handle_user_exception(e)
  File "c:\users\xiaocheng wang\appdata\local\programs\python\python38-32\lib\site-packages\flask\app.py", line 1821, in handle_user_exception
    reraise(exc_type, exc_value, tb)
  File "c:\users\xiaocheng wang\appdata\local\programs\python\python38-32\lib\site-packages\flask\_compat.py", line 39, in reraise
    raise value
  File "c:\users\xiaocheng wang\appdata\local\programs\python\python38-32\lib\site-packages\flask\app.py", line 1950, in full_dispatch_request
    rv = self.dispatch_request()
  File "c:\users\xiaocheng wang\appdata\local\programs\python\python38-32\lib\site-packages\flask\app.py", line 1936, in dispatch_request
    return self.view_functions[rule.endpoint](**req.view_args)
  File "E:\Study\UWA\Year3\S2\CITS3200\project\SDURI-Admin-Platform\app\routes.py", line 32, in favicon
    return send_from_directory(os.path.join(app.root_path, 'static'),
NameError: name 'send_from_directory' is not defined
INFO:werkzeug:127.0.0.1 - - [23/Sep/2020 05:47:43] "[35m[1mGET /favicon.ico HTTP/1.1[0m" 500 -
