INFO:werkzeug: * Running on http://127.0.0.1:5000/ (Press CTRL+C to quit)
INFO:werkzeug:127.0.0.1 - - [14/Sep/2020 18:50:05] "[37mGET / HTTP/1.1[0m" 200 -
INFO:werkzeug:127.0.0.1 - - [14/Sep/2020 18:50:07] "[37mGET /login HTTP/1.1[0m" 200 -
INFO:werkzeug:127.0.0.1 - - [14/Sep/2020 19:00:40] "[37mGET /login HTTP/1.1[0m" 200 -
INFO:werkzeug:127.0.0.1 - - [14/Sep/2020 19:00:45] "[37mPOST /login HTTP/1.1[0m" 200 -
ERROR:app:Exception on /favicon.ico [GET]
Traceback (most recent call last):
  File "C:\Users\Xiaocheng Wang\AppData\Local\Programs\Python\Python38-32\lib\site-packages\flask\app.py", line 2447, in wsgi_app
    response = self.full_dispatch_request()
  File "C:\Users\Xiaocheng Wang\AppData\Local\Programs\Python\Python38-32\lib\site-packages\flask\app.py", line 1952, in full_dispatch_request
    rv = self.handle_user_exception(e)
  File "C:\Users\Xiaocheng Wang\AppData\Local\Programs\Python\Python38-32\lib\site-packages\flask\app.py", line 1821, in handle_user_exception
    reraise(exc_type, exc_value, tb)
  File "C:\Users\Xiaocheng Wang\AppData\Local\Programs\Python\Python38-32\lib\site-packages\flask\_compat.py", line 39, in reraise
    raise value
  File "C:\Users\Xiaocheng Wang\AppData\Local\Programs\Python\Python38-32\lib\site-packages\flask\app.py", line 1950, in full_dispatch_request
    rv = self.dispatch_request()
  File "C:\Users\Xiaocheng Wang\AppData\Local\Programs\Python\Python38-32\lib\site-packages\flask\app.py", line 1936, in dispatch_request
    return self.view_functions[rule.endpoint](**req.view_args)
  File "E:\Study\UWA\Year3\S2\CITS3200\project\SDURI-Admin-Platform\app\routes.py", line 30, in favicon
    return send_from_directory(os.path.join(app.root_path, 'static'),
NameError: name 'send_from_directory' is not defined
INFO:werkzeug:127.0.0.1 - - [14/Sep/2020 19:00:45] "[35m[1mGET /favicon.ico HTTP/1.1[0m" 500 -
INFO:werkzeug:127.0.0.1 - - [14/Sep/2020 19:00:55] "[32mGET /login HTTP/1.1[0m" 302 -
INFO:werkzeug:127.0.0.1 - - [14/Sep/2020 19:00:55] "[37mGET /index HTTP/1.1[0m" 200 -
ERROR:app:Exception on /favicon.ico [GET]
Traceback (most recent call last):
  File "C:\Users\Xiaocheng Wang\AppData\Local\Programs\Python\Python38-32\lib\site-packages\flask\app.py", line 2447, in wsgi_app
    response = self.full_dispatch_request()
  File "C:\Users\Xiaocheng Wang\AppData\Local\Programs\Python\Python38-32\lib\site-packages\flask\app.py", line 1952, in full_dispatch_request
    rv = self.handle_user_exception(e)
  File "C:\Users\Xiaocheng Wang\AppData\Local\Programs\Python\Python38-32\lib\site-packages\flask\app.py", line 1821, in handle_user_exception
    reraise(exc_type, exc_value, tb)
  File "C:\Users\Xiaocheng Wang\AppData\Local\Programs\Python\Python38-32\lib\site-packages\flask\_compat.py", line 39, in reraise
    raise value
  File "C:\Users\Xiaocheng Wang\AppData\Local\Programs\Python\Python38-32\lib\site-packages\flask\app.py", line 1950, in full_dispatch_request
    rv = self.dispatch_request()
  File "C:\Users\Xiaocheng Wang\AppData\Local\Programs\Python\Python38-32\lib\site-packages\flask\app.py", line 1936, in dispatch_request
    return self.view_functions[rule.endpoint](**req.view_args)
  File "E:\Study\UWA\Year3\S2\CITS3200\project\SDURI-Admin-Platform\app\routes.py", line 30, in favicon
    return send_from_directory(os.path.join(app.root_path, 'static'),
NameError: name 'send_from_directory' is not defined
INFO:werkzeug:127.0.0.1 - - [14/Sep/2020 19:00:55] "[35m[1mGET /favicon.ico HTTP/1.1[0m" 500 -
INFO:werkzeug:127.0.0.1 - - [14/Sep/2020 19:00:57] "[32mGET /register HTTP/1.1[0m" 302 -
INFO:werkzeug:127.0.0.1 - - [14/Sep/2020 19:00:57] "[37mGET /index HTTP/1.1[0m" 200 -
ERROR:app:Exception on /favicon.ico [GET]
Traceback (most recent call last):
  File "C:\Users\Xiaocheng Wang\AppData\Local\Programs\Python\Python38-32\lib\site-packages\flask\app.py", line 2447, in wsgi_app
    response = self.full_dispatch_request()
  File "C:\Users\Xiaocheng Wang\AppData\Local\Programs\Python\Python38-32\lib\site-packages\flask\app.py", line 1952, in full_dispatch_request
    rv = self.handle_user_exception(e)
  File "C:\Users\Xiaocheng Wang\AppData\Local\Programs\Python\Python38-32\lib\site-packages\flask\app.py", line 1821, in handle_user_exception
    reraise(exc_type, exc_value, tb)
  File "C:\Users\Xiaocheng Wang\AppData\Local\Programs\Python\Python38-32\lib\site-packages\flask\_compat.py", line 39, in reraise
    raise value
  File "C:\Users\Xiaocheng Wang\AppData\Local\Programs\Python\Python38-32\lib\site-packages\flask\app.py", line 1950, in full_dispatch_request
    rv = self.dispatch_request()
  File "C:\Users\Xiaocheng Wang\AppData\Local\Programs\Python\Python38-32\lib\site-packages\flask\app.py", line 1936, in dispatch_request
    return self.view_functions[rule.endpoint](**req.view_args)
  File "E:\Study\UWA\Year3\S2\CITS3200\project\SDURI-Admin-Platform\app\routes.py", line 30, in favicon
    return send_from_directory(os.path.join(app.root_path, 'static'),
NameError: name 'send_from_directory' is not defined
INFO:werkzeug:127.0.0.1 - - [14/Sep/2020 19:00:57] "[35m[1mGET /favicon.ico HTTP/1.1[0m" 500 -
INFO:werkzeug:127.0.0.1 - - [14/Sep/2020 19:17:22] "[32mGET /register HTTP/1.1[0m" 302 -
INFO:werkzeug:127.0.0.1 - - [14/Sep/2020 19:17:22] "[37mGET /index HTTP/1.1[0m" 200 -
ERROR:app:Exception on /favicon.ico [GET]
Traceback (most recent call last):
  File "C:\Users\Xiaocheng Wang\AppData\Local\Programs\Python\Python38-32\lib\site-packages\flask\app.py", line 2447, in wsgi_app
    response = self.full_dispatch_request()
  File "C:\Users\Xiaocheng Wang\AppData\Local\Programs\Python\Python38-32\lib\site-packages\flask\app.py", line 1952, in full_dispatch_request
    rv = self.handle_user_exception(e)
  File "C:\Users\Xiaocheng Wang\AppData\Local\Programs\Python\Python38-32\lib\site-packages\flask\app.py", line 1821, in handle_user_exception
    reraise(exc_type, exc_value, tb)
  File "C:\Users\Xiaocheng Wang\AppData\Local\Programs\Python\Python38-32\lib\site-packages\flask\_compat.py", line 39, in reraise
    raise value
  File "C:\Users\Xiaocheng Wang\AppData\Local\Programs\Python\Python38-32\lib\site-packages\flask\app.py", line 1950, in full_dispatch_request
    rv = self.dispatch_request()
  File "C:\Users\Xiaocheng Wang\AppData\Local\Programs\Python\Python38-32\lib\site-packages\flask\app.py", line 1936, in dispatch_request
    return self.view_functions[rule.endpoint](**req.view_args)
  File "E:\Study\UWA\Year3\S2\CITS3200\project\SDURI-Admin-Platform\app\routes.py", line 30, in favicon
    return send_from_directory(os.path.join(app.root_path, 'static'),
NameError: name 'send_from_directory' is not defined
INFO:werkzeug:127.0.0.1 - - [14/Sep/2020 19:17:22] "[35m[1mGET /favicon.ico HTTP/1.1[0m" 500 -
INFO:werkzeug:127.0.0.1 - - [14/Sep/2020 19:17:49] "[32mGET /login HTTP/1.1[0m" 302 -
INFO:werkzeug:127.0.0.1 - - [14/Sep/2020 19:17:49] "[37mGET /index HTTP/1.1[0m" 200 -
ERROR:app:Exception on /favicon.ico [GET]
Traceback (most recent call last):
  File "C:\Users\Xiaocheng Wang\AppData\Local\Programs\Python\Python38-32\lib\site-packages\flask\app.py", line 2447, in wsgi_app
    response = self.full_dispatch_request()
  File "C:\Users\Xiaocheng Wang\AppData\Local\Programs\Python\Python38-32\lib\site-packages\flask\app.py", line 1952, in full_dispatch_request
    rv = self.handle_user_exception(e)
  File "C:\Users\Xiaocheng Wang\AppData\Local\Programs\Python\Python38-32\lib\site-packages\flask\app.py", line 1821, in handle_user_exception
    reraise(exc_type, exc_value, tb)
  File "C:\Users\Xiaocheng Wang\AppData\Local\Programs\Python\Python38-32\lib\site-packages\flask\_compat.py", line 39, in reraise
    raise value
  File "C:\Users\Xiaocheng Wang\AppData\Local\Programs\Python\Python38-32\lib\site-packages\flask\app.py", line 1950, in full_dispatch_request
    rv = self.dispatch_request()
  File "C:\Users\Xiaocheng Wang\AppData\Local\Programs\Python\Python38-32\lib\site-packages\flask\app.py", line 1936, in dispatch_request
    return self.view_functions[rule.endpoint](**req.view_args)
  File "E:\Study\UWA\Year3\S2\CITS3200\project\SDURI-Admin-Platform\app\routes.py", line 30, in favicon
    return send_from_directory(os.path.join(app.root_path, 'static'),
NameError: name 'send_from_directory' is not defined
INFO:werkzeug:127.0.0.1 - - [14/Sep/2020 19:17:50] "[35m[1mGET /favicon.ico HTTP/1.1[0m" 500 -
INFO:werkzeug:127.0.0.1 - - [14/Sep/2020 19:17:52] "[32mGET /register HTTP/1.1[0m" 302 -
INFO:werkzeug:127.0.0.1 - - [14/Sep/2020 19:17:52] "[37mGET /index HTTP/1.1[0m" 200 -
ERROR:app:Exception on /favicon.ico [GET]
Traceback (most recent call last):
  File "C:\Users\Xiaocheng Wang\AppData\Local\Programs\Python\Python38-32\lib\site-packages\flask\app.py", line 2447, in wsgi_app
    response = self.full_dispatch_request()
  File "C:\Users\Xiaocheng Wang\AppData\Local\Programs\Python\Python38-32\lib\site-packages\flask\app.py", line 1952, in full_dispatch_request
    rv = self.handle_user_exception(e)
  File "C:\Users\Xiaocheng Wang\AppData\Local\Programs\Python\Python38-32\lib\site-packages\flask\app.py", line 1821, in handle_user_exception
    reraise(exc_type, exc_value, tb)
  File "C:\Users\Xiaocheng Wang\AppData\Local\Programs\Python\Python38-32\lib\site-packages\flask\_compat.py", line 39, in reraise
    raise value
  File "C:\Users\Xiaocheng Wang\AppData\Local\Programs\Python\Python38-32\lib\site-packages\flask\app.py", line 1950, in full_dispatch_request
    rv = self.dispatch_request()
  File "C:\Users\Xiaocheng Wang\AppData\Local\Programs\Python\Python38-32\lib\site-packages\flask\app.py", line 1936, in dispatch_request
    return self.view_functions[rule.endpoint](**req.view_args)
  File "E:\Study\UWA\Year3\S2\CITS3200\project\SDURI-Admin-Platform\app\routes.py", line 30, in favicon
    return send_from_directory(os.path.join(app.root_path, 'static'),
NameError: name 'send_from_directory' is not defined
INFO:werkzeug:127.0.0.1 - - [14/Sep/2020 19:17:52] "[35m[1mGET /favicon.ico HTTP/1.1[0m" 500 -
INFO:werkzeug:127.0.0.1 - - [14/Sep/2020 19:20:13] "[32mGET /register HTTP/1.1[0m" 302 -
INFO:werkzeug:127.0.0.1 - - [14/Sep/2020 19:20:13] "[37mGET /index HTTP/1.1[0m" 200 -
ERROR:app:Exception on /favicon.ico [GET]
Traceback (most recent call last):
  File "C:\Users\Xiaocheng Wang\AppData\Local\Programs\Python\Python38-32\lib\site-packages\flask\app.py", line 2447, in wsgi_app
    response = self.full_dispatch_request()
  File "C:\Users\Xiaocheng Wang\AppData\Local\Programs\Python\Python38-32\lib\site-packages\flask\app.py", line 1952, in full_dispatch_request
    rv = self.handle_user_exception(e)
  File "C:\Users\Xiaocheng Wang\AppData\Local\Programs\Python\Python38-32\lib\site-packages\flask\app.py", line 1821, in handle_user_exception
    reraise(exc_type, exc_value, tb)
  File "C:\Users\Xiaocheng Wang\AppData\Local\Programs\Python\Python38-32\lib\site-packages\flask\_compat.py", line 39, in reraise
    raise value
  File "C:\Users\Xiaocheng Wang\AppData\Local\Programs\Python\Python38-32\lib\site-packages\flask\app.py", line 1950, in full_dispatch_request
    rv = self.dispatch_request()
  File "C:\Users\Xiaocheng Wang\AppData\Local\Programs\Python\Python38-32\lib\site-packages\flask\app.py", line 1936, in dispatch_request
    return self.view_functions[rule.endpoint](**req.view_args)
  File "E:\Study\UWA\Year3\S2\CITS3200\project\SDURI-Admin-Platform\app\routes.py", line 30, in favicon
    return send_from_directory(os.path.join(app.root_path, 'static'),
NameError: name 'send_from_directory' is not defined
INFO:werkzeug:127.0.0.1 - - [14/Sep/2020 19:20:13] "[35m[1mGET /favicon.ico HTTP/1.1[0m" 500 -
INFO:werkzeug:127.0.0.1 - - [14/Sep/2020 19:21:52] "[37mGET / HTTP/1.1[0m" 200 -
ERROR:app:Exception on /favicon.ico [GET]
Traceback (most recent call last):
  File "C:\Users\Xiaocheng Wang\AppData\Local\Programs\Python\Python38-32\lib\site-packages\flask\app.py", line 2447, in wsgi_app
    response = self.full_dispatch_request()
  File "C:\Users\Xiaocheng Wang\AppData\Local\Programs\Python\Python38-32\lib\site-packages\flask\app.py", line 1952, in full_dispatch_request
    rv = self.handle_user_exception(e)
  File "C:\Users\Xiaocheng Wang\AppData\Local\Programs\Python\Python38-32\lib\site-packages\flask\app.py", line 1821, in handle_user_exception
    reraise(exc_type, exc_value, tb)
  File "C:\Users\Xiaocheng Wang\AppData\Local\Programs\Python\Python38-32\lib\site-packages\flask\_compat.py", line 39, in reraise
    raise value
  File "C:\Users\Xiaocheng Wang\AppData\Local\Programs\Python\Python38-32\lib\site-packages\flask\app.py", line 1950, in full_dispatch_request
    rv = self.dispatch_request()
  File "C:\Users\Xiaocheng Wang\AppData\Local\Programs\Python\Python38-32\lib\site-packages\flask\app.py", line 1936, in dispatch_request
    return self.view_functions[rule.endpoint](**req.view_args)
  File "E:\Study\UWA\Year3\S2\CITS3200\project\SDURI-Admin-Platform\app\routes.py", line 30, in favicon
    return send_from_directory(os.path.join(app.root_path, 'static'),
NameError: name 'send_from_directory' is not defined
INFO:werkzeug:127.0.0.1 - - [14/Sep/2020 19:21:52] "[35m[1mGET /favicon.ico HTTP/1.1[0m" 500 -
INFO:werkzeug:127.0.0.1 - - [14/Sep/2020 19:21:53] "[37mGET / HTTP/1.1[0m" 200 -
ERROR:app:Exception on /favicon.ico [GET]
Traceback (most recent call last):
  File "C:\Users\Xiaocheng Wang\AppData\Local\Programs\Python\Python38-32\lib\site-packages\flask\app.py", line 2447, in wsgi_app
    response = self.full_dispatch_request()
  File "C:\Users\Xiaocheng Wang\AppData\Local\Programs\Python\Python38-32\lib\site-packages\flask\app.py", line 1952, in full_dispatch_request
    rv = self.handle_user_exception(e)
  File "C:\Users\Xiaocheng Wang\AppData\Local\Programs\Python\Python38-32\lib\site-packages\flask\app.py", line 1821, in handle_user_exception
    reraise(exc_type, exc_value, tb)
  File "C:\Users\Xiaocheng Wang\AppData\Local\Programs\Python\Python38-32\lib\site-packages\flask\_compat.py", line 39, in reraise
    raise value
  File "C:\Users\Xiaocheng Wang\AppData\Local\Programs\Python\Python38-32\lib\site-packages\flask\app.py", line 1950, in full_dispatch_request
    rv = self.dispatch_request()
  File "C:\Users\Xiaocheng Wang\AppData\Local\Programs\Python\Python38-32\lib\site-packages\flask\app.py", line 1936, in dispatch_request
    return self.view_functions[rule.endpoint](**req.view_args)
  File "E:\Study\UWA\Year3\S2\CITS3200\project\SDURI-Admin-Platform\app\routes.py", line 30, in favicon
    return send_from_directory(os.path.join(app.root_path, 'static'),
NameError: name 'send_from_directory' is not defined
INFO:werkzeug:127.0.0.1 - - [14/Sep/2020 19:21:55] "[35m[1mGET /favicon.ico HTTP/1.1[0m" 500 -
INFO:werkzeug:127.0.0.1 - - [14/Sep/2020 19:21:56] "[37mGET / HTTP/1.1[0m" 200 -
ERROR:app:Exception on /favicon.ico [GET]
Traceback (most recent call last):
  File "C:\Users\Xiaocheng Wang\AppData\Local\Programs\Python\Python38-32\lib\site-packages\flask\app.py", line 2447, in wsgi_app
    response = self.full_dispatch_request()
  File "C:\Users\Xiaocheng Wang\AppData\Local\Programs\Python\Python38-32\lib\site-packages\flask\app.py", line 1952, in full_dispatch_request
    rv = self.handle_user_exception(e)
  File "C:\Users\Xiaocheng Wang\AppData\Local\Programs\Python\Python38-32\lib\site-packages\flask\app.py", line 1821, in handle_user_exception
    reraise(exc_type, exc_value, tb)
  File "C:\Users\Xiaocheng Wang\AppData\Local\Programs\Python\Python38-32\lib\site-packages\flask\_compat.py", line 39, in reraise
    raise value
  File "C:\Users\Xiaocheng Wang\AppData\Local\Programs\Python\Python38-32\lib\site-packages\flask\app.py", line 1950, in full_dispatch_request
    rv = self.dispatch_request()
  File "C:\Users\Xiaocheng Wang\AppData\Local\Programs\Python\Python38-32\lib\site-packages\flask\app.py", line 1936, in dispatch_request
    return self.view_functions[rule.endpoint](**req.view_args)
  File "E:\Study\UWA\Year3\S2\CITS3200\project\SDURI-Admin-Platform\app\routes.py", line 30, in favicon
    return send_from_directory(os.path.join(app.root_path, 'static'),
NameError: name 'send_from_directory' is not defined
INFO:werkzeug:127.0.0.1 - - [14/Sep/2020 19:21:56] "[35m[1mGET /favicon.ico HTTP/1.1[0m" 500 -
INFO:werkzeug:127.0.0.1 - - [14/Sep/2020 19:21:56] "[37mGET / HTTP/1.1[0m" 200 -
ERROR:app:Exception on /favicon.ico [GET]
Traceback (most recent call last):
  File "C:\Users\Xiaocheng Wang\AppData\Local\Programs\Python\Python38-32\lib\site-packages\flask\app.py", line 2447, in wsgi_app
    response = self.full_dispatch_request()
  File "C:\Users\Xiaocheng Wang\AppData\Local\Programs\Python\Python38-32\lib\site-packages\flask\app.py", line 1952, in full_dispatch_request
    rv = self.handle_user_exception(e)
  File "C:\Users\Xiaocheng Wang\AppData\Local\Programs\Python\Python38-32\lib\site-packages\flask\app.py", line 1821, in handle_user_exception
    reraise(exc_type, exc_value, tb)
  File "C:\Users\Xiaocheng Wang\AppData\Local\Programs\Python\Python38-32\lib\site-packages\flask\_compat.py", line 39, in reraise
    raise value
  File "C:\Users\Xiaocheng Wang\AppData\Local\Programs\Python\Python38-32\lib\site-packages\flask\app.py", line 1950, in full_dispatch_request
    rv = self.dispatch_request()
  File "C:\Users\Xiaocheng Wang\AppData\Local\Programs\Python\Python38-32\lib\site-packages\flask\app.py", line 1936, in dispatch_request
    return self.view_functions[rule.endpoint](**req.view_args)
  File "E:\Study\UWA\Year3\S2\CITS3200\project\SDURI-Admin-Platform\app\routes.py", line 30, in favicon
    return send_from_directory(os.path.join(app.root_path, 'static'),
NameError: name 'send_from_directory' is not defined
INFO:werkzeug:127.0.0.1 - - [14/Sep/2020 19:21:57] "[35m[1mGET /favicon.ico HTTP/1.1[0m" 500 -
ERROR:app:Exception on /favicon.ico [GET]
Traceback (most recent call last):
  File "C:\Users\Xiaocheng Wang\AppData\Local\Programs\Python\Python38-32\lib\site-packages\flask\app.py", line 2447, in wsgi_app
    response = self.full_dispatch_request()
  File "C:\Users\Xiaocheng Wang\AppData\Local\Programs\Python\Python38-32\lib\site-packages\flask\app.py", line 1952, in full_dispatch_request
    rv = self.handle_user_exception(e)
  File "C:\Users\Xiaocheng Wang\AppData\Local\Programs\Python\Python38-32\lib\site-packages\flask\app.py", line 1821, in handle_user_exception
    reraise(exc_type, exc_value, tb)
  File "C:\Users\Xiaocheng Wang\AppData\Local\Programs\Python\Python38-32\lib\site-packages\flask\_compat.py", line 39, in reraise
    raise value
  File "C:\Users\Xiaocheng Wang\AppData\Local\Programs\Python\Python38-32\lib\site-packages\flask\app.py", line 1950, in full_dispatch_request
    rv = self.dispatch_request()
  File "C:\Users\Xiaocheng Wang\AppData\Local\Programs\Python\Python38-32\lib\site-packages\flask\app.py", line 1936, in dispatch_request
    return self.view_functions[rule.endpoint](**req.view_args)
  File "E:\Study\UWA\Year3\S2\CITS3200\project\SDURI-Admin-Platform\app\routes.py", line 30, in favicon
    return send_from_directory(os.path.join(app.root_path, 'static'),
NameError: name 'send_from_directory' is not defined
INFO:werkzeug:127.0.0.1 - - [14/Sep/2020 19:21:58] "[35m[1mGET /favicon.ico HTTP/1.1[0m" 500 -
INFO:werkzeug:127.0.0.1 - - [14/Sep/2020 19:22:01] "[37mGET / HTTP/1.1[0m" 200 -
ERROR:app:Exception on /favicon.ico [GET]
Traceback (most recent call last):
  File "C:\Users\Xiaocheng Wang\AppData\Local\Programs\Python\Python38-32\lib\site-packages\flask\app.py", line 2447, in wsgi_app
    response = self.full_dispatch_request()
  File "C:\Users\Xiaocheng Wang\AppData\Local\Programs\Python\Python38-32\lib\site-packages\flask\app.py", line 1952, in full_dispatch_request
    rv = self.handle_user_exception(e)
  File "C:\Users\Xiaocheng Wang\AppData\Local\Programs\Python\Python38-32\lib\site-packages\flask\app.py", line 1821, in handle_user_exception
    reraise(exc_type, exc_value, tb)
  File "C:\Users\Xiaocheng Wang\AppData\Local\Programs\Python\Python38-32\lib\site-packages\flask\_compat.py", line 39, in reraise
    raise value
  File "C:\Users\Xiaocheng Wang\AppData\Local\Programs\Python\Python38-32\lib\site-packages\flask\app.py", line 1950, in full_dispatch_request
    rv = self.dispatch_request()
  File "C:\Users\Xiaocheng Wang\AppData\Local\Programs\Python\Python38-32\lib\site-packages\flask\app.py", line 1936, in dispatch_request
    return self.view_functions[rule.endpoint](**req.view_args)
  File "E:\Study\UWA\Year3\S2\CITS3200\project\SDURI-Admin-Platform\app\routes.py", line 30, in favicon
    return send_from_directory(os.path.join(app.root_path, 'static'),
NameError: name 'send_from_directory' is not defined
INFO:werkzeug:127.0.0.1 - - [14/Sep/2020 19:22:01] "[35m[1mGET /favicon.ico HTTP/1.1[0m" 500 -
